Workbook

Sheet Litoral
A2: Código | B2: Descripción | C2: EAN | D2: Kg. x Caja | E2: Cant. X Caja | F2: Precio de Lista | G2: Dcto | H2: Precio oferta | I2: Precio Neto estuche en factura | J2: IVA | K2: Px Unitario IVA Inc | L2: M-up Dx | M2: Px Unitario Minorista | N2: M-up Minorista | O2: Px Unitario Público | Q2: NOV | S2: OFERTAS Y ACCIONES | AF2: SEP | AG2: %
J3: 0.21 | L3: 0.35 | N3: 0.45
A4: 100021632 | B4: HAMBURGUESAS 30x160g CLASICA x2 SWIFT | C4: 7790360026606 | D4: 4.8 | E4: 30 | F4: =+VLOOKUP(A4,$AK$4:$AL$110,2,FALSE) -> 40261.782 | H4: =+F4*(1-G4) -> 40261.782 | I4: =+H4/E4 -> 1342.0594 | J4: =+I4*J$3 -> 281.83247 | K4: =+I4+J4 -> 1623.8919 | L4: =+K4*L$3 -> 568.36216 | M4: =+K4+L4 -> 2192.254 | N4: =+M4*N$3 -> 986.51431 | O4: =+M4+N4 -> 3178.7683 | P4: =H4/Q4-1 -> 0.05 | Q4: 38344.554 | S4: 5,67% de dcto adicional vía Flex. Para oferta $2.900 (Mup 33% dx , 42.5% min). VER CUPOS | AF4: 29534.055 | AG4: =+(H4-AF4)/AF4 -> 0.36323243 | AK4: 100021632 | AL4: 40261.782 | AN4: =+Q4/H4 -> 0.95238095
A5: 100021652 | B5: HAMBURGUESA 18X4X80G CLASICA SWIFT | C5: 7790360026576 | D5: 5.76 | E5: 18 | F5: =+VLOOKUP(A5,$AK$4:$AL$110,2,FALSE) -> 50775.845 | H5: =+F5*(1-G5) -> 50775.845 | I5: =+H5/E5 -> 2820.8803 | J5: =+I5*J$3 -> 592.38486 | K5: =+I5+J5 -> 3413.2651 | L5: =+K5*L$3 -> 1194.6428 | M5: =+K5+L5 -> 4607.9079 | N5: =+M5*N$3 -> 2073.5586 | O5: =+M5+N5 -> 6681.4665 | P5: =H5/Q5-1 -> 0.1 | Q5: 46159.859 | AF5: 38042.377 | AG5: =+(H5-AF5)/AF5 -> 0.334718 | AK5: 100021652 | AL5: 50775.845 | AN5: =+Q5/H5 -> 0.90909091
A6: 100021631 | B6: HAMBURGUESA 8X12X80G CLASICA SWIFT | C6: 7790360026590 | D6: 7.68 | E6: 8 | F6: =+VLOOKUP(A6,$AK$4:$AL$110,2,FALSE) -> 64362.044 | H6: =+F6*(1-G6) -> 64362.044 | I6: =+H6/E6 -> 8045.2555 | J6: =+I6*J$3 -> 1689.5037 | K6: =+I6+J6 -> 9734.7592 | L6: =+K6*L$3 -> 3407.1657 | M6: =+K6+L6 -> 13141.925 | N6: =+M6*N$3 -> 5913.8662 | O6: =+M6+N6 -> 19055.791 | P6: =H6/Q6-1 -> 0.1 | Q6: 58510.949 | AF6: 63884.504 | AG6: =+(H6-AF6)/AF6 -> 0.0074750646 | AK6: 100021631 | AL6: 64362.044 | AN6: =+Q6/H6 -> 0.90909091
A7: 100021630 | B7: HAMBURGUESA 6X20X80G CLASICA SWIFT | C7: 7790360026583 | D7: 9.6 | E7: 6 | F7: =+VLOOKUP(A7,$AK$4:$AL$110,2,FALSE) -> 78890.37 | H7: =+F7*(1-G7) -> 78890.37 | I7: =+H7/E7 -> 13148.395 | J7: =+I7*J$3 -> 2761.1629 | K7: =+I7+J7 -> 15909.558 | L7: =+K7*L$3 -> 5568.3453 | M7: =+K7+L7 -> 21477.903 | N7: =+M7*N$3 -> 9665.0564 | O7: =+M7+N7 -> 31142.96 | P7: =H7/Q7-1 -> 0.1 | Q7: 71718.518 | AF7: 79885.735 | AG7: =+(H7-AF7)/AF7 -> -0.012459863 | AK7: 100021630 | AL7: 78890.37 | AN7: =+Q7/H7 -> 0.90909091
A8: 100021653 | B8: MEDALLON 18X4X80G PARRILLERO SWIFT | C8: 7790360026682 | D8: 5.76 | E8: 18 | F8: =+VLOOKUP(A8,$AK$4:$AL$110,2,FALSE) -> 50614.812 | H8: =+F8*(1-G8) -> 50614.812 | I8: =+H8/E8 -> 2811.934 | J8: =+I8*J$3 -> 590.50614 | K8: =+I8+J8 -> 3402.4401 | L8: =+K8*L$3 -> 1190.854 | M8: =+K8+L8 -> 4593.2942 | N8: =+M8*N$3 -> 2066.9824 | O8: =+M8+N8 -> 6660.2765 | P8: =H8/Q8-1 -> 0 | Q8: 50614.812 | AF8: 50298.202 | AG8: =+(H8-AF8)/AF8 -> 0.0062946466 | AK8: 100021653 | AL8: 50614.812 | AN8: =+Q8/H8 -> 1
A9: 100516169 | B9: MEDALLONES 18X4X80G SWIFT RECETA ESPECIAL | C9: 7790360967961 | D9: 5.76 | E9: 18 | F9: =+VLOOKUP(A9,$AK$4:$AL$110,2,FALSE) -> 46670.247 | H9: =+F9*(1-G9) -> 46670.247 | I9: =+H9/E9 -> 2592.7915 | J9: =+I9*J$3 -> 544.48622 | K9: =+I9+J9 -> 3137.2777 | L9: =+K9*L$3 -> 1098.0472 | M9: =+K9+L9 -> 4235.3249 | N9: =+M9*N$3 -> 1905.8962 | O9: =+M9+N9 -> 6141.2212 | P9: =H9/Q9-1 -> 0 | Q9: 46670.247 | AF9: 41155.421 | AG9: =+(H9-AF9)/AF9 -> 0.134 | AK9: 100516169 | AL9: 46670.247 | AN9: =+Q9/H9 -> 1
A10: 100520337 | B10: MEDALLON BURGER SWIFT MEGA 30 x 160 g | C10: 7790360977960 | D10: 4.8 | E10: 30 | F10: =+VLOOKUP(A10,$AK$4:$AL$110,2,FALSE) -> 28467.876 | H10: =+F10*(1-G10) -> 28467.876 | I10: =+H10/E10 -> 948.9292 | J10: =+I10*J$3 -> 199.27513 | K10: =+I10+J10 -> 1148.2043 | L10: =+K10*L$3 -> 401.87151 | M10: =+K10+L10 -> 1550.0758 | N10: =+M10*N$3 -> 697.53413 | O10: =+M10+N10 -> 2247.61 | P10: =H10/Q10-1 -> 0.05 | Q10: 27112.263 | AF10: 25103.947 | AG10: =+(H10-AF10)/AF10 -> 0.134 | AK10: 100520337 | AL10: 28467.876 | AN10: =+Q10/H10 -> 0.95238095
A11: 100021503 | B11: Medallón CAJITA 12x4 69 grs | C11: 7790360966841 | D11: 3.312 | E11: 12 | F11: =+VLOOKUP(A11,$AK$4:$AL$110,2,FALSE) -> 21735.959 | H11: =+F11*(1-G11) -> 21735.959 | I11: =+H11/E11 -> 1811.3299 | J11: =+I11*J$3 -> 380.37928 | K11: =+I11+J11 -> 2191.7092 | L11: =+K11*L$3 -> 767.09821 | M11: =+K11+L11 -> 2958.8074 | N11: =+M11*N$3 -> 1331.4633 | O11: =+M11+N11 -> 4290.2707 | P11: =H11/Q11-1 -> 0.14541289 | Q11: 18976.527 | AF11: 15081.22 | AG11: =+(H11-AF11)/AF11 -> 0.44126 | AK11: 100021503 | AL11: 21735.959 | AN11: =+Q11/H11 -> 0.87304762
A12: 100516201 | B12: HAMBURGUESA 8X12X69G BURGER SWIFT | C12: 7790360968548 | D12: 6.624 | E12: 8 | F12: =+VLOOKUP(A12,$AK$4:$AL$110,2,FALSE) -> 47491.011 | H12: =+F12*(1-G12) -> 47491.011 | I12: =+H12/E12 -> 5936.3763 | J12: =+I12*J$3 -> 1246.639 | K12: =+I12+J12 -> 7183.0154 | L12: =+K12*L$3 -> 2514.0554 | M12: =+K12+L12 -> 9697.0707 | N12: =+M12*N$3 -> 4363.6818 | O12: =+M12+N12 -> 14060.753 | P12: =H12/Q12-1 -> 0.05 | Q12: 45229.534 | AF12: 37985.667 | AG12: =+(H12-AF12)/AF12 -> 0.250235 | AK12: 100516201 | AL12: 47491.011 | AN12: =+Q12/H12 -> 0.95238095
A13: 100021643 | B13: MEDALLON 42X112G DOBLE BURGER SWIFT | C13: 7790360966797 | D13: 4.704 | E13: 42 | F13: =+VLOOKUP(A13,$AK$4:$AL$110,2,FALSE) -> 29124.796 | G13: 0.095238095 | H13: =+F13*(1-G13) -> 26351.006 | I13: =+H13/E13 -> 627.40491 | J13: =+I13*J$3 -> 131.75503 | K13: =+I13+J13 -> 759.15994 | L13: =+K13*L$3 -> 265.70598 | M13: =+K13+L13 -> 1024.8659 | N13: =+M13*N$3 -> 461.18966 | O13: =+M13+N13 -> 1486.0556 | P13: =H13/Q13-1 -> -0.05 | Q13: 27737.901 | S13: COMPRA 19 ESTUCHES + 2 DE REGALO | AF13: 23295.457 | AG13: =+(H13-AF13)/AF13 -> 0.131165 | AK13: 100021643 | AL13: 29124.796 | AN13: =+Q13/H13 -> 1.0526316
A14: 100516325 | B14: MEDALLON DOBLE BURGER 2X2 | C14: 7790360967763 | D14: 4.704 | E14: 21 | F14: =+VLOOKUP(A14,$AK$4:$AL$110,2,FALSE) -> 32755.097 | H14: =+F14*(1-G14) -> 32755.097 | I14: =+H14/E14 -> 1559.7665 | J14: =+I14*J$3 -> 327.55097 | K14: =+I14+J14 -> 1887.3175 | L14: =+K14*L$3 -> 660.56112 | M14: =+K14+L14 -> 2547.8786 | N14: =+M14*N$3 -> 1146.5454 | O14: =+M14+N14 -> 3694.424 | P14: =H14/Q14-1 -> 0.05 | Q14: 31195.33 | AF14: 27509.109 | AG14: =+(H14-AF14)/AF14 -> 0.1907 | AK14: 100516325 | AL14: 32755.097 | AN14: =+Q14/H14 -> 0.95238095
A15: 100021676 | B15: HAMBURGUESA 30X250g CLASICA "XL" SWIFT | C15: 7790360967411 | D15: 7.5 | E15: 30 | F15: =+VLOOKUP(A15,$AK$4:$AL$110,2,FALSE) -> 60777.549 | H15: =+F15*(1-G15) -> 60777.549 | I15: =+H15/E15 -> 2025.9183 | J15: =+I15*J$3 -> 425.44284 | K15: =+I15+J15 -> 2451.3612 | L15: =+K15*L$3 -> 857.9764 | M15: =+K15+L15 -> 3309.3376 | N15: =+M15*N$3 -> 1489.2019 | O15: =+M15+N15 -> 4798.5395 | P15: =H15/Q15-1 -> 0.071466838 | Q15: 56723.687 | AF15: 53595.722 | AG15: =+(H15-AF15)/AF15 -> 0.134 | AK15: 100021676 | AL15: 60777.549 | AN15: =+Q15/H15 -> 0.9333
A16: 100516008 | B16: HAMBURGUESA 24X2X120g CASERA SWIFT | C16: 7790360967701 | D16: 5.76 | E16: 24 | F16: =+VLOOKUP(A16,$AK$4:$AL$110,2,FALSE) -> 50957.087 | G16: 0.05 | H16: =+F16*(1-G16) -> 48409.232 | I16: =+H16/E16 -> 2017.0514 | J16: =+I16*J$3 -> 423.58078 | K16: =+I16+J16 -> 2440.6321 | L16: =+K16*L$3 -> 854.22125 | M16: =+K16+L16 -> 3294.8534 | N16: =+M16*0.4265 -> 1405.255 | O16: =+M16+N16 -> 4700.1084 | P16: =H16/Q16-1 -> 0.04498955 | Q16: 46325.088 | S16: Oferta a $4.700 | AF16: 47578.979 | AG16: =+(H16-AF16)/AF16 -> 0.01745 | AK16: 100516008 | AL16: 50957.087 | AN16: =+Q16/H16 -> 0.95694737
A17: 100520834 | B17: HAMBURGUESA X-TREMA 36 x 185 grs | C17: 7790360980618 | D17: 6.66 | E17: 36 | F17: =+VLOOKUP(A17,$AK$4:$AL$110,2,FALSE) -> 63095.588 | H17: =+F17*(1-G17) -> 63095.588 | I17: =+H17/E17 -> 1752.6552 | J17: =+I17*J$3 -> 368.0576 | K17: =+I17+J17 -> 2120.7128 | L17: =+K17*L$3 -> 742.24949 | M17: =+K17+L17 -> 2862.9623 | N17: =+M17*N$3 -> 1288.333 | O17: =+M17+N17 -> 4151.2954 | P17: =H17/Q17-1 -> 0 | Q17: 63095.588 | AF17: 55639.849 | AG17: =+(H17-AF17)/AF17 -> 0.134 | AK17: 100520834 | AL17: 63095.588 | AN17: =+Q17/H17 -> 1
A18: 100021680 | B18: HAMBURGUESAS 18X2X120g CLL BRA/ARG | C18: 7790360967688 | D18: 4.32 | E18: 18 | F18: =+VLOOKUP(A18,$AK$4:$AL$110,2,FALSE) -> #N/A | H18: =+F18*(1-G18) -> #N/A | I18: =+H18/E18 -> #N/A | J18: =+I18*J$3 -> #N/A | K18: =+I18+J18 -> #N/A | L18: =+K18*L$3 -> #N/A | M18: =+K18+L18 -> #N/A | N18: =+M18*N$3 -> #N/A | O18: =+M18+N18 -> #N/A | P18: =H18/Q18-1 -> #N/A | Q18: 50536.767 | AF18: 44565.05 | AG18: =+(H18-AF18)/AF18 -> #N/A | AK18: 100021644 | AL18: 21089.839 | AN18: =+Q18/H18 -> #N/A
A19: 100021644 | B19: MEDALLON 42X112G LA BLANCA | C19: 7790360008541 | D19: 4.704 | E19: 42 | F19: =+VLOOKUP(A19,$AK$4:$AL$110,2,FALSE) -> 21089.839 | H19: =+F19*(1-G19) -> 21089.839 | I19: =+H19/E19 -> 502.13904 | J19: =+I19*J$3 -> 105.4492 | K19: =+I19+J19 -> 607.58823 | L19: =+K19*0.3 -> 182.27647 | M19: =+K19+L19 -> 789.8647 | N19: =+M19*N$3 -> 355.43912 | O19: =+M19+N19 -> 1145.3038 | P19: =H19/Q19-1 -> 0.1 | Q19: 19172.581 | AF19: 14434.467 | AG19: =+(H19-AF19)/AF19 -> 0.461075 | AK19: 100021677 | AL19: 16737.231 | AN19: =+Q19/H19 -> 0.90909091
A20: 100021677 | B20: MEDALLON 12x4X69G LA BLANCA | C20: 7790360967404 | D20: 3.312 | E20: 12 | F20: =+VLOOKUP(A20,$AK$4:$AL$110,2,FALSE) -> 16737.231 | H20: =+F20*(1-G20) -> 16737.231 | I20: =+H20/E20 -> 1394.7692 | J20: =+I20*J$3 -> 292.90154 | K20: =+I20+J20 -> 1687.6708 | L20: =+K20*0.3 -> 506.30123 | M20: =+K20+L20 -> 2193.972 | N20: =+M20*N$3 -> 987.28741 | O20: =+M20+N20 -> 3181.2594 | P20: =H20/Q20-1 -> 0.1 | Q20: 15215.664 | AF20: 13173.735 | AG20: =+(H20-AF20)/AF20 -> 0.2705 | AK20: 100021638 | AL20: 47532.849 | AN20: =+Q20/H20 -> 0.90909091
A21: 100021638 | B21: MEDALLONES 60X80g "SWIFT BURGER" PARRILLERAS FAMILY | C21: 7790360026699 | D21: 4.8 | E21: 60 | F21: =+VLOOKUP(A21,$AK$4:$AL$110,2,FALSE) -> 47532.849 | H21: =+F21*(1-G21) -> 47532.849 | I21: =+H21/E21 -> 792.21415 | J21: =+I21*J$3 -> 166.36497 | K21: =+I21+J21 -> 958.57912 | L21: =+K21*L$3 -> 335.50269 | M21: =+K21+L21 -> 1294.0818 | N21: =+M21*N$3 -> 582.33681 | O21: =+M21+N21 -> 1876.4186 | P21: =H21/Q21-1 -> 0 | Q21: 47532.849 | AF21: 41916.092 | AG21: =+(H21-AF21)/AF21 -> 0.134 | AK21: 100021575 | AL21: 38984.492 | AN21: =+Q21/H21 -> 1
A22: 100021575 | B22: MEDALLONES 60X69g "SWIFT BURGER"PARRILLERAS FAMILY | C22: 7790360007032 | D22: 4.14 | E22: 60 | F22: =+VLOOKUP(A22,$AK$4:$AL$110,2,FALSE) -> 38984.492 | H22: =+F22*(1-G22) -> 38984.492 | I22: =+H22/E22 -> 649.74153 | J22: =+I22*J$3 -> 136.44572 | K22: =+I22+J22 -> 786.18725 | L22: =+K22*L$3 -> 275.16554 | M22: =+K22+L22 -> 1061.3528 | N22: =+M22*N$3 -> 477.60875 | O22: =+M22+N22 -> 1538.9615 | P22: =H22/Q22-1 -> 0 | Q22: 38984.492 | AF22: 34377.859 | AG22: =+(H22-AF22)/AF22 -> 0.134 | AK22: 100021514 | AL22: 35475.666 | AN22: =+Q22/H22 -> 1
A23: 100021514 | B23: MEDALLON 60X69G CARNE VACUNA | C23: 7790360006943 | D23: 4.14 | E23: 60 | F23: =+VLOOKUP(A23,$AK$4:$AL$110,2,FALSE) -> 35475.666 | H23: =+F23*(1-G23) -> 35475.666 | I23: =+H23/E23 -> 591.26111 | J23: =+I23*J$3 -> 124.16483 | K23: =+I23+J23 -> 715.42594 | L23: =+K23*L$3 -> 250.39908 | M23: =+K23+L23 -> 965.82502 | N23: =+M23*N$3 -> 434.62126 | O23: =+M23+N23 -> 1400.4463 | P23: =H23/Q23-1 -> 0 | Q23: 35475.666 | AF23: 31283.656 | AG23: =+(H23-AF23)/AF23 -> 0.134 | AK23: 100516208 | AL23: 41131.229 | AN23: =+Q23/H23 -> 1
A24: 100516208 | B24: MEDALLON 60x80g PARRILLERO MC SWIFT | C24: 7790360968203 | D24: =60*0.08 -> 4.8 | E24: 60 | F24: =+VLOOKUP(A24,$AK$4:$AL$110,2,FALSE) -> 41131.229 | H24: =+F24*(1-G24) -> 41131.229 | I24: =+H24/E24 -> 685.52049 | J24: =+I24*J$3 -> 143.9593 | K24: =+I24+J24 -> 829.47979 | L24: =+K24*L$3 -> 290.31793 | M24: =+K24+L24 -> 1119.7977 | N24: =+M24*N$3 -> 503.90897 | O24: =+M24+N24 -> 1623.7067 | P24: =H24/Q24-1 -> 0 | Q24: 41131.229 | AF24: 36270.925 | AG24: =+(H24-AF24)/AF24 -> 0.134 | AK24: 100518346 | AL24: 58788.442 | AN24: =+Q24/H24 -> 1
A25: 100518346 | B25: MEDALLON 60X109G CARNE VACUNA PARRILLERO SWIFT | C25: 7790360975478 | D25: =60*0.109 -> 6.54 | E25: 60 | F25: =+VLOOKUP(A25,$AK$4:$AL$110,2,FALSE) -> 58788.442 | H25: =+F25*(1-G25) -> 58788.442 | I25: =+H25/E25 -> 979.80737 | J25: =I25*J3 -> 205.75955 | K25: =J25+I25 -> 1185.5669 | L25: =K25*L3 -> 414.94842 | M25: =L25+K25 -> 1600.5153 | N25: =M25*N3 -> 720.2319 | O25: =N25+M25 -> 2320.7472 | P25: =H25/Q25-1 -> 0 | Q25: 58788.442 | AF25: 51841.66 | AG25: =+(H25-AF25)/AF25 -> 0.134 | AK25: 100516259 | AL25: 136018.21 | AN25: =+Q25/H25 -> 1
A26: 100516259 | B26: MEDALLON GIGANTE 48x113.5g | C26: 7790360968340 | D26: 18.16 | E26: 48 | F26: =+VLOOKUP(A26,$AK$4:$AL$110,2,FALSE) -> 136018.21 | H26: =+F26*(1-G26) -> 136018.21 | I26: =+H26/E26 -> 2833.7127 | J26: =+I26*J$3 -> 595.07967 | K26: =+I26+J26 -> 3428.7924 | L26: =+K26*L$3 -> 1200.0773 | M26: =+K26+L26 -> 4628.8697 | N26: =+M26*N$3 -> 2082.9914 | O26: =+M26+N26 -> 6711.8611 | P26: =H26/Q26-1 -> 0 | Q26: 136018.21 | AF26: 119945.51 | AG26: =+(H26-AF26)/AF26 -> 0.134 | AK26: 100518095 | AL26: 67770.616 | AN26: =+Q26/H26 -> 1
A27: 100518095 | B27: HAMBURGUESA 36 X 185 GRS | C27: 7790360974785 | D27: 6.66 | E27: 36 | F27: =+VLOOKUP(A27,$AK$4:$AL$110,2,FALSE) -> 67770.616 | H27: =+F27*(1-G27) -> 67770.616 | I27: =+H27/E27 -> 1882.5171 | J27: =+I27*J$3 -> 395.32859 | K27: =+I27+J27 -> 2277.8457 | L27: =+K27*L$3 -> 797.24599 | M27: =+K27+L27 -> 3075.0917 | N27: =+M27*N$3 -> 1383.7913 | O27: =+M27+N27 -> 4458.883 | P27: =H27/Q27-1 -> 0 | Q27: 67770.616 | AF27: 59762.448 | AG27: =+(H27-AF27)/AF27 -> 0.134 | AK27: 100518223 | AL27: 52763.191 | AN27: =+Q27/H27 -> 1
A28: 100518223 | B28: HAMBURGUESA 30x2x106 GRS | C28: 7790360975065 | D28: =60*0.106 -> 6.36 | E28: 30 | F28: =+VLOOKUP(A28,$AK$4:$AL$110,2,FALSE) -> 52763.191 | H28: =+F28*(1-G28) -> 52763.191 | I28: =+H28/E28 -> 1758.773 | J28: =+I28*J$3 -> 369.34234 | K28: =+I28+J28 -> 2128.1154 | L28: =+K28*L$3 -> 744.84038 | M28: =+K28+L28 -> 2872.9557 | N28: =+M28*N$3 -> 1292.8301 | O28: =+M28+N28 -> 4165.7858 | P28: =H28/Q28-1 -> 0 | Q28: 52763.191 | AF28: 46528.387 | AG28: =+(H28-AF28)/AF28 -> 0.134 | AN28: =+Q28/H28 -> 1
F29: =+VLOOKUP(A29,$AK$4:$AL$110,2,FALSE) -> #N/A | H29: =+F29*(1-G29) -> #N/A | I29: =+H29/E29 -> #N/A | P29: =H29/Q29-1 -> #N/A | Q29: #N/A | Y29: OCT | Z29: PATY VIENA | AA29: VIENISSIMA | AB29: PALADINI | AF29: #N/A | AG29: =+(H29-AF29)/AF29 -> #N/A | AK29: 100522204 | AL29: 23406.479 | AN29: =+Q29/H29 -> #N/A
A30: 100022085 | B30: SALCHICHAS 24X6 SWIFT | C30: 7790360000132 | D30: 5.4 | E30: 24 | F30: =+VLOOKUP(A30,$AK$4:$AL$110,2,FALSE) -> #N/A | G30: =0.0833333333333333*100% -> 0.083333333 | H30: =+F30*(1-G30) -> #N/A | I30: =+H30/E30 -> #N/A | J30: =+I30*J$3 -> #N/A | K30: =+I30+J30 -> #N/A | L30: =+K30*L$3 -> #N/A | M30: =+K30+L30 -> #N/A | N30: =+M30*0.438 -> #N/A | O30: =+M30+N30 -> #N/A | P30: =H30/Q30-1 -> #N/A | Q30: 20434.227 | S30: Compra 11 estuches + 1 de regalo ----> OFERTA $2.100 público | Y30: 1900 | Z30: 2080 | AA30: 2435 | AB30: 2328 | AF30: 18238.814 | AG30: =+(H30-AF30)/AF30 -> #N/A | AK30: 100522205 | AL30: 22236.155 | AN30: =+Q30/H30 -> #N/A
A31: 100522204 | B31: SALCHICHAS 24X6 SWIFT | C31: 7790360983947 | D31: 5.4 | E31: 24 | F31: =+VLOOKUP(A31,$AK$4:$AL$110,2,FALSE) -> 23406.479 | G31: 0.083333333 | H31: =+F31*(1-G31) -> 21455.939 | I31: =+H31/E31 -> 893.99745 | J31: =+I31*J$3 -> 187.73946 | K31: =+I31+J31 -> 1081.7369 | L31: =+K31*L$3 -> 378.60792 | M31: =+K31+L31 -> 1460.3448 | N31: =+M31*0.438 -> 639.63103 | O31: =+M31+N31 -> 2099.9759 | P31: =H31/Q31-1 -> 0.05 | Q31: 20434.227 | S31: Compra 11 estuches + 1 de regalo ----> OFERTA $2.100 público | AK31: 100516849 | AL31: 18023.644
A32: 100022072 | B32: SALCHICHAS 12X12 SWIFT | C32: 7790360024541 | D32: 5.4 | E32: 12 | F32: =+VLOOKUP(A32,$AK$4:$AL$110,2,FALSE) -> #N/A | G32: =0.0833333333333333*100% -> 0.083333333 | H32: =+F32*(1-G32) -> #N/A | I32: =+H32/E32 -> #N/A | J32: =+I32*J$3 -> #N/A | K32: =+I32+J32 -> #N/A | L32: =+K32*0.3388 -> #N/A | M32: =+K32+L32 -> #N/A | N32: =+M32*N$3 -> #N/A | O32: =+M32+N32 -> #N/A | P32: =H32/Q32-1 -> #N/A | Q32: 19412.516 | S32: Conveniencia vs 22085: Oferta $3.990 | Y32: 3600 | Z32: 4090 | AA32: 4495 | AB32: 4400 | AF32: 17225.547 | AG32: =+(H32-AF32)/AF32 -> #N/A | AK32: 100522206 | AL32: 58843.879 | AN32: =+Q32/H32 -> #N/A
A33: 100522205 | B33: SALCHICHAS 12X12 SWIFT | C33: 7790360983954 | D33: 5.4 | E33: 12 | F33: =+VLOOKUP(A33,$AK$4:$AL$110,2,FALSE) -> 22236.155 | G33: =0.0833333333333333*100% -> 0.083333333 | H33: =+F33*(1-G33) -> 20383.142 | I33: =+H33/E33 -> 1698.5951 | J33: =+I33*J$3 -> 356.70498 | K33: =+I33+J33 -> 2055.3001 | L33: =+K33*0.3388 -> 696.33568 | M33: =+K33+L33 -> 2751.6358 | N33: =+M33*N$3 -> 1238.2361 | O33: =+M33+N33 -> 3989.8719 | P33: =H33/Q33-1 -> 0.05 | Q33: 19412.516 | S33: Conveniencia vs 22085: Oferta $3.990 | AK33: 100022058 | AL33: 15783.589
A34: 100516849 | B34: SALCHICHAS SIN PIEL 24X6 "SWIFT KIDS" X 190 g | C34: 7790360970053 | D34: 4.56 | E34: 24 | F34: =+VLOOKUP(A34,$AK$4:$AL$110,2,FALSE) -> 18023.644 | H34: =+F34*(1-G34) -> 18023.644 | I34: =+H34/E34 -> 750.98516 | J34: =+I34*J$3 -> 157.70688 | K34: =+I34+J34 -> 908.69205 | L34: =+K34*0.339 -> 308.0466 | M34: =+K34+L34 -> 1216.7386 | N34: =+M34*0.4 -> 486.69546 | O34: =+M34+N34 -> 1703.4341 | P34: =H34/Q34-1 -> 0.05 | Q34: 17165.375 | S34: Oferta incluida en lista: $1.700 | Y34: 1650 | Z34: 1888 | AA34: PATY FUN | AF34: 15705.646 | AG34: =+(H34-AF34)/AF34 -> 0.14759012 | AK34: 100518151 | AL34: 67038.027 | AN34: =+Q34/H34 -> 0.95238095
A35: 100022039 | B35: SALCHICHAS LARGAS 10 x 12 SWIFT INSTITUCIONAL | C35: 7790360007063 | D35: 8.7 | E35: 10 | F35: =+VLOOKUP(A35,$AK$4:$AL$110,2,FALSE) -> #N/A | H35: =+F35*(1-G35) -> #N/A | I35: =+H35/E35 -> #N/A | J35: =+I35*J$3 -> #N/A | K35: =+I35+J35 -> #N/A | L35: =+K35*L$3 -> #N/A | M35: =+K35+L35 -> #N/A | N35: =+M35*N$3 -> #N/A | O35: =+M35+N35 -> #N/A | P35: =H35/Q35-1 -> #N/A | Q35: 56041.789 | Z35: ICB | AA35: 66 | AB35: PANCHIN | AC35: fela | AF35: 44083.414 | AG35: =+(H35-AF35)/AF35 -> #N/A | AN35: =+Q35/H35 -> #N/A
A36: 100522206 | B36: SALCHICHAS LARGAS 10 x 12 SWIFT INSTITUCIONAL | C36: 7790360983961 | D36: 8.7 | E36: 10 | F36: 56041.789 | H36: =+F36*(1-G36) -> 56041.789 | I36: =+H36/E36 -> 5604.1789 | J36: =+I36*J$3 -> 1176.8776 | K36: =+I36+J36 -> 6781.0565 | L36: =+K36*L$3 -> 2373.3698 | M36: =+K36+L36 -> 9154.4263 | N36: =+M36*N$3 -> 4119.4918 | O36: =+M36+N36 -> 13273.918 | P36: =H36/Q36-1 -> 0 | Q36: 56041.789 | AK36: 100021000 | AL36: 12962.274
A37: 100022058 | B37: SALCHICHAS SIN PIEL "LA BLANCA" 24X6X190 Grs; | C37: 7790360026002 | D37: 4.56 | E37: 24 | F37: =+VLOOKUP(A37,$AK$4:$AL$110,2,FALSE) -> 15783.589 | H37: =+F37*(1-G37) -> 15783.589 | I37: =+H37/E37 -> 657.64956 | J37: =+I37*J$3 -> 138.10641 | K37: =+I37+J37 -> 795.75597 | L37: =+K37*0.3 -> 238.72679 | M37: =+K37+L37 -> 1034.4828 | N37: =+M37*N$3 -> 465.51724 | O37: =+M37+N37 -> 1500 | P37: =H37/Q37-1 -> 0 | Q37: 15783.589 | Y37: 1130 | Z37: 1190 | AA37: 1000 | AB37: 1198 | AC37: 1500 | AD37: MISMO PX MES ANT | AF37: 11449.922 | AG37: =+(H37-AF37)/AF37 -> 0.37848877 | AK37: 100021001 | AL37: 12962.274 | AN37: =+Q37/H37 -> 1
A38: 100518151 | B38: SALCHICHAS LARGAS 10 x 12 x 870g | C38: 7790360974990 | D38: 8.7 | E38: 10 | F38: =+VLOOKUP(A38,$AK$4:$AL$110,2,FALSE) -> 67038.027 | H38: =+F38*(1-G38) -> 67038.027 | I38: =+H38/E38 -> 6703.8027 | J38: =+I38*J$3 -> 1407.7986 | K38: =+I38+J38 -> 8111.6012 | L38: =+K38*0.3 -> 2433.4804 | M38: =+K38+L38 -> 10545.082 | N38: =+M38*N$3 -> 4745.2867 | O38: =+M38+N38 -> 15290.368 | P38: =H38/Q38-1 -> 0.05 | Q38: 63845.74 | AF38: 50222.132 | AG38: =+(H38-AF38)/AF38 -> 0.33483035 | AK38: 100522277 | AL38: 12962.274 | AN38: =+Q38/H38 -> 0.95238095
F39: =+VLOOKUP(A39,$AK$4:$AL$110,2,FALSE) -> #N/A | H39: =+F39*(1-G39) -> #N/A | I39: =+H39/E39 -> #N/A | J39: 0.21 | L39: 0.22 | N39: 0.35 | P39: =H39/Q39-1 -> #N/A | Q39: #N/A | Y39: =+Y37*24 -> 27120 | AF39: #N/A | AG39: =+(H39-AF39)/AF39 -> #N/A | AK39: 100522333 | AL39: 12962.274 | AN39: =+Q39/H39 -> #N/A
A40: 100021000 | B40: PATE DE FOIE 24X90G SWIFT | C40: 7790360720382 | D40: 2.16 | E40: 24 | F40: =+VLOOKUP(A40,$AK$4:$AL$110,2,FALSE) -> 12962.274 | H40: =+F40*(1-G40) -> 12962.274 | I40: =+H40/E40 -> 540.09474 | J40: =+I40*J$3 -> 113.41989 | K40: =+I40+J40 -> 653.51463 | L40: =+K40*L$39 -> 143.77322 | M40: =+K40+L40 -> 797.28785 | N40: =+M40*N$39 -> 279.05075 | O40: =+M40+N40 -> 1076.3386 | P40: =H40/Q40-1 -> 0.05 | Q40: 12345.023 | Y40: =+Y39/1.21/1.35/1.45 -> 11449.922 | Z40: PX 22058 | AF40: 10353.088 | AG40: =+(H40-AF40)/AF40 -> 0.25202 | AK40: 100021045 | AL40: 12962.274 | AN40: =+Q40/H40 -> 0.95238095
A41: 100021001 | B41: PICADILLO DE CARNE 24X90G SWIFT | C41: 7790360720115 | D41: 2.16 | E41: 24 | F41: =+VLOOKUP(A41,$AK$4:$AL$110,2,FALSE) -> 12962.274 | H41: =+F41*(1-G41) -> 12962.274 | I41: =+H41/E41 -> 540.09474 | J41: =+I41*J$3 -> 113.41989 | K41: =+I41+J41 -> 653.51463 | L41: =+K41*L$39 -> 143.77322 | M41: =+K41+L41 -> 797.28785 | N41: =+M41*N$39 -> 279.05075 | O41: =+M41+N41 -> 1076.3386 | P41: =H41/Q41-1 -> 0.05 | Q41: 12345.023 | Y41: =+F37-Y40 -> 4333.667 | AF41: 10353.088 | AG41: =+(H41-AF41)/AF41 -> 0.25202 | AK41: 100021004 | AL41: 12962.274 | AN41: =+Q41/H41 -> 0.95238095
...

Sheet NEA
Z1: ACCIÓN VIA NC: COMBO CLASICA 2 X 80 + CHORIZOS
A2: Código | B2: Descripción | C2: EAN | D2: Kg. x Caja | E2: Cant. X Caja | F2: Precio de Lista | H2: Precio de Factura | I2: Precio Neto estuche en factura | J2: IVA | K2: Px Unitario IVA Inc | L2: M-up Dx | M2: Px Unitario Minorista | N2: M-up Minorista | O2: Px Unitario Público | Q2: Enero | S2: OFERTAS Y ACCIONES | Z2: DCTO (%) | AA2: Px ACCIÓN CAJA ($) | AB2: Px Acción estuche ($) | AC2: Px oferta (%) | AD2: CUPO (Cajas) | AE2: CONDICIÓN | AI2: SEP | AJ2: VAR %
J3: 0.21 | L3: 0.33 | N3: 0.4 | AN3: 100021632 | AO3: 42178.607
A4: 100021632 | B4: HAMBURGUESAS 30x160g CLASICA x2 SWIFT | C4: 7790360026606 | D4: 4.8 | E4: 30 | F4: =+VLOOKUP(A4,$AN$3:$AO$109,2,FALSE) -> 42178.607 | G4: 0.07 | H4: =+F4*(1-G4) -> 39226.104 | I4: =+H4/E4 -> 1307.5368 | J4: =+I4*J$3 -> 274.58273 | K4: =+I4+J4 -> 1582.1195 | L4: =+K4*0.309 -> 488.87494 | M4: =+K4+L4 -> 2070.9945 | N4: =+M4*N$3 -> 828.39779 | O4: =+M4+N4 -> 2899.3923 | P4: =H4/Q4-1 -> -0.0235 | Q4: 40170.102 | S4: 7% dcto para oferta $2.900: +15% vs Friar ($2.600) -15% vs Paty ($3.500) | Y4: =+Z4*H4 -> 3922.6104 | Z4: 0.1 | AA4: =+H4*(1-Z4) -> 35303.494 | AB4: =+AA4/E4 -> 1176.7831 | AC4: =+AB4*1.21*1.3*1.4 -> 2591.5118 | AD4: VER CUPOS | AE4: Con la compra de 1 caja de 21632 + 2 unidades de Chorizos --> 10% de dcto en ambos SKU | AI4: 33427.033 | AJ4: =+(H4-AI4)/AI4 -> 0.17348446 | AN4: 100021652 | AO4: 52310.046
A5: 100021652 | B5: HAMBURGUESA 18X4X80G CLASICA SWIFT | C5: 7790360026576 | D5: 5.76 | E5: 18 | F5: =+VLOOKUP(A5,$AN$3:$AO$109,2,FALSE) -> 52310.046 | H5: =+F5*(1-G5) -> 52310.046 | I5: =+H5/E5 -> 2906.1137 | J5: =+I5*J$3 -> 610.28388 | K5: =+I5+J5 -> 3516.3976 | L5: =+K5*L$3 -> 1160.4112 | M5: =+K5+L5 -> 4676.8088 | N5: =+M5*N$3 -> 1870.7235 | O5: =+M5+N5 -> 6547.5323 | P5: =H5/Q5-1 -> 0 | Q5: 52310.046 | AI5: 43529.132 | AJ5: =+(H5-AI5)/AI5 -> 0.201725 | AN5: 100021631 | AO5: 61058.555
A6: 100021631 | B6: HAMBURGUESA 8X12X80G CLASICA SWIFT | C6: 7790360026590 | D6: 7.68 | E6: 8 | F6: =+VLOOKUP(A6,$AN$3:$AO$109,2,FALSE) -> 61058.555 | H6: =+F6*(1-G6) -> 61058.555 | I6: =+H6/E6 -> 7632.3193 | J6: =+I6*J$3 -> 1602.7871 | K6: =+I6+J6 -> 9235.1064 | L6: =+K6*L$3 -> 3047.5851 | M6: =+K6+L6 -> 12282.692 | N6: =+M6*N$3 -> 4913.0766 | O6: =+M6+N6 -> 17195.768 | P6: =H6/Q6-1 -> 0 | Q6: 61058.555 | Y6: =+O4*0.9 -> 2609.4531 | AI6: 69881.188 | AJ6: =+(H6-AI6)/AI6 -> -0.1262519 | AN6: 100021630 | AO6: 74716.389
A7: 100021630 | B7: HAMBURGUESA 6X20X80G CLASICA SWIFT | C7: 7790360026583 | D7: 9.6 | E7: 6 | F7: =+VLOOKUP(A7,$AN$3:$AO$109,2,FALSE) -> 74716.389 | H7: =+F7*(1-G7) -> 74716.389 | I7: =+H7/E7 -> 12452.732 | J7: =+I7*J$3 -> 2615.0736 | K7: =+I7+J7 -> 15067.805 | L7: =+K7*L$3 -> 4972.3757 | M7: =+K7+L7 -> 20040.181 | N7: =+M7*N$3 -> 8016.0724 | O7: =+M7+N7 -> 28056.253 | P7: =H7/Q7-1 -> 0 | Q7: 74716.389 | AI7: 87351.485 | AJ7: =+(H7-AI7)/AI7 -> -0.1446466 | AN7: 100021653 | AO7: 53024.534
A8: 100021653 | B8: MEDALLON 18X4X80G PARRILLERO SWIFT | C8: 7790360026682 | D8: 5.76 | E8: 18 | F8: =+VLOOKUP(A8,$AN$3:$AO$109,2,FALSE) -> 53024.534 | H8: =+F8*(1-G8) -> 53024.534 | I8: =+H8/E8 -> 2945.8075 | J8: =+I8*J$3 -> 618.61957 | K8: =+I8+J8 -> 3564.427 | L8: =+K8*L$3 -> 1176.2609 | M8: =+K8+L8 -> 4740.688 | N8: =+M8*N$3 -> 1896.2752 | O8: =+M8+N8 -> 6636.9631 | P8: =H8/Q8-1 -> 0 | Q8: 53024.534 | AI8: 52653.64 | AJ8: =+(H8-AI8)/AI8 -> 0.00704404 | AN8: 100516169 | AO8: 43213.192
A9: 100516169 | B9: MEDALLONES 18X4X80G SWIFT RECETA ESPECIAL | C9: 7790360967961 | D9: 5.76 | E9: 18 | F9: =+VLOOKUP(A9,$AN$3:$AO$109,2,FALSE) -> 43213.192 | H9: =+F9*(1-G9) -> 43213.192 | I9: =+H9/E9 -> 2400.7329 | J9: =+I9*J$3 -> 504.15391 | K9: =+I9+J9 -> 2904.8868 | L9: =+K9*L$3 -> 958.61264 | M9: =+K9+L9 -> 3863.4994 | N9: =+M9*N$3 -> 1545.3998 | O9: =+M9+N9 -> 5408.8992 | P9: =H9/Q9-1 -> 0 | Q9: 43213.192 | AI9: 41155.421 | AJ9: =+(H9-AI9)/AI9 -> 0.05 | AN9: 100520337 | AO9: 28412.978
A10: 100520337 | B10: MEDALLON BURGER SWIFT MEGA 30 x 160 g | C10: 7790360977960 | D10: 4.8 | E10: 30 | F10: =+VLOOKUP(A10,$AN$3:$AO$109,2,FALSE) -> 28412.978 | H10: =+F10*(1-G10) -> 28412.978 | I10: =+H10/E10 -> 947.09928 | J10: =+I10*J$3 -> 198.89085 | K10: =+I10+J10 -> 1145.9901 | L10: =+K10*0.309 -> 354.11095 | M10: =+K10+L10 -> 1500.1011 | N10: =+M10*N$3 -> 600.04043 | O10: =+M10+N10 -> 2100.1415 | P10: =H10/Q10-1 -> 0.12491965 | Q10: 25257.785 | S10: Oferta neteada en lista: $2.100 para activar estrategia Sandwich vs Friar 2x80 a $2600----> $2.100 con Mega y $2.900 con Clásica | AI10: 27059.979 | AJ10: =+(H10-AI10)/AI10 -> 0.05 | AN10: 100021503 | AO10: 22877.766
A11: 100021503 | B11: Medallón CAJITA 12x4 69 grs | C11: 7790360966841 | D11: 3.312 | E11: 12 | F11: =+VLOOKUP(A11,$AN$3:$AO$109,2,FALSE) -> 22877.766 | G11: 0.083333333 | H11: =+F11*(1-G11) -> 20971.285 | I11: =+H11/E11 -> 1747.6071 | J11: =+I11*J$3 -> 366.99749 | K11: =+I11+J11 -> 2114.6046 | L11: =+K11*L$3 -> 697.81951 | M11: =+K11+L11 -> 2812.4241 | N11: =+M11*N$3 -> 1124.9696 | O11: =+M11+N11 -> 3937.3937 | P11: =H11/Q11-1 -> 0.10044018 | Q11: 19057.179 | S11: Contra 10 estuches + 1 de regalo | AI11: 18946.39 | AJ11: =+(H11-AI11)/AI11 -> 0.106875 | AN11: 100516201 | AO11: 45177.91
A12: 100516201 | B12: HAMBURGUESA 8X12X69G BURGER SWIFT | C12: 7790360968548 | D12: 6.624 | E12: 8 | F12: =+VLOOKUP(A12,$AN$3:$AO$109,2,FALSE) -> 45177.91 | H12: =+F12*(1-G12) -> 45177.91 | I12: =+H12/E12 -> 5647.2388 | J12: =+I12*J$3 -> 1185.9201 | K12: =+I12+J12 -> 6833.1589 | L12: =+K12*L$3 -> 2254.9425 | M12: =+K12+L12 -> 9088.1014 | N12: =+M12*N$3 -> 3635.2406 | O12: =+M12+N12 -> 12723.342 | P12: =H12/Q12-1 -> 0 | Q12: 45177.91 | AI12: 43026.581 | AJ12: =+(H12-AI12)/AI12 -> 0.05 | AN12: 100021643 | AO12: 25320.574
A13: 100021643 | B13: MEDALLON 42X112G DOBLE BURGER SWIFT | C13: 7790360966797 | D13: 4.704 | E13: 42 | F13: =+VLOOKUP(A13,$AN$3:$AO$109,2,FALSE) -> 25320.574 | H13: =+F13*(1-G13) -> 25320.574 | I13: =+H13/E13 -> 602.87081 | J13: =+I13*J$3 -> 126.60287 | K13: =+I13+J13 -> 729.47368 | L13: =+K13*L$3 -> 240.72632 | M13: =+K13+L13 -> 970.2 | N13: =+M13*N$3 -> 388.08 | O13: =+M13+N13 -> 1358.28 | P13: =H13/Q13-1 -> 0 | Q13: 25320.574 | AI13: 19573.728 | AJ13: =+(H13-AI13)/AI13 -> 0.2936 | AN13: 100516325 | AO13: 27224.602
A14: 100516325 | B14: MEDALLON DOBLE BURGER 2X2 | C14: 7790360967763 | D14: 4.704 | E14: 21 | F14: =+VLOOKUP(A14,$AN$3:$AO$109,2,FALSE) -> 27224.602 | H14: =+F14*(1-G14) -> 27224.602 | I14: =+H14/E14 -> 1296.4096 | J14: =+I14*J$3 -> 272.24602 | K14: =+I14+J14 -> 1568.6556 | L14: =+K14*L$3 -> 517.65635 | M14: =+K14+L14 -> 2086.312 | N14: =+M14*N$3 -> 834.52479 | O14: =+M14+N14 -> 2920.8368 | P14: =H14/Q14-1 -> 0 | Q14: 27224.602 | AI14: 25928.192 | AJ14: =+(H14-AI14)/AI14 -> 0.05 | AN14: 100021676 | AO14: 64129.004
A15: 100021676 | B15: HAMBURGUESA 30X250g CLASICA "XL" SWIFT | C15: 7790360967411 | D15: 7.5 | E15: 30 | F15: =+VLOOKUP(A15,$AN$3:$AO$109,2,FALSE) -> 64129.004 | H15: =+F15*(1-G15) -> 64129.004 | I15: =+H15/E15 -> 2137.6335 | J15: =+I15*J$3 -> 448.90303 | K15: =+I15+J15 -> 2586.5365 | L15: =+K15*L$3 -> 853.55704 | M15: =+K15+L15 -> 3440.0935 | N15: =+M15*N$3 -> 1376.0374 | O15: =+M15+N15 -> 4816.131 | P15: =H15/Q15-1 -> 0 | Q15: 64129.004 | AI15: 53108.906 | AJ15: =+(H15-AI15)/AI15 -> 0.2075 | AN15: 100516008 | AO15: 62722.098
A16: 100516008 | B16: HAMBURGUESA 24X2X120g CASERA SWIFT | C16: 7790360967701 | D16: 5.76 | E16: 24 | F16: =+VLOOKUP(A16,$AN$3:$AO$109,2,FALSE) -> 62722.098 | G16: 0.0909 | H16: =+F16*(1-G16) -> 57020.659 | I16: =+H16/E16 -> 2375.8608 | J16: =+I16*J$3 -> 498.93077 | K16: =+I16+J16 -> 2874.7916 | L16: =+K16*L$3 -> 948.68121 | M16: =+K16+L16 -> 3823.4728 | N16: =+M16*N$3 -> 1529.3891 | O16: =+M16+N16 -> 5352.8619 | P16: =H16/Q16-1 -> 0 | Q16: 57020.659 | S16: OFERTA Compra 10 FLOW + 1 de regalo | AI16: 56890.791 | AJ16: =+(H16-AI16)/AI16 -> 0.00228275 | AN16: 100520834 | AO16: 61418.235
A17: 100520834 | B17: HAMBURGUESA X-TREMA 36 x 185 grs | C17: 7790360980618 | D17: 6.66 | E17: 36 | F17: =+VLOOKUP(A17,$AN$3:$AO$109,2,FALSE) -> 61418.235 | H17: =+F17*(1-G17) -> 61418.235 | I17: =+H17/E17 -> 1706.0621 | J17: =+I17*J$3 -> 358.27304 | K17: =+I17+J17 -> 2064.3351 | L17: =+K17*L$3 -> 681.23059 | M17: =+K17+L17 -> 2745.5657 | N17: =+M17*N$3 -> 1098.2263 | O17: =+M17+N17 -> 3843.792 | P17: =H17/Q17-1 -> 0 | Q17: 61418.235 | AI17: 55708.15 | AJ17: =+(H17-AI17)/AI17 -> 0.1025 | AN17: 100021644 | AO17: 21516.282
A18: 100021680 | B18: HAMBURGUESAS 18X2X120g CLL BRA/ARG | C18: 7790360967688 | D18: 4.32 | E18: 18 | F18: =+VLOOKUP(A18,$AN$3:$AO$109,2,FALSE) -> #N/A | H18: =+F18*(1-G18) -> #N/A | I18: =+H18/E18 -> #N/A | J18: =+I18*J$3 -> #N/A | K18: =+I18+J18 -> #N/A | L18: =+K18*L$3 -> #N/A | M18: =+K18+L18 -> #N/A | N18: =+M18*N$3 -> #N/A | O18: =+M18+N18 -> #N/A | P18: =H18/Q18-1 -> #N/A | Q18: 48105.264 | AI18: 45814.537 | AJ18: =+(H18-AI18)/AI18 -> #N/A | AN18: 100021677 | AO18: 16253.297
A19: 100021644 | B19: MEDALLON 42X112G LA BLANCA | C19: 7790360008541 | D19: 4.704 | E19: 42 | F19: =+VLOOKUP(A19,$AN$3:$AO$109,2,FALSE) -> 21516.282 | G19: 0.1 | H19: =+F19*(1-G19) -> 19364.654 | I19: =+H19/E19 -> 461.06319 | J19: =+I19*J$3 -> 96.823269 | K19: =+I19+J19 -> 557.88646 | L19: =+K19*0.3 -> 167.36594 | M19: =+K19+L19 -> 725.25239 | N19: =+M19*0.35 -> 253.83834 | O19: =+M19+N19 -> 979.09073 | P19: =H19/Q19-1 -> -0.0010570825 | Q19: 19385.146 | S19: Dcto a px en factura para oferta $980 vs $1.100 Friar | AI19: 14418.309 | AJ19: =+(H19-AI19)/AI19 -> 0.34305999 | AN19: 100021638 | AO19: 49008.427
A20: 100021677 | B20: MEDALLON 12x4X69G LA BLANCA | C20: 7790360967404 | D20: 3.312 | E20: 12 | F20: =+VLOOKUP(A20,$AN$3:$AO$109,2,FALSE) -> 16253.297 | H20: =+F20*(1-G20) -> 16253.297 | I20: =+H20/E20 -> 1354.4415 | J20: =+I20*J$3 -> 284.4327 | K20: =+I20+J20 -> 1638.8742 | L20: =+K20*0.3 -> 491.66225 | M20: =+K20+L20 -> 2130.5364 | N20: =+M20*N$3 -> 852.21456 | O20: =+M20+N20 -> 2982.751 | P20: =H20/Q20-1 -> 0.05 | Q20: 15479.331 | AI20: 13777.776 | AJ20: =+(H20-AI20)/AI20 -> 0.179675 | AN20: 100021575 | AO20: 39802.191
A21: 100021638 | B21: MEDALLONES 60X80g "SWIFT BURGER" PARRILLERAS FAMILY | C21: 7790360026699 | D21: 4.8 | E21: 60 | F21: =+VLOOKUP(A21,$AN$3:$AO$109,2,FALSE) -> 49008.427 | H21: =+F21*(1-G21) -> 49008.427 | I21: =+H21/E21 -> 816.80712 | J21: =+I21*J$3 -> 171.5295 | K21: =+I21+J21 -> 988.33661 | L21: =+K21*L$3 -> 326.15108 | M21: =+K21+L21 -> 1314.4877 | N21: =+M21*N$3 -> 525.79508 | O21: =+M21+N21 -> 1840.2828 | P21: =H21/Q21-1 -> 0 | Q21: 49008.427 | AI21: 44452.088 | AJ21: =+(H21-AI21)/AI21 -> 0.1025 | AN21: 100021514 | AO21: 36576.95
A22: 100021575 | B22: MEDALLONES 60X69g "SWIFT BURGER"PARRILLERAS FAMILY | C22: 7790360007032 | D22: 4.14 | E22: 60 | F22: =+VLOOKUP(A22,$AN$3:$AO$109,2,FALSE) -> 39802.191 | H22: =+F22*(1-G22) -> 39802.191 | I22: =+H22/E22 -> 663.36986 | J22: =+I22*J$3 -> 139.30767 | K22: =+I22+J22 -> 802.67753 | L22: =+K22*L$3 -> 264.88358 | M22: =+K22+L22 -> 1067.5611 | N22: =+M22*N$3 -> 427.02444 | O22: =+M22+N22 -> 1494.5856 | P22: =H22/Q22-1 -> 0 | Q22: 39802.191 | Z22: 7732.76 | AI22: 36101.761 | AJ22: =+(H22-AI22)/AI22 -> 0.1025 | AN22: 100516208 | AO22: 41975.344
A23: 100021514 | B23: MEDALLON 60X69G CARNE VACUNA | C23: 7790360006943 | D23: 4.14 | E23: 60 | F23: =+VLOOKUP(A23,$AN$3:$AO$109,2,FALSE) -> 36576.95 | H23: =+F23*(1-G23) -> 36576.95 | I23: =+H23/E23 -> 609.61583 | J23: =+I23*J$3 -> 128.01932 | K23: =+I23+J23 -> 737.63515 | L23: =+K23*L$3 -> 243.4196 | M23: =+K23+L23 -> 981.05475 | N23: =+M23*N$3 -> 392.4219 | O23: =+M23+N23 -> 1373.4766 | P23: =H23/Q23-1 -> 0 | Q23: 36576.95 | Z23: =+Z22*8640 -> 66811046 | AI23: 33176.372 | AJ23: =+(H23-AI23)/AI23 -> 0.1025 | AN23: 100518346 | AO23: 57727.078
A24: 100516208 | B24: MEDALLON 60x80g PARRILLERO MC SWIFT | C24: 7790360968203 | D24: =60*0.08 -> 4.8 | E24: 60 | F24: =+VLOOKUP(A24,$AN$3:$AO$109,2,FALSE) -> 41975.344 | H24: =+F24*(1-G24) -> 41975.344 | I24: =+H24/E24 -> 699.58907 | J24: =+I24*J$3 -> 146.91371 | K24: =+I24+J24 -> 846.50278 | L24: =+K24*L$3 -> 279.34592 | M24: =+K24+L24 -> 1125.8487 | N24: =+M24*N$3 -> 450.33948 | O24: =+M24+N24 -> 1576.1882 | P24: =H24/Q24-1 -> 0 | Q24: 41975.344 | Z24: =+Z23/2 -> 33405523 | AI24: 38072.875 | AJ24: =+(H24-AI24)/AI24 -> 0.1025 | AN24: 100516259 | AO24: 135947.63
A25: 100518346 | B25: MEDALLON 60X109G CARNE VACUNA PARRILLERO SWIFT | C25: 7790360975478 | D25: =60*0.109 -> 6.54 | E25: 60 | F25: =+VLOOKUP(A25,$AN$3:$AO$109,2,FALSE) -> 57727.078 | H25: =+F25*(1-G25) -> 57727.078 | I25: =+H25/E25 -> 962.11796 | J25: =I25*J3 -> 202.04477 | K25: =J25+I25 -> 1164.1627 | L25: =K25*L3 -> 384.1737 | M25: =L25+K25 -> 1548.3364 | N25: =M25*N3 -> 619.33457 | O25: =N25+M25 -> 2167.671 | P25: =H25/Q25-1 -> 0 | Q25: 57727.078 | AI25: 52360.161 | AJ25: =+(H25-AI25)/AI25 -> 0.1025 | AN25: 100518095 | AO25: 64509.932
A26: 100516259 | B26: MEDALLON GIGANTE 48x113.5g | C26: 7790360968340 | D26: 18.16 | E26: 48 | F26: =+VLOOKUP(A26,$AN$3:$AO$109,2,FALSE) -> 135947.63 | H26: =+F26*(1-G26) -> 135947.63 | I26: =+H26/E26 -> 2832.2423 | J26: =+I26*J$3 -> 594.77089 | K26: =+I26+J26 -> 3427.0132 | L26: =+K26*L$3 -> 1130.9144 | M26: =+K26+L26 -> 4557.9276 | N26: =+M26*N$3 -> 1823.171 | O26: =+M26+N26 -> 6381.0986 | P26: =H26/Q26-1 -> 0 | Q26: 135947.63 | AI26: 123308.51 | AJ26: =+(H26-AI26)/AI26 -> 0.1025 | AN26: 100518223 | AO26: 50224.567
A27: 100518095 | B27: HAMBURGUESA 36 X 185 GRS | C27: 7790360974785 | D27: 6.66 | E27: 36 | F27: =+VLOOKUP(A27,$AN$3:$AO$109,2,FALSE) -> 64509.932 | H27: =+F27*(1-G27) -> 64509.932 | I27: =+H27/E27 -> 1791.9426 | J27: =+I27*J$3 -> 376.30794 | K27: =+I27+J27 -> 2168.2505 | L27: =+K27*L$3 -> 715.52266 | M27: =+K27+L27 -> 2883.7732 | N27: =+M27*N$3 -> 1153.5093 | O27: =+M27+N27 -> 4037.2824 | P27: =H27/Q27-1 -> 0 | Q27: 64509.932 | AI27: 58512.41 | AJ27: =+(H27-AI27)/AI27 -> 0.1025
A28: 100518223 | B28: HAMBURGUESA 30x2x106 GRS | C28: 7790360975065 | D28: =60*0.106 -> 6.36 | E28: 30 | F28: =+VLOOKUP(A28,$AN$3:$AO$109,2,FALSE) -> 50224.567 | H28: =+F28*(1-G28) -> 50224.567 | I28: =+H28/E28 -> 1674.1522 | J28: =+I28*J$3 -> 351.57197 | K28: =+I28+J28 -> 2025.7242 | L28: =+K28*L$3 -> 668.48899 | M28: =+K28+L28 -> 2694.2132 | N28: =+M28*N$3 -> 1077.6853 | O28: =+M28+N28 -> 3771.8985 | P28: =H28/Q28-1 -> 0 | Q28: 50224.567 | AI28: 45555.163 | AJ28: =+(H28-AI28)/AI28 -> 0.1025 | AN28: 100522204 | AO28: 26630.922
F29: =+VLOOKUP(A29,$AN$3:$AO$109,2,FALSE) -> #N/A | H29: =+F29*(1-G29) -> #N/A | I29: =+H29/E29 -> #N/A | P29: =H29/Q29-1 -> #N/A | Q29: #N/A | Y29: SEPT | Z29: SEPT | AB29: PATY VIENA | AC29: VIENISSIMA | AD29: PALADINI | AE29: FRIAR | AI29: #N/A | AJ29: =+(H29-AI29)/AI29 -> #N/A | AN29: 100522205 | AO29: 25299.376
A30: 100022085 | B30: SALCHICHAS 24X6 SWIFT | C30: 7790360000132 | D30: 5.4 | E30: 24 | F30: =+VLOOKUP(A30,$AN$3:$AO$109,2,FALSE) -> #N/A | G30: 0.16666667 | H30: =+F30*(1-G30) -> #N/A | I30: =+H30/E30 -> #N/A | J30: =+I30*J$3 -> #N/A | K30: =+I30+J30 -> #N/A | L30: =+K30*0.3 -> #N/A | M30: =+K30+L30 -> #N/A | N30: =+M30*N$3 -> #N/A | O30: =+M30+N30 -> #N/A | P30: =H30/Q30-1 -> #N/A | Q30: 24411.679 | S30: compra 10 estuches + 2 de regalo ----> OFERTA $2.050 público | Y30: 1850 | Z30: =+Y30 -> 1850 | AB30: 2295 | AC30: 2518 | AD30: 2518 | AE30: 1328 | AI30: 19706.882 | AJ30: =+(H30-AI30)/AI30 -> #N/A | AN30: 100516849 | AO30: 20506.556
A31: 100522204 | B31: SALCHICHAS 24X6 SWIFT | C31: 7790360983947 | D31: 5.4 | E31: 24 | F31: =+VLOOKUP(A31,$AN$3:$AO$109,2,FALSE) -> 26630.922 | G31: 0.16666667 | H31: =+F31*(1-G31) -> 22192.435 | I31: =+H31/E31 -> 924.68479 | J31: =+I31*J$3 -> 194.18381 | K31: =+I31+J31 -> 1118.8686 | L31: =+K31*0.309 -> 345.7304 | M31: =+K31+L31 -> 1464.599 | N31: =+M31*N$3 -> 585.8396 | O31: =+M31+N31 -> 2050.4386 | P31: =H31/Q31-1 -> -0.090909091 | Q31: 24411.679 | S31: Oferta: compra 10 estuches + 2 de regalo ----> OFERTA $2.050 público | AN31: 100522206 | AO31: 60366.789
A32: 100022072 | B32: SALCHICHAS 12X12 SWIFT | C32: 7790360024541 | D32: 5.4 | E32: 12 | F32: =+VLOOKUP(A32,$AN$3:$AO$109,2,FALSE) -> #N/A | G32: 0.16666667 | H32: =+F32*(1-G32) -> #N/A | I32: =+H32/E32 -> #N/A | J32: =+I32*J$3 -> #N/A | K32: =+I32+J32 -> #N/A | L32: =+K32*0.328678 -> #N/A | M32: =+K32+L32 -> #N/A | N32: =+M32*N$3 -> #N/A | O32: =+M32+N32 -> #N/A | P32: =H32/Q32-1 -> #N/A | Q32: 23191.095 | S32: Conveniencia vs 22085: Oferta $3.899 | Y32: 3400 | Z32: =+Y32 -> 3400 | AB32: 4590 | AC32: 5045 | AI32: 18109.027 | AJ32: =+(H32-AI32)/AI32 -> #N/A | AN32: 100022058 | AO32: 15595.314
A33: 100522205 | B33: SALCHICHAS 12X12 SWIFT | C33: 7790360983954 | D33: 5.4 | E33: 12 | F33: =+VLOOKUP(A33,$AN$3:$AO$109,2,FALSE) -> 25299.376 | G33: 0.16666667 | H33: =+F33*(1-G33) -> 21082.813 | I33: =+H33/E33 -> 1756.9011 | J33: =+I33*J$3 -> 368.94923 | K33: =+I33+J33 -> 2125.8503 | L33: =+K33*0.31 -> 659.01361 | M33: =+K33+L33 -> 2784.8639 | N33: =+M33*N$3 -> 1113.9456 | O33: =+M33+N33 -> 3898.8095 | P33: =H33/Q33-1 -> -0.090909091 | Q33: 23191.095 | S33: Conveniencia vs 22085: Oferta $3.899 | AN33: 100518151 | AO33: 69421.808
A34: 100516849 | B34: SALCHICHAS SIN PIEL 24X6 "SWIFT KIDS" X 190 g | C34: 7790360970053 | D34: 4.56 | E34: 24 | F34: =+VLOOKUP(A34,$AN$3:$AO$109,2,FALSE) -> 20506.556 | H34: =+F34*(1-G34) -> 20506.556 | I34: =+H34/E34 -> 854.43982 | J34: =+I34*J$3 -> 179.43236 | K34: =+I34+J34 -> 1033.8722 | L34: =+K34*0.306 -> 316.36489 | M34: =+K34+L34 -> 1350.2371 | N34: =+M34*N$3 -> 540.09483 | O34: =+M34+N34 -> 1890.3319 | P34: =H34/Q34-1 -> 0 | Q34: 20506.556 | S34: Oferta incluida en lista: $1.890 | Y34: 1600 | Z34: 1650 | AA34: PATY FUN | AB34: 1745 | AI34: 17043.79 | AJ34: =+(H34-AI34)/AI34 -> 0.20316875
A35: 100022039 | B35: SALCHICHAS LARGAS 10 x 12 SWIFT INSTITUCIONAL | C35: 7790360007063 | D35: 8.7 | E35: 10 | F35: =+VLOOKUP(A35,$AN$3:$AO$109,2,FALSE) -> #N/A | H35: =+F35*(1-G35) -> #N/A | I35: =+H35/E35 -> #N/A | J35: =+I35*J$3 -> #N/A | K35: =+I35+J35 -> #N/A | L35: =+K35*L$3 -> #N/A | M35: =+K35+L35 -> #N/A | N35: =+M35*N$3 -> #N/A | O35: =+M35+N35 -> #N/A | P35: =H35/Q35-1 -> #N/A | Q35: 60366.789 | AB35: ICB | AC35: 66 | AD35: PANCHIN | AE35: NUTRITE | AI35: 46618.161 | AJ35: =+(H35-AI35)/AI35 -> #N/A | AN35: 100021000 | AO35: 12962.274
A36: 100522206 | B36: SALCHICHAS LARGAS 10 x 12 SWIFT INSTITUCIONAL | C36: 7790360983961 | D36: 8.7 | E36: 10 | F36: =+VLOOKUP(A36,$AN$3:$AO$109,2,FALSE) -> 60366.789 | H36: =+F36*(1-G36) -> 60366.789 | I36: =+H36/E36 -> 6036.6789 | J36: =+I36*J$3 -> 1267.7026 | K36: =+I36+J36 -> 7304.3815 | L36: =+K36*L$3 -> 2410.4459 | M36: =+K36+L36 -> 9714.8274 | N36: =+M36*N$3 -> 3885.931 | O36: =+M36+N36 -> 13600.758 | Q36: 60366.789 | AN36: 100021001 | AO36: 12962.274
A37: 100022058 | B37: SALCHICHAS SIN PIEL "LA BLANCA" 24X6X190 Grs; | C37: 7790360026002 | D37: 4.56 | E37: 24 | F37: =+VLOOKUP(A37,$AN$3:$AO$109,2,FALSE) -> 15595.314 | H37: =+F37*(1-G37) -> 15595.314 | I37: =+H37/E37 -> 649.80474 | J37: =+I37*J$3 -> 136.459 | K37: =+I37+J37 -> 786.26374 | L37: =+K37*0.3 -> 235.87912 | M37: =+K37+L37 -> 1022.1429 | N37: =+M37*N$3 -> 408.85714 | O37: =+M37+N37 -> 1431 | P37: =H37/Q37-1 -> 0.06 | Q37: 14712.56 | Y37: 1090 | Z37: 1090 | AA37: MANTENEMOS PX | AB37: 1044 | AC37: 887 | AD37: 1069 | AE37: 988 | AI37: 11611.082 | AJ37: =+(H37-AI37)/AI37 -> 0.34314044 | AN37: 100522277 | AO37: 12962.274
A38: 100518151 | B38: SALCHICHAS LARGAS 10 x 12 x 870g | C38: 7790360974990 | D38: 8.7 | E38: 10 | F38: =+VLOOKUP(A38,$AN$3:$AO$109,2,FALSE) -> 69421.808 | H38: =+F38*(1-G38) -> 69421.808 | I38: =+H38/E38 -> 6942.1808 | J38: =+I38*J$3 -> 1457.858 | K38: =+I38+J38 -> 8400.0387 | L38: =+K38*0.3 -> 2520.0116 | M38: =+K38+L38 -> 10920.05 | N38: =+M38*N$3 -> 4368.0201 | O38: =+M38+N38 -> 15288.071 | P38: =H38/Q38-1 -> 0 | Q38: 69421.808 | Z38: =+Z37*24 -> 26160 | AI38: 53610.885 | AJ38: =+(H38-AI38)/AI38 -> 0.29492 | AN38: 100522333 | AO38: 12962.274
F39: =+VLOOKUP(A39,$AN$3:$AO$109,2,FALSE) -> #N/A | H39: =+F39*(1-G39) -> #N/A | I39: =+H39/E39 -> #N/A | J39: 0.21 | L39: 0.22 | N39: 0.35 | P39: =H39/Q39-1 -> #N/A | Q39: #N/A | Z39: =+Z38/1.21/1.33/1.4 -> 11611.082 | AA39: =+Z32*12 -> 40800 | AI39: #N/A | AJ39: =+(H39-AI39)/AI39 -> #N/A | AN39: 100021045 | AO39: 12962.274
A40: 100021000 | B40: PATE DE FOIE 24X90G SWIFT | C40: 7790360720382 | D40: 2.16 | E40: 24 | F40: =+VLOOKUP(A40,$AN$3:$AO$109,2,FALSE) -> 12962.274 | H40: =+F40*(1-G40) -> 12962.274 | I40: =+H40/E40 -> 540.09474 | J40: =+I40*J$3 -> 113.41989 | K40: =+I40+J40 -> 653.51463 | L40: =+K40*L$39 -> 143.77322 | M40: =+K40+L40 -> 797.28785 | N40: =+M40*N$39 -> 279.05075 | O40: =+M40+N40 -> 1076.3386 | P40: =H40/Q40-1 -> 0.05 | Q40: 12345.023 | Z40: =+F37-Z39 -> 3984.2318 | AA40: =+AA39/1.21/1.33/1.4 -> 18109.027 | AI40: 10353.088 | AJ40: =+(H40-AI40)/AI40 -> 0.25202 | AN40: 100021004 | AO40: 12962.274
...

Sheet NOA
H1: =10700*1.05 -> 11235 | Z1: ACCIÓN VIA NC: COMBO CLASICA 2 X 80 + CHORIZOS
A2: Código | B2: Descripción | C2: EAN | D2: Kg. x Caja | E2: Cant. X Caja | F2: Precio de Factura | G2: Dcto | H2: Precio de Factura | I2: Precio Neto estuche en factura | J2: IVA | K2: Px Unitario IVA Inc | L2: M-up Dx | M2: Px Unitario Minorista | N2: M-up Minorista | O2: Px Unitario Público | Q2: Enero | S2: OFERTAS Y ACCIONES | Z2: DCTO (%) | AA2: Px ACCIÓN CAJA ($) | AB2: Px Acción estuche ($) | AC2: Px oferta (%) | AD2: CUPO (Cajas) | AE2: CONDICIÓN | AG2: SEP | AH2: Var %
J3: 0.21 | L3: 0.33 | N3: 0.4
A4: 100021632 | B4: HAMBURGUESAS 30x160g CLASICA x2 SWIFT | C4: 7790360026606 | D4: 4.8 | E4: 30 | F4: =+VLOOKUP(A4,$AL$4:$AM$110,2,FALSE) -> 36223.374 | H4: =+F4*(1-G4) -> 36223.374 | I4: =+H4/E4 -> 1207.4458 | J4: =+I4*J$3 -> 253.56362 | K4: =+I4+J4 -> 1461.0094 | L4: =+K4*L$3 -> 482.1331 | M4: =+K4+L4 -> 1943.1425 | N4: =+M4*N$3 -> 777.257 | O4: =+M4+N4 -> 2720.3995 | P4: =H4/Q4-1 -> 0.05 | Q4: 34498.451 | Y4: =+Z4*H4 -> 3622.3374 | Z4: 0.1 | AA4: =+H4*(1-Z4) -> 32601.036 | AB4: =+AA4/E4 -> 1086.7012 | AC4: =+AB4*1.21*1.3*1.4 -> 2393.1334 | AD4: VER CUPOS | AE4: Con la compra de 1 caja de 21632 + 2 unidades de Chorizos --> 10% de dcto en ambos SKU | AG4: 28670.618 | AH4: =+(H4-AG4)/AG4 -> 0.26343193 | AL4: 100021632 | AM4: 36223.374
A5: 100021652 | B5: HAMBURGUESA 18X4X80G CLASICA SWIFT | C5: 7790360026576 | D5: 5.76 | E5: 18 | F5: =+VLOOKUP(A5,$AL$4:$AM$110,2,FALSE) -> 49208.688 | H5: =+F5*(1-G5) -> 49208.688 | I5: =+H5/E5 -> 2733.816 | J5: =+I5*J$3 -> 574.10136 | K5: =+I5+J5 -> 3307.9174 | L5: =+K5*L$3 -> 1091.6127 | M5: =+K5+L5 -> 4399.5301 | N5: =+M5*N$3 -> 1759.812 | O5: =+M5+N5 -> 6159.3421 | P5: =H5/Q5-1 -> 0 | Q5: 49208.688 | AG5: 41713.767 | AH5: =+(H5-AG5)/AG5 -> 0.179675 | AL5: 100021652 | AM5: 49208.688
A6: 100021631 | B6: HAMBURGUESA 8X12X80G CLASICA SWIFT | C6: 7790360026590 | D6: 7.68 | E6: 8 | F6: =+VLOOKUP(A6,$AL$4:$AM$110,2,FALSE) -> 60717.274 | H6: =+F6*(1-G6) -> 60717.274 | I6: =+H6/E6 -> 7589.6592 | J6: =+I6*J$3 -> 1593.8284 | K6: =+I6+J6 -> 9183.4877 | L6: =+K6*L$3 -> 3030.5509 | M6: =+K6+L6 -> 12214.039 | N6: =+M6*N$3 -> 4885.6154 | O6: =+M6+N6 -> 17099.654 | P6: =H6/Q6-1 -> 0 | Q6: 60717.274 | AG6: 61026.747 | AH6: =+(H6-AG6)/AG6 -> -0.0050711089 | AL6: 100021631 | AM6: 60717.274
A7: 100021630 | B7: HAMBURGUESA 6X20X80G CLASICA SWIFT | C7: 7790360026583 | D7: 9.6 | E7: 6 | F7: =+VLOOKUP(A7,$AL$4:$AM$110,2,FALSE) -> 75896.592 | H7: =+F7*(1-G7) -> 75896.592 | I7: =+H7/E7 -> 12649.432 | J7: =+I7*J$3 -> 2656.3807 | K7: =+I7+J7 -> 15305.813 | L7: =+K7*L$3 -> 5050.9182 | M7: =+K7+L7 -> 20356.731 | N7: =+M7*N$3 -> 8142.6924 | O7: =+M7+N7 -> 28499.423 | P7: =H7/Q7-1 -> 0 | Q7: 75896.592 | AG7: 76268.328 | AH7: =+(H7-AG7)/AG7 -> -0.0048740543 | AL7: 100021630 | AM7: 75896.592
A8: 100021653 | B8: MEDALLON 18X4X80G PARRILLERO SWIFT | C8: 7790360026682 | D8: 5.76 | E8: 18 | F8: =+VLOOKUP(A8,$AL$4:$AM$110,2,FALSE) -> 49208.688 | H8: =+F8*(1-G8) -> 49208.688 | I8: =+H8/E8 -> 2733.816 | J8: =+I8*J$3 -> 574.10136 | K8: =+I8+J8 -> 3307.9174 | L8: =+K8*L$3 -> 1091.6127 | M8: =+K8+L8 -> 4399.5301 | N8: =+M8*N$3 -> 1759.812 | O8: =+M8+N8 -> 6159.3421 | P8: =H8/Q8-1 -> 0 | Q8: 49208.688 | AG8: 49250.373 | AH8: =+(H8-AG8)/AG8 -> -0.0008463821 | AL8: 100021653 | AM8: 49208.688
A9: 100516169 | B9: MEDALLONES 18X4X80G SWIFT RECETA ESPECIAL | C9: 7790360967961 | D9: 5.76 | E9: 18 | F9: =+VLOOKUP(A9,$AL$4:$AM$110,2,FALSE) -> 45373.852 | H9: =+F9*(1-G9) -> 45373.852 | I9: =+H9/E9 -> 2520.7695 | J9: =+I9*J$3 -> 529.3616 | K9: =+I9+J9 -> 3050.1311 | L9: =+K9*L$3 -> 1006.5433 | M9: =+K9+L9 -> 4056.6744 | N9: =+M9*N$3 -> 1622.6698 | O9: =+M9+N9 -> 5679.3442 | P9: =H9/Q9-1 -> 0 | Q9: 45373.852 | AG9: 41155.421 | AH9: =+(H9-AG9)/AG9 -> 0.1025 | AL9: 100516169 | AM9: 45373.852
A10: 100520337 | B10: MEDALLON BURGER SWIFT MEGA 30 x 160 g | C10: 7790360977960 | D10: 4.8 | E10: 30 | F10: =+VLOOKUP(A10,$AL$4:$AM$110,2,FALSE) -> 28211.35 | H10: =+F10*(1-G10) -> 28211.35 | I10: =+H10/E10 -> 940.37834 | J10: =+I10*J$3 -> 197.47945 | K10: =+I10+J10 -> 1137.8578 | L10: =+K10*L$3 -> 375.49307 | M10: =+K10+L10 -> 1513.3509 | N10: =+M10*N$3 -> 605.34035 | O10: =+M10+N10 -> 2118.6912 | P10: =H10/Q10-1 -> 0.05 | Q10: 26867.953 | AG10: 24370.025 | AH10: =+(H10-AG10)/AG10 -> 0.157625 | AL10: 100520337 | AM10: 28211.35
A11: 100021503 | B11: Medallón CAJITA 12x4 69 grs | C11: 7790360966841 | D11: 3.312 | E11: 12 | F11: =+VLOOKUP(A11,$AL$4:$AM$110,2,FALSE) -> 19950.311 | G11: 0.090909091 | H11: =+F11*(1-G11) -> 18136.646 | I11: =+H11/E11 -> 1511.3872 | J11: =+I11*J$3 -> 317.3913 | K11: =+I11+J11 -> 1828.7785 | L11: =+K11*L$3 -> 603.49689 | M11: =+K11+L11 -> 2432.2754 | N11: =+M11*N$3 -> 972.91015 | O11: =+M11+N11 -> 3405.1855 | P11: =H11/Q11-1 -> 0.090821825 | Q11: 16626.589 | S11: Contra 10 estuches + 1 de regalo | AG11: 16911.701 | AH11: =+(H11-AG11)/AG11 -> 0.072431818 | AL11: 100021503 | AM11: 19950.311
A12: 100516201 | B12: HAMBURGUESA 8X12X69G BURGER SWIFT | C12: 7790360968548 | D12: 6.624 | E12: 8 | F12: =+VLOOKUP(A12,$AL$4:$AM$110,2,FALSE) -> 39562.393 | H12: =+F12*(1-G12) -> 39562.393 | I12: =+H12/E12 -> 4945.2992 | J12: =+I12*J$3 -> 1038.5128 | K12: =+I12+J12 -> 5983.812 | L12: =+K12*L$3 -> 1974.658 | M12: =+K12+L12 -> 7958.4699 | N12: =+M12*N$3 -> 3183.388 | O12: =+M12+N12 -> 11141.858 | P12: =H12/Q12-1 -> 0.05 | Q12: 37678.47 | AG12: 34175.483 | AH12: =+(H12-AG12)/AG12 -> 0.157625 | AL12: 100516201 | AM12: 39562.393
A13: 100021643 | B13: MEDALLON 42X112G DOBLE BURGER SWIFT | C13: 7790360966797 | D13: 4.704 | E13: 42 | F13: =+VLOOKUP(A13,$AL$4:$AM$110,2,FALSE) -> 27190.844 | H13: =+F13*(1-G13) -> 27190.844 | I13: =+H13/E13 -> 647.40104 | J13: =+I13*J$3 -> 135.95422 | K13: =+I13+J13 -> 783.35526 | L13: =+K13*L$3 -> 258.50724 | M13: =+K13+L13 -> 1041.8625 | N13: =+M13*N$3 -> 416.745 | O13: =+M13+N13 -> 1458.6075 | P13: =H13/Q13-1 -> 0 | Q13: 27190.844 | AG13: 25896.042 | AH13: =+(H13-AG13)/AG13 -> 0.05 | AL13: 100021643 | AM13: 27190.844
A14: 100516325 | B14: MEDALLON DOBLE BURGER 2X2 | C14: 7790360967763 | D14: 4.704 | E14: 21 | F14: =+VLOOKUP(A14,$AL$4:$AM$110,2,FALSE) -> 26444.818 | H14: =+F14*(1-G14) -> 26444.818 | I14: =+H14/E14 -> 1259.2771 | J14: =+I14*J$3 -> 264.44818 | K14: =+I14+J14 -> 1523.7253 | L14: =+K14*L$3 -> 502.82933 | M14: =+K14+L14 -> 2026.5546 | N14: =+M14*N$3 -> 810.62184 | O14: =+M14+N14 -> 2837.1764 | P14: =H14/Q14-1 -> 0 | Q14: 26444.818 | AG14: 23986.23 | AH14: =+(H14-AG14)/AG14 -> 0.1025 | AL14: 100516325 | AM14: 26444.818
A15: 100021676 | B15: HAMBURGUESA 30X250g CLASICA "XL" SWIFT | C15: 7790360967411 | D15: 7.5 | E15: 30 | F15: =+VLOOKUP(A15,$AL$4:$AM$110,2,FALSE) -> 58407.612 | G15: 0.088 | H15: =+F15*(1-G15) -> 53267.743 | I15: =+H15/E15 -> 1775.5914 | J15: =+I15*J$3 -> 372.8742 | K15: =+I15+J15 -> 2148.4656 | L15: =+K15*0.33 -> 708.99365 | M15: =+K15+L15 -> 2857.4593 | N15: =+M15*N$3 -> 1142.9837 | O15: =+M15+N15 -> 4000.443 | P15: =H15/Q15-1 -> -0.088 | Q15: 58407.612 | S15: Dcto por posicionamiento para oferta a $3.999 | AG15: 48161.297 | AH15: =+(H15-AG15)/AG15 -> 0.106028 | AL15: 100021676 | AM15: 58407.612
A16: 100516008 | B16: HAMBURGUESA 24X2X120g CASERA SWIFT | C16: 7790360967701 | D16: 5.76 | E16: 24 | F16: =+VLOOKUP(A16,$AL$4:$AM$110,2,FALSE) -> 57960.92 | G16: 0.083333333 | H16: =+F16*(1-G16) -> 53130.844 | I16: =+H16/E16 -> 2213.7851 | J16: =+I16*J$3 -> 464.89488 | K16: =+I16+J16 -> 2678.68 | L16: =+K16*L$3 -> 883.96441 | M16: =+K16+L16 -> 3562.6444 | N16: =+M16*N$3 -> 1425.0578 | O16: =+M16+N16 -> 4987.7022 | P16: =H16/Q16-1 -> 0.0083232501 | Q16: 52692.273 | S16: OFERTA Compra 10 FLOW + 1 de regalo | AG16: 52572.263 | AH16: =+(H16-AG16)/AG16 -> 0.010625 | AL16: 100516008 | AM16: 57960.92
A17: 100520834 | B17: HAMBURGUESA X-TREMA 36 x 185 grs | C17: 7790360980618 | D17: 6.66 | E17: 36 | F17: =+VLOOKUP(A17,$AL$4:$AM$110,2,FALSE) -> 67713.604 | H17: =+F17*(1-G17) -> 67713.604 | I17: =+H17/E17 -> 1880.9335 | J17: =+I17*J$3 -> 394.99603 | K17: =+I17+J17 -> 2275.9295 | L17: =+K17*L$3 -> 751.05673 | M17: =+K17+L17 -> 3026.9862 | N17: =+M17*N$3 -> 1210.7945 | O17: =+M17+N17 -> 4237.7807 | P17: =H17/Q17-1 -> 0 | Q17: 67713.604 | AG17: 58493.557 | AH17: =+(H17-AG17)/AG17 -> 0.157625 | AL17: 100520834 | AM17: 67713.604
A18: 100021680 | B18: HAMBURGUESAS 18X2X120g CLL BRA/ARG | C18: 7790360967688 | D18: 4.32 | E18: 18 | F18: =+VLOOKUP(A18,$AL$4:$AM$110,2,FALSE) -> #N/A | H18: =+F18*(1-G18) -> #N/A | I18: =+H18/E18 -> #N/A | J18: =+I18*J$3 -> #N/A | K18: =+I18+J18 -> #N/A | L18: =+K18*L$3 -> #N/A | M18: =+K18+L18 -> #N/A | N18: =+M18*N$3 -> #N/A | O18: =+M18+N18 -> #N/A | P18: =H18/Q18-1 -> #N/A | Q18: 51589.616 | AG18: 44565.05 | AH18: =+(H18-AG18)/AG18 -> #N/A | AL18: 100021644 | AM18: 20661.7
A19: 100021644 | B19: MEDALLON 42X112G LA BLANCA | C19: 7790360008541 | D19: 4.704 | E19: 42 | F19: =+VLOOKUP(A19,$AL$4:$AM$110,2,FALSE) -> 20661.7 | H19: =+F19*(1-G19) -> 20661.7 | I19: =+H19/E19 -> 491.94523 | J19: =+I19*J$3 -> 103.3085 | K19: =+I19+J19 -> 595.25373 | L19: =+K19*0.3 -> 178.57612 | M19: =+K19+L19 -> 773.82985 | N19: =+M19*N$3 -> 309.53194 | O19: =+M19+N19 -> 1083.3618 | P19: =H19/Q19-1 -> 0.05 | Q19: 19677.809 | AG19: 15520.307 | AH19: =+(H19-AG19)/AG19 -> 0.33126875 | AL19: 100021677 | AM19: 16816.177
A20: 100021677 | B20: MEDALLON 12x4X69G LA BLANCA | C20: 7790360967404 | D20: 3.312 | E20: 12 | F20: =+VLOOKUP(A20,$AL$4:$AM$110,2,FALSE) -> 16816.177 | H20: =+F20*(1-G20) -> 16816.177 | I20: =+H20/E20 -> 1401.3481 | J20: =+I20*J$3 -> 294.2831 | K20: =+I20+J20 -> 1695.6312 | L20: =+K20*0.3 -> 508.68937 | M20: =+K20+L20 -> 2204.3206 | N20: =+M20*N$3 -> 881.72823 | O20: =+M20+N20 -> 3086.0488 | P20: =H20/Q20-1 -> 0 | Q20: 16816.177 | AG20: 14526.446 | AH20: =+(H20-AG20)/AG20 -> 0.157625 | AL20: 100021638 | AM20: 48130.217
A21: 100021638 | B21: MEDALLONES 60X80g "SWIFT BURGER" PARRILLERAS FAMILY | C21: 7790360026699 | D21: 4.8 | E21: 60 | F21: =+VLOOKUP(A21,$AL$4:$AM$110,2,FALSE) -> 48130.217 | H21: =+F21*(1-G21) -> 48130.217 | I21: =+H21/E21 -> 802.17028 | J21: =+I21*J$3 -> 168.45576 | K21: =+I21+J21 -> 970.62604 | L21: =+K21*L$3 -> 320.30659 | M21: =+K21+L21 -> 1290.9326 | N21: =+M21*N$3 -> 516.37305 | O21: =+M21+N21 -> 1807.3057 | P21: =H21/Q21-1 -> 0 | Q21: 48130.217 | AG21: 41576.691 | AH21: =+(H21-AG21)/AG21 -> 0.157625 | AL21: 100021575 | AM21: 40652.511
A22: 100021575 | B22: MEDALLONES 60X69g "SWIFT BURGER"PARRILLERAS FAMILY | C22: 7790360007032 | D22: 4.14 | E22: 60 | F22: =+VLOOKUP(A22,$AL$4:$AM$110,2,FALSE) -> 40652.511 | H22: =+F22*(1-G22) -> 40652.511 | I22: =+H22/E22 -> 677.54185 | J22: =+I22*J$3 -> 142.28379 | K22: =+I22+J22 -> 819.82564 | L22: =+K22*L$3 -> 270.54246 | M22: =+K22+L22 -> 1090.3681 | N22: =+M22*N$3 -> 436.14724 | O22: =+M22+N22 -> 1526.5153 | P22: =H22/Q22-1 -> 0 | Q22: 40652.511 | AG22: 35117.167 | AH22: =+(H22-AG22)/AG22 -> 0.157625 | AL22: 100021514 | AM22: 37358.366
A23: 100021514 | B23: MEDALLON 60X69G CARNE VACUNA | C23: 7790360006943 | D23: 4.14 | E23: 60 | F23: =+VLOOKUP(A23,$AL$4:$AM$110,2,FALSE) -> 37358.366 | H23: =+F23*(1-G23) -> 37358.366 | I23: =+H23/E23 -> 622.63944 | J23: =+I23*J$3 -> 130.75428 | K23: =+I23+J23 -> 753.39372 | L23: =+K23*L$3 -> 248.61993 | M23: =+K23+L23 -> 1002.0136 | N23: =+M23*N$3 -> 400.80546 | O23: =+M23+N23 -> 1402.8191 | P23: =H23/Q23-1 -> 0 | Q23: 37358.366 | AG23: 32271.561 | AH23: =+(H23-AG23)/AG23 -> 0.157625 | AL23: 100516208 | AM23: 42872.09
A24: 100516208 | B24: MEDALLON 60x80g PARRILLERO MC SWIFT | C24: 7790360968203 | D24: =60*0.08 -> 4.8 | E24: 60 | F24: =+VLOOKUP(A24,$AL$4:$AM$110,2,FALSE) -> 42872.09 | H24: =+F24*(1-G24) -> 42872.09 | I24: =+H24/E24 -> 714.53484 | J24: =+I24*J$3 -> 150.05232 | K24: =+I24+J24 -> 864.58716 | L24: =+K24*L$3 -> 285.31376 | M24: =+K24+L24 -> 1149.9009 | N24: =+M24*N$3 -> 459.96037 | O24: =+M24+N24 -> 1609.8613 | P24: =H24/Q24-1 -> 0 | Q24: 42872.09 | AG24: 37034.524 | AH24: =+(H24-AG24)/AG24 -> 0.157625 | AL24: 100518346 | AM24: 61908.355
A25: 100518346 | B25: MEDALLON 60X109G CARNE VACUNA PARRILLERO SWIFT | C25: 7790360975478 | D25: =60*0.109 -> 6.54 | E25: 60 | F25: =+VLOOKUP(A25,$AL$4:$AM$110,2,FALSE) -> 61908.355 | H25: =+F25*(1-G25) -> 61908.355 | I25: =+H25/E25 -> 1031.8059 | J25: =I25*J3 -> 216.67924 | K25: =J25+I25 -> 1248.4852 | L25: =K25*L3 -> 412.0001 | M25: =L25+K25 -> 1660.4853 | N25: =M25*N3 -> 664.1941 | O25: =N25+M25 -> 2324.6794 | P25: =H25/Q25-1 -> 0 | Q25: 61908.355 | AG25: 53478.765 | AH25: =+(H25-AG25)/AG25 -> 0.157625 | AL25: 100516259 | AM25: 138851.97
A26: 100516259 | B26: MEDALLON GIGANTE 48x113.5g | C26: 7790360968340 | D26: 18.16 | E26: 48 | F26: =+VLOOKUP(A26,$AL$4:$AM$110,2,FALSE) -> 138851.97 | H26: =+F26*(1-G26) -> 138851.97 | I26: =+H26/E26 -> 2892.7493 | J26: =+I26*J$3 -> 607.47736 | K26: =+I26+J26 -> 3500.2267 | L26: =+K26*L$3 -> 1155.0748 | M26: =+K26+L26 -> 4655.3015 | N26: =+M26*N$3 -> 1862.1206 | O26: =+M26+N26 -> 6517.4221 | P26: =H26/Q26-1 -> 0 | Q26: 138851.97 | AG26: 119945.55 | AH26: =+(H26-AG26)/AG26 -> 0.157625 | AL26: 100518095 | AM26: 69182.504
A27: 100518095 | B27: HAMBURGUESA 36 X 185 GRS | C27: 7790360974785 | D27: 6.66 | E27: 36 | F27: =+VLOOKUP(A27,$AL$4:$AM$110,2,FALSE) -> 69182.504 | H27: =+F27*(1-G27) -> 69182.504 | I27: =+H27/E27 -> 1921.7362 | J27: =+I27*J$3 -> 403.5646 | K27: =+I27+J27 -> 2325.3008 | L27: =+K27*L$3 -> 767.34927 | M27: =+K27+L27 -> 3092.6501 | N27: =+M27*N$3 -> 1237.06 | O27: =+M27+N27 -> 4329.7101 | P27: =H27/Q27-1 -> 0 | Q27: 69182.504 | AG27: 59762.448 | AH27: =+(H27-AG27)/AG27 -> 0.157625 | AL27: 100518223 | AM27: 53862.424
A28: 100518223 | B28: HAMBURGUESA 30x2x106 GRS | C28: 7790360975065 | D28: =60*0.106 -> 6.36 | E28: 30 | F28: =+VLOOKUP(A28,$AL$4:$AM$110,2,FALSE) -> 53862.424 | H28: =+F28*(1-G28) -> 53862.424 | I28: =+H28/E28 -> 1795.4141 | J28: =+I28*J$3 -> 377.03697 | K28: =+I28+J28 -> 2172.4511 | L28: =+K28*L$3 -> 716.90886 | M28: =+K28+L28 -> 2889.36 | N28: =+M28*N$3 -> 1155.744 | O28: =+M28+N28 -> 4045.1039 | P28: =H28/Q28-1 -> 0 | Q28: 53862.424 | AG28: 46528.387 | AH28: =+(H28-AG28)/AG28 -> 0.157625
F29: =+VLOOKUP(A29,$AL$4:$AM$110,2,FALSE) -> #N/A | H29: =+F29*(1-G29) -> #N/A | I29: =+H29/E29 -> #N/A | P29: =H29/Q29-1 -> #N/A | Q29: #N/A | Y29: SEP | Z29: OCT | AB29: PATY VIENA | AC29: VIENISSIMA | AD29: PALADINI | AG29: #N/A | AH29: =+(H29-AG29)/AG29 -> #N/A | AL29: 100522204 | AM29: 26630.922
A30: 100022085 | B30: SALCHICHAS 24X6 SWIFT | C30: 7790360000132 | D30: 5.4 | E30: 24 | F30: =+VLOOKUP(A30,$AL$4:$AM$110,2,FALSE) -> #N/A | G30: 0.25 | H30: =+F30*(1-G30) -> #N/A | I30: =+H30/E30 -> #N/A | J30: =+I30*J$3 -> #N/A | K30: =+I30+J30 -> #N/A | L30: =+K30*L$3 -> #N/A | M30: =+K30+L30 -> #N/A | N30: =+M30*N$3 -> #N/A | O30: =+M30+N30 -> #N/A | P30: =H30/Q30-1 -> #N/A | Q30: 19973.192 | S30: Px LISTA: $2.500 + además compra 9 estuches + 2 de regalo ----> OFERTA $1.875 Público | Y30: 1700 | Z30: 1750 | AB30: 1890 | AC30: 2153 | AD30: 2208 | AG30: 18109.027 | AH30: =+(H30-AG30)/AG30 -> #N/A | AL30: 100522205 | AM30: 25299.376
A31: 100522204 | B31: SALCHICHAS 24X6 SWIFT | C31: 7790360983947 | D31: 5.4 | E31: 24 | F31: =+VLOOKUP(A31,$AL$4:$AM$110,2,FALSE) -> 26630.922 | G31: 0.25 | H31: =+F31*(1-G31) -> 19973.192 | I31: =+H31/E31 -> 832.21631 | J31: =+I31*J$3 -> 174.76543 | K31: =+I31+J31 -> 1006.9817 | L31: =+K31*L$3 -> 332.30397 | M31: =+K31+L31 -> 1339.2857 | N31: =+M31*N$3 -> 535.71429 | O31: =+M31+N31 -> 1875 | P31: =H31/Q31-1 -> 0 | Q31: 19973.192 | S31: Px LISTA: $2.500 + además compra 9 estuches + 2 de regalo ----> OFERTA $1.875 Público | AL31: 100516849 | AM31: 17895.98
A32: 100022072 | B32: SALCHICHAS 12X12 SWIFT | C32: 7790360024541 | D32: 5.4 | E32: 12 | F32: =+VLOOKUP(A32,$AL$4:$AM$110,2,FALSE) -> #N/A | G32: 0.2106 | H32: =+F32*(1-G32) -> #N/A | I32: =+H32/E32 -> #N/A | J32: =+I32*J$3 -> #N/A | K32: =+I32+J32 -> #N/A | L32: =+K32*0.30667 -> #N/A | M32: =+K32+L32 -> #N/A | N32: =+M32*N$3 -> #N/A | O32: =+M32+N32 -> #N/A | P32: =H32/Q32-1 -> #N/A | Q32: 18974.532 | S32: Conveniencia vs 22085: Oferta $3.500 | Y32: 3300 | Z32: 3350 | AG32: 17576.409 | AH32: =+(H32-AG32)/AG32 -> #N/A | AL32: 100522206 | AM32: 47623.273
A33: 100522205 | B33: SALCHICHAS 12X12 SWIFT | C33: 7790360983954 | D33: 5.4 | E33: 12 | F33: =+VLOOKUP(A33,$AL$4:$AM$110,2,FALSE) -> 25299.376 | G33: 0.2106 | H33: =+F33*(1-G33) -> 19971.327 | I33: =+H33/E33 -> 1664.2773 | J33: =+I33*J$3 -> 349.49823 | K33: =+I33+J33 -> 2013.7755 | L33: =+K33*0.31239 -> 629.08333 | M33: =+K33+L33 -> 2642.8588 | N33: =+M33*N$3 -> 1057.1435 | O33: =+M33+N33 -> 3700.0024 | P33: =H33/Q33-1 -> 0.052533333 | Q33: 18974.532 | S33: Conveniencia vs 22085: Oferta $3.700 | AL33: 100022058 | AM33: 15595.314
A34: 100516849 | B34: SALCHICHAS SIN PIEL 24X6 "SWIFT KIDS" X 190 g | C34: 7790360970053 | D34: 4.56 | E34: 24 | F34: =+VLOOKUP(A34,$AL$4:$AM$110,2,FALSE) -> 17895.98 | H34: =+F34*(1-G34) -> 17895.98 | I34: =+H34/E34 -> 745.66582 | J34: =+I34*J$3 -> 156.58982 | K34: =+I34+J34 -> 902.25564 | L34: =+K34*L$3 -> 297.74436 | M34: =+K34+L34 -> 1200 | N34: =+M34*N$3 -> 480 | O34: =+M34+N34 -> 1680 | P34: =H34/Q34-1 -> 0.12 | Q34: 15978.553 | S34: Oferta incluida en lista: $1.680 público | Y34: 1450 | Z34: 1500 | AA34: PATY FUN | AB34: 1534 | AG34: 15445.935 | AH34: =+(H34-AG34)/AG34 -> 0.15862069 | AL34: 100518151 | AM34: 58015.64
