Workbook

Sheet Litoral
A2: Código | B2: Descripción | C2: EAN | D2: Kg. x Caja | E2: Cant. X Caja | F2: Precio de Lista | G2: Dcto | H2: Precio de Factura | I2: Precio Neto estuche en factura | J2: IVA | K2: Px Unitario IVA Inc | L2: M-up Dx | M2: Px Unitario Minorista | N2: M-up Minorista | O2: Px Unitario Público | Q2: NOV | AF2: SEP | AG2: %
J3: 0.21 | L3: 0.35 | N3: 0.45
A4: 100021632 | B4: HAMBURGUESAS 30x160g CLASICA x2 SWIFT | C4: 7790360026606 | D4: 4.8 | E4: 30 | F4: =+VLOOKUP(A4,$AK$4:$AL$108,2,FALSE) -> 38344.554 | H4: =+F4*(1-G4) -> 38344.554 | I4: =+H4/E4 -> 1278.1518 | J4: =+I4*J$3 -> 268.41188 | K4: =+I4+J4 -> 1546.5637 | L4: =+K4*L$3 -> 541.29729 | M4: =+K4+L4 -> 2087.861 | N4: =+M4*N$3 -> 939.53744 | O4: =+M4+N4 -> 3027.3984 | P4: =H4/Q4-1 -> 0.08 | Q4: 35504.217 | AF4: 29534.055 | AG4: =+(H4-AF4)/AF4 -> 0.2983166 | AK4: 100021632 | AL4: 38344.554 | AN4: =+Q4/H4 -> 0.92592593
A5: 100021652 | B5: HAMBURGUESA 18X4X80G CLASICA SWIFT | C5: 7790360026576 | D5: 5.76 | E5: 18 | F5: =+VLOOKUP(A5,$AK$4:$AL$108,2,FALSE) -> 46159.859 | H5: =+F5*(1-G5) -> 46159.859 | I5: =+H5/E5 -> 2564.4366 | J5: =+I5*J$3 -> 538.53169 | K5: =+I5+J5 -> 3102.9683 | L5: =+K5*L$3 -> 1086.0389 | M5: =+K5+L5 -> 4189.0072 | N5: =+M5*N$3 -> 1885.0532 | O5: =+M5+N5 -> 6074.0605 | P5: =H5/Q5-1 -> 0.08 | Q5: 42740.61 | AF5: 38042.377 | AG5: =+(H5-AF5)/AF5 -> 0.21338 | AK5: 100021652 | AL5: 46159.859 | AN5: =+Q5/H5 -> 0.92592593
A6: 100021631 | B6: HAMBURGUESA 8X12X80G CLASICA SWIFT | C6: 7790360026590 | D6: 7.68 | E6: 8 | F6: =+VLOOKUP(A6,$AK$4:$AL$108,2,FALSE) -> 58510.949 | H6: =+F6*(1-G6) -> 58510.949 | I6: =+H6/E6 -> 7313.8687 | J6: =+I6*J$3 -> 1535.9124 | K6: =+I6+J6 -> 8849.7811 | L6: =+K6*L$3 -> 3097.4234 | M6: =+K6+L6 -> 11947.204 | N6: =+M6*N$3 -> 5376.242 | O6: =+M6+N6 -> 17323.447 | P6: =H6/Q6-1 -> 0.03 | Q6: 56806.747 | AF6: 63884.504 | AG6: =+(H6-AF6)/AF6 -> -0.084113578 | AK6: 100021631 | AL6: 58510.949 | AN6: =+Q6/H6 -> 0.97087379
A7: 100021630 | B7: HAMBURGUESA 6X20X80G CLASICA SWIFT | C7: 7790360026583 | D7: 9.6 | E7: 6 | F7: =+VLOOKUP(A7,$AK$4:$AL$108,2,FALSE) -> 71718.518 | H7: =+F7*(1-G7) -> 71718.518 | I7: =+H7/E7 -> 11953.086 | J7: =+I7*J$3 -> 2510.1481 | K7: =+I7+J7 -> 14463.234 | L7: =+K7*L$3 -> 5062.1321 | M7: =+K7+L7 -> 19525.367 | N7: =+M7*N$3 -> 8786.415 | O7: =+M7+N7 -> 28311.782 | P7: =H7/Q7-1 -> 0.01 | Q7: 71008.434 | AF7: 79885.735 | AG7: =+(H7-AF7)/AF7 -> -0.10223624 | AK7: 100021630 | AL7: 71718.518 | AN7: =+Q7/H7 -> 0.99009901
A8: 100021653 | B8: MEDALLON 18X4X80G PARRILLERO SWIFT | C8: 7790360026682 | D8: 5.76 | E8: 18 | F8: =+VLOOKUP(A8,$AK$4:$AL$108,2,FALSE) -> 50614.812 | H8: =+F8*(1-G8) -> 50614.812 | I8: =+H8/E8 -> 2811.934 | J8: =+I8*J$3 -> 590.50614 | K8: =+I8+J8 -> 3402.4401 | L8: =+K8*L$3 -> 1190.854 | M8: =+K8+L8 -> 4593.2942 | N8: =+M8*N$3 -> 2066.9824 | O8: =+M8+N8 -> 6660.2765 | P8: =H8/Q8-1 -> 0.08 | Q8: 46865.566 | AF8: 50298.202 | AG8: =+(H8-AF8)/AF8 -> 0.0062946466 | AK8: 100021653 | AL8: 50614.812 | AN8: =+Q8/H8 -> 0.92592593
A9: 100516169 | B9: MEDALLONES 18X4X80G SWIFT RECETA ESPECIAL | C9: 7790360967961 | D9: 5.76 | E9: 18 | F9: =+VLOOKUP(A9,$AK$4:$AL$108,2,FALSE) -> 46670.247 | H9: =+F9*(1-G9) -> 46670.247 | I9: =+H9/E9 -> 2592.7915 | J9: =+I9*J$3 -> 544.48622 | K9: =+I9+J9 -> 3137.2777 | L9: =+K9*L$3 -> 1098.0472 | M9: =+K9+L9 -> 4235.3249 | N9: =+M9*N$3 -> 1905.8962 | O9: =+M9+N9 -> 6141.2212 | P9: =H9/Q9-1 -> 0.08 | Q9: 43213.192 | AF9: 41155.421 | AG9: =+(H9-AF9)/AF9 -> 0.134 | AK9: 100516169 | AL9: 46670.247 | AN9: =+Q9/H9 -> 0.92592593
A10: 100520337 | B10: MEDALLON BURGER SWIFT MEGA 30 x 160 g | C10: 7790360977960 | D10: 4.8 | E10: 30 | F10: =+VLOOKUP(A10,$AK$4:$AL$108,2,FALSE) -> 27112.263 | H10: =+F10*(1-G10) -> 27112.263 | I10: =+H10/E10 -> 903.74209 | J10: =+I10*J$3 -> 189.78584 | K10: =+I10+J10 -> 1093.5279 | L10: =+K10*L$3 -> 382.73478 | M10: =+K10+L10 -> 1476.2627 | N10: =+M10*N$3 -> 664.31822 | O10: =+M10+N10 -> 2140.5809 | P10: =H10/Q10-1 -> 0.08 | Q10: 25103.947 | AF10: 25103.947 | AG10: =+(H10-AF10)/AF10 -> 0.08 | AK10: 100520337 | AL10: 27112.263 | AN10: =+Q10/H10 -> 0.92592593
A11: 100021503 | B11: Medallón CAJITA 12x4 69 grs | C11: 7790360966841 | D11: 3.312 | E11: 12 | F11: =+VLOOKUP(A11,$AK$4:$AL$108,2,FALSE) -> 20700.913 | G11: 0.0833 | H11: =+F11*(1-G11) -> 18976.527 | I11: =+H11/E11 -> 1581.3773 | J11: =+I11*J$3 -> 332.08922 | K11: =+I11+J11 -> 1913.4665 | L11: =+K11*L$3 -> 669.71327 | M11: =+K11+L11 -> 2583.1797 | N11: =+M11*N$3 -> 1162.4309 | O11: =+M11+N11 -> 3745.6106 | P11: =H11/Q11-1 -> 0.08 | Q11: 17570.858 | S11: Contra 11 estuches + 1 de regalo | AF11: 15081.22 | AG11: =+(H11-AF11)/AF11 -> 0.25828861 | AK11: 100021503 | AL11: 20700.913 | AN11: =+Q11/H11 -> 0.92592593
A12: 100516201 | B12: HAMBURGUESA 8X12X69G BURGER SWIFT | C12: 7790360968548 | D12: 6.624 | E12: 8 | F12: =+VLOOKUP(A12,$AK$4:$AL$108,2,FALSE) -> 45229.534 | H12: =+F12*(1-G12) -> 45229.534 | I12: =+H12/E12 -> 5653.6917 | J12: =+I12*J$3 -> 1187.2753 | K12: =+I12+J12 -> 6840.967 | L12: =+K12*L$3 -> 2394.3385 | M12: =+K12+L12 -> 9235.3055 | N12: =+M12*N$3 -> 4155.8875 | O12: =+M12+N12 -> 13391.193 | P12: =H12/Q12-1 -> 0.08 | Q12: 41879.198 | AF12: 37985.667 | AG12: =+(H12-AF12)/AF12 -> 0.1907 | AK12: 100516201 | AL12: 45229.534 | AN12: =+Q12/H12 -> 0.92592593
A13: 100021643 | B13: MEDALLON 42X112G DOBLE BURGER SWIFT | C13: 7790360966797 | D13: 4.704 | E13: 42 | F13: =+VLOOKUP(A13,$AK$4:$AL$108,2,FALSE) -> 27737.901 | H13: =+F13*(1-G13) -> 27737.901 | I13: =+H13/E13 -> 660.42622 | J13: =+I13*J$3 -> 138.68951 | K13: =+I13+J13 -> 799.11572 | L13: =+K13*L$3 -> 279.6905 | M13: =+K13+L13 -> 1078.8062 | N13: =+M13*N$3 -> 485.4628 | O13: =+M13+N13 -> 1564.269 | P13: =H13/Q13-1 -> 0.08 | Q13: 25683.242 | AF13: 23295.457 | AG13: =+(H13-AF13)/AF13 -> 0.1907 | AK13: 100021643 | AL13: 27737.901 | AN13: =+Q13/H13 -> 0.92592593
A14: 100516325 | B14: MEDALLON DOBLE BURGER 2X2 | C14: 7790360967763 | D14: 4.704 | E14: 21 | F14: =+VLOOKUP(A14,$AK$4:$AL$108,2,FALSE) -> 31195.33 | H14: =+F14*(1-G14) -> 31195.33 | I14: =+H14/E14 -> 1485.4919 | J14: =+I14*J$3 -> 311.9533 | K14: =+I14+J14 -> 1797.4452 | L14: =+K14*L$3 -> 629.10582 | M14: =+K14+L14 -> 2426.551 | N14: =+M14*N$3 -> 1091.948 | O14: =+M14+N14 -> 3518.499 | P14: =H14/Q14-1 -> 0.08 | Q14: 28884.565 | AF14: 27509.109 | AG14: =+(H14-AF14)/AF14 -> 0.134 | AK14: 100516325 | AL14: 31195.33 | AN14: =+Q14/H14 -> 0.92592593
A15: 100021676 | B15: HAMBURGUESA 30X250g CLASICA "XL" SWIFT | C15: 7790360967411 | D15: 7.5 | E15: 30 | F15: =+VLOOKUP(A15,$AK$4:$AL$108,2,FALSE) -> 60777.549 | G15: 0.0667 | H15: =+F15*(1-G15) -> 56723.687 | I15: =+H15/E15 -> 1890.7896 | J15: =+I15*J$3 -> 397.06581 | K15: =+I15+J15 -> 2287.8554 | L15: =+K15*L$3 -> 800.74938 | M15: =+K15+L15 -> 3088.6047 | N15: =+M15*N$3 -> 1389.8721 | O15: =+M15+N15 -> 4478.4769 | P15: =H15/Q15-1 -> 0.08 | Q15: 52521.932 | S15: Contra 14 flow + 1 de regalo | AF15: 53595.722 | AG15: =+(H15-AF15)/AF15 -> 0.0583622 | AK15: 100021676 | AL15: 60777.549 | AN15: =+Q15/H15 -> 0.92592593
A16: 100516008 | B16: HAMBURGUESA 24X2X120g CASERA SWIFT | C16: 7790360967701 | D16: 5.76 | E16: 24 | F16: =+VLOOKUP(A16,$AK$4:$AL$108,2,FALSE) -> 50957.087 | G16: 0.0909 | H16: =+F16*(1-G16) -> 46325.088 | I16: =+H16/E16 -> 1930.212 | J16: =+I16*J$3 -> 405.34452 | K16: =+I16+J16 -> 2335.5565 | L16: =+K16*L$3 -> 817.44477 | M16: =+K16+L16 -> 3153.0013 | N16: =+M16*N$3 -> 1418.8506 | O16: =+M16+N16 -> 4571.8518 | P16: =H16/Q16-1 -> 0.02 | Q16: 45416.753 | S16: OFERTA Compra 10 FLOW + 1 de regalo | AF16: 47578.979 | AG16: =+(H16-AF16)/AF16 -> -0.0263539 | AK16: 100516008 | AL16: 50957.087 | AN16: =+Q16/H16 -> 0.98039216
A17: 100520834 | B17: HAMBURGUESA X-TREMA 36 x 185 grs | C17: 7790360980618 | D17: 6.66 | E17: 36 | F17: =+VLOOKUP(A17,$AK$4:$AL$108,2,FALSE) -> 63095.588 | H17: =+F17*(1-G17) -> 63095.588 | I17: =+H17/E17 -> 1752.6552 | J17: =+I17*J$3 -> 368.0576 | K17: =+I17+J17 -> 2120.7128 | L17: =+K17*L$3 -> 742.24949 | M17: =+K17+L17 -> 2862.9623 | N17: =+M17*N$3 -> 1288.333 | O17: =+M17+N17 -> 4151.2954 | P17: =H17/Q17-1 -> 0.08 | Q17: 58421.841 | AF17: 55639.849 | AG17: =+(H17-AF17)/AF17 -> 0.134 | AK17: 100520834 | AL17: 63095.588 | AN17: =+Q17/H17 -> 0.92592593
A18: 100021680 | B18: HAMBURGUESAS 18X2X120g CLL BRA/ARG | C18: 7790360967688 | D18: 4.32 | E18: 18 | F18: =+VLOOKUP(A18,$AK$4:$AL$108,2,FALSE) -> 50536.767 | H18: =+F18*(1-G18) -> 50536.767 | I18: =+H18/E18 -> 2807.5981 | J18: =+I18*J$3 -> 589.59561 | K18: =+I18+J18 -> 3397.1938 | L18: =+K18*L$3 -> 1189.0178 | M18: =+K18+L18 -> 4586.2116 | N18: =+M18*N$3 -> 2063.7952 | O18: =+M18+N18 -> 6650.0068 | P18: =H18/Q18-1 -> 0.08 | Q18: 46793.302 | AF18: 44565.05 | AG18: =+(H18-AF18)/AF18 -> 0.134 | AK18: 100021680 | AL18: 50536.767 | AN18: =+Q18/H18 -> 0.92592593
A19: 100021644 | B19: MEDALLON 42X112G LA BLANCA | C19: 7790360008541 | D19: 4.704 | E19: 42 | F19: =+VLOOKUP(A19,$AK$4:$AL$108,2,FALSE) -> 19172.581 | H19: =+F19*(1-G19) -> 19172.581 | I19: =+H19/E19 -> 456.49003 | J19: =+I19*J$3 -> 95.862907 | K19: =+I19+J19 -> 552.35294 | L19: =+K19*0.3 -> 165.70588 | M19: =+K19+L19 -> 718.05882 | N19: =+M19*N$3 -> 323.12647 | O19: =+M19+N19 -> 1041.1853 | P19: =H19/Q19-1 -> 0.1 | Q19: 17429.619 | AF19: 14434.467 | AG19: =+(H19-AF19)/AF19 -> 0.32825 | AK19: 100021644 | AL19: 19172.581 | AN19: =+Q19/H19 -> 0.90909091
A20: 100021677 | B20: MEDALLON 12x4X69G LA BLANCA | C20: 7790360967404 | D20: 3.312 | E20: 12 | F20: =+VLOOKUP(A20,$AK$4:$AL$108,2,FALSE) -> 15215.664 | H20: =+F20*(1-G20) -> 15215.664 | I20: =+H20/E20 -> 1267.972 | J20: =+I20*J$3 -> 266.27413 | K20: =+I20+J20 -> 1534.2462 | L20: =+K20*0.3 -> 460.27385 | M20: =+K20+L20 -> 1994.52 | N20: =+M20*N$3 -> 897.53401 | O20: =+M20+N20 -> 2892.054 | P20: =H20/Q20-1 -> 0.1 | Q20: 13832.422 | AF20: 13173.735 | AG20: =+(H20-AF20)/AF20 -> 0.155 | AK20: 100021677 | AL20: 15215.664 | AN20: =+Q20/H20 -> 0.90909091
A21: 100021638 | B21: MEDALLONES 60X80g "SWIFT BURGER" PARRILLERAS FAMILY | C21: 7790360026699 | D21: 4.8 | E21: 60 | F21: =+VLOOKUP(A21,$AK$4:$AL$108,2,FALSE) -> 47532.849 | H21: =+F21*(1-G21) -> 47532.849 | I21: =+H21/E21 -> 792.21415 | J21: =+I21*J$3 -> 166.36497 | K21: =+I21+J21 -> 958.57912 | L21: =+K21*L$3 -> 335.50269 | M21: =+K21+L21 -> 1294.0818 | N21: =+M21*N$3 -> 582.33681 | O21: =+M21+N21 -> 1876.4186 | P21: =H21/Q21-1 -> 0.08 | Q21: 44011.897 | AF21: 41916.092 | AG21: =+(H21-AF21)/AF21 -> 0.134 | AK21: 100021638 | AL21: 47532.849 | AN21: =+Q21/H21 -> 0.92592593
A22: 100021575 | B22: MEDALLONES 60X69g "SWIFT BURGER"PARRILLERAS FAMILY | C22: 7790360007032 | D22: 4.14 | E22: 60 | F22: =+VLOOKUP(A22,$AK$4:$AL$108,2,FALSE) -> 38984.492 | H22: =+F22*(1-G22) -> 38984.492 | I22: =+H22/E22 -> 649.74153 | J22: =+I22*J$3 -> 136.44572 | K22: =+I22+J22 -> 786.18725 | L22: =+K22*L$3 -> 275.16554 | M22: =+K22+L22 -> 1061.3528 | N22: =+M22*N$3 -> 477.60875 | O22: =+M22+N22 -> 1538.9615 | P22: =H22/Q22-1 -> 0.08 | Q22: 36096.752 | AF22: 34377.859 | AG22: =+(H22-AF22)/AF22 -> 0.134 | AK22: 100021575 | AL22: 38984.492 | AN22: =+Q22/H22 -> 0.92592593
A23: 100021514 | B23: MEDALLON 60X69G CARNE VACUNA | C23: 7790360006943 | D23: 4.14 | E23: 60 | F23: =+VLOOKUP(A23,$AK$4:$AL$108,2,FALSE) -> 35475.666 | H23: =+F23*(1-G23) -> 35475.666 | I23: =+H23/E23 -> 591.26111 | J23: =+I23*J$3 -> 124.16483 | K23: =+I23+J23 -> 715.42594 | L23: =+K23*L$3 -> 250.39908 | M23: =+K23+L23 -> 965.82502 | N23: =+M23*N$3 -> 434.62126 | O23: =+M23+N23 -> 1400.4463 | P23: =H23/Q23-1 -> 0.08 | Q23: 32847.839 | AF23: 31283.656 | AG23: =+(H23-AF23)/AF23 -> 0.134 | AK23: 100021514 | AL23: 35475.666 | AN23: =+Q23/H23 -> 0.92592593
A24: 100516208 | B24: MEDALLON 60x80g PARRILLERO MC SWIFT | C24: 7790360968203 | D24: =60*0.08 -> 4.8 | E24: 60 | F24: =+VLOOKUP(A24,$AK$4:$AL$108,2,FALSE) -> 41131.229 | H24: =+F24*(1-G24) -> 41131.229 | I24: =+H24/E24 -> 685.52049 | J24: =+I24*J$3 -> 143.9593 | K24: =+I24+J24 -> 829.47979 | L24: =+K24*L$3 -> 290.31793 | M24: =+K24+L24 -> 1119.7977 | N24: =+M24*N$3 -> 503.90897 | O24: =+M24+N24 -> 1623.7067 | P24: =H24/Q24-1 -> 0.08 | Q24: 38084.471 | AF24: 36270.925 | AG24: =+(H24-AF24)/AF24 -> 0.134 | AK24: 100516208 | AL24: 41131.229 | AN24: =+Q24/H24 -> 0.92592593
A25: 100518346 | B25: MEDALLON 60X109G CARNE VACUNA PARRILLERO SWIFT | C25: 7790360975478 | D25: =60*0.109 -> 6.54 | E25: 60 | F25: =+VLOOKUP(A25,$AK$4:$AL$108,2,FALSE) -> 58788.442 | H25: =+F25*(1-G25) -> 58788.442 | I25: =+H25/E25 -> 979.80737 | J25: =I25*J3 -> 205.75955 | K25: =J25+I25 -> 1185.5669 | L25: =K25*L3 -> 414.94842 | M25: =L25+K25 -> 1600.5153 | N25: =M25*N3 -> 720.2319 | O25: =N25+M25 -> 2320.7472 | P25: =H25/Q25-1 -> 0.08 | Q25: 54433.743 | AF25: 51841.66 | AG25: =+(H25-AF25)/AF25 -> 0.134 | AK25: 100518346 | AL25: 58788.442 | AN25: =+Q25/H25 -> 0.92592593
A26: 100516259 | B26: MEDALLON GIGANTE 48x113.5g | C26: 7790360968340 | D26: 18.16 | E26: 48 | F26: =+VLOOKUP(A26,$AK$4:$AL$108,2,FALSE) -> 136018.21 | H26: =+F26*(1-G26) -> 136018.21 | I26: =+H26/E26 -> 2833.7127 | J26: =+I26*J$3 -> 595.07967 | K26: =+I26+J26 -> 3428.7924 | L26: =+K26*L$3 -> 1200.0773 | M26: =+K26+L26 -> 4628.8697 | N26: =+M26*N$3 -> 2082.9914 | O26: =+M26+N26 -> 6711.8611 | P26: =H26/Q26-1 -> 0.08 | Q26: 125942.79 | AF26: 119945.51 | AG26: =+(H26-AF26)/AF26 -> 0.134 | AK26: 100516259 | AL26: 136018.21 | AN26: =+Q26/H26 -> 0.92592593
A27: 100518095 | B27: HAMBURGUESA 36 X 185 GRS | C27: 7790360974785 | D27: 6.66 | E27: 36 | F27: =+VLOOKUP(A27,$AK$4:$AL$108,2,FALSE) -> 67770.616 | H27: =+F27*(1-G27) -> 67770.616 | I27: =+H27/E27 -> 1882.5171 | J27: =+I27*J$3 -> 395.32859 | K27: =+I27+J27 -> 2277.8457 | L27: =+K27*L$3 -> 797.24599 | M27: =+K27+L27 -> 3075.0917 | N27: =+M27*N$3 -> 1383.7913 | O27: =+M27+N27 -> 4458.883 | P27: =H27/Q27-1 -> 0.08 | Q27: 62750.57 | AF27: 59762.448 | AG27: =+(H27-AF27)/AF27 -> 0.134 | AK27: 100518095 | AL27: 67770.616 | AN27: =+Q27/H27 -> 0.92592593
A28: 100518223 | B28: HAMBURGUESA 30x2x106 GRS | C28: 7790360975065 | D28: =60*0.106 -> 6.36 | E28: 30 | F28: =+VLOOKUP(A28,$AK$4:$AL$108,2,FALSE) -> 52763.191 | H28: =+F28*(1-G28) -> 52763.191 | I28: =+H28/E28 -> 1758.773 | J28: =+I28*J$3 -> 369.34234 | K28: =+I28+J28 -> 2128.1154 | L28: =+K28*L$3 -> 744.84038 | M28: =+K28+L28 -> 2872.9557 | N28: =+M28*N$3 -> 1292.8301 | O28: =+M28+N28 -> 4165.7858 | P28: =H28/Q28-1 -> 0.08 | Q28: 48854.806 | AF28: 46528.387 | AG28: =+(H28-AF28)/AF28 -> 0.134 | AK28: 100518223 | AL28: 52763.191 | AN28: =+Q28/H28 -> 0.92592593
F29: =+VLOOKUP(A29,$AK$4:$AL$108,2,FALSE) -> #N/A | H29: =+F29*(1-G29) -> #N/A | I29: =+H29/E29 -> #N/A | P29: =H29/Q29-1 -> #N/A | Q29: #N/A | Y29: OCT | Z29: PATY VIENA | AA29: VIENISSIMA | AB29: PALADINI | AF29: #N/A | AG29: =+(H29-AF29)/AF29 -> #N/A | AN29: =+Q29/H29 -> #N/A
A30: 100022085 | B30: SALCHICHAS 24X6 SWIFT | C30: 7790360000132 | D30: 5.4 | E30: 24 | F30: =+VLOOKUP(A30,$AK$4:$AL$108,2,FALSE) -> 22291.884 | G30: =0.0833333333333333*100% -> 0.083333333 | H30: =+F30*(1-G30) -> 20434.227 | I30: =+H30/E30 -> 851.42614 | J30: =+I30*J$3 -> 178.79949 | K30: =+I30+J30 -> 1030.2256 | L30: =+K30*L$3 -> 360.57897 | M30: =+K30+L30 -> 1390.8046 | N30: =+M30*0.438 -> 609.17241 | O30: =+M30+N30 -> 1999.977 | P30: =H30/Q30-1 -> -5.2899972e-07 | Q30: 20434.238 | S30: Px LISTA: $2.200 + compra 11 estuches + 1 de regalo ----> OFERTA $2.000 público | Y30: 1900 | Z30: 2080 | AA30: 2435 | AB30: 2328 | AF30: 18238.814 | AG30: =+(H30-AF30)/AF30 -> 0.12037037 | AK30: 100022085 | AL30: 22291.884 | AN30: =+Q30/H30 -> 1.0000005
A31: 100522204 | B31: SALCHICHAS 24X6 SWIFT | C31: 7790360983947 | D31: 5.4 | E31: 24 | F31: =+VLOOKUP(A31,$AK$4:$AL$108,2,FALSE) -> 22291.884 | G31: =0.0833333333333333*100% -> 0.083333333 | H31: =+F31*(1-G31) -> 20434.227 | I31: =+H31/E31 -> 851.42614 | J31: =+I31*J$3 -> 178.79949 | K31: =+I31+J31 -> 1030.2256 | L31: =+K31*L$3 -> 360.57897 | M31: =+K31+L31 -> 1390.8046 | N31: =+M31*0.438 -> 609.17241 | O31: =+M31+N31 -> 1999.977 | P31: =H31/Q31-1 -> -5.2899972e-07 | Q31: 20434.238 | S31: Px LISTA: $2.200 + compra 11 estuches + 1 de regalo ----> OFERTA $2.000 público | AK31: 100522204 | AL31: 22291.884
A32: 100022072 | B32: SALCHICHAS 12X12 SWIFT | C32: 7790360024541 | D32: 5.4 | E32: 12 | F32: =+VLOOKUP(A32,$AK$4:$AL$108,2,FALSE) -> 21177.29 | G32: =0.0833333333333333*100% -> 0.083333333 | H32: =+F32*(1-G32) -> 19412.516 | I32: =+H32/E32 -> 1617.7097 | J32: =+I32*J$3 -> 339.71903 | K32: =+I32+J32 -> 1957.4287 | L32: =+K32*0.3388 -> 663.17684 | M32: =+K32+L32 -> 2620.6055 | N32: =+M32*N$3 -> 1179.2725 | O32: =+M32+N32 -> 3799.878 | P32: =H32/Q32-1 -> -3.6362314e-05 | Q32: 19413.222 | S32: Conveniencia vs 22085: Oferta $3.800 | Y32: 3600 | Z32: 4090 | AA32: 4495 | AB32: 4400 | AF32: 17225.547 | AG32: =+(H32-AF32)/AF32 -> 0.12696078 | AK32: 100022072 | AL32: 21177.29 | AN32: =+Q32/H32 -> 1.0000364
A33: 100522205 | B33: SALCHICHAS 12X12 SWIFT | C33: 7790360983954 | D33: 5.4 | E33: 12 | F33: =+VLOOKUP(A33,$AK$4:$AL$108,2,FALSE) -> 21177.29 | G33: =0.0833333333333333*100% -> 0.083333333 | H33: =+F33*(1-G33) -> 19412.516 | I33: =+H33/E33 -> 1617.7097 | J33: =+I33*J$3 -> 339.71903 | K33: =+I33+J33 -> 1957.4287 | L33: =+K33*0.3388 -> 663.17684 | M33: =+K33+L33 -> 2620.6055 | N33: =+M33*N$3 -> 1179.2725 | O33: =+M33+N33 -> 3799.878 | P33: =H33/Q33-1 -> -3.6362314e-05 | Q33: 19413.222 | S33: Conveniencia vs 22085: Oferta $3.800 | AK33: 100522205 | AL33: 21177.29
A34: 100516849 | B34: SALCHICHAS SIN PIEL 24X6 "SWIFT KIDS" X 190 g | C34: 7790360970053 | D34: 4.56 | E34: 24 | F34: =+VLOOKUP(A34,$AK$4:$AL$108,2,FALSE) -> 17165.375 | H34: =+F34*(1-G34) -> 17165.375 | I34: =+H34/E34 -> 715.22396 | J34: =+I34*J$3 -> 150.19703 | K34: =+I34+J34 -> 865.421 | L34: =+K34*0.339 -> 293.37772 | M34: =+K34+L34 -> 1158.7987 | N34: =+M34*0.424 -> 491.33065 | O34: =+M34+N34 -> 1650.1294 | P34: =H34/Q34-1 -> 0.05 | Q34: 16347.976 | S34: Oferta incluida en lista: $1.650 | Y34: 1650 | Z34: 1888 | AA34: PATY FUN | AF34: 15705.646 | AG34: =+(H34-AF34)/AF34 -> 0.092942968 | AK34: 100516849 | AL34: 17165.375 | AN34: =+Q34/H34 -> 0.95238095
A35: 100022039 | B35: SALCHICHAS LARGAS 10 x 12 SWIFT INSTITUCIONAL | C35: 7790360007063 | D35: 8.7 | E35: 10 | F35: =+VLOOKUP(A35,$AK$4:$AL$108,2,FALSE) -> 56041.789 | H35: =+F35*(1-G35) -> 56041.789 | I35: =+H35/E35 -> 5604.1789 | J35: =+I35*J$3 -> 1176.8776 | K35: =+I35+J35 -> 6781.0565 | L35: =+K35*L$3 -> 2373.3698 | M35: =+K35+L35 -> 9154.4263 | N35: =+M35*N$3 -> 4119.4918 | O35: =+M35+N35 -> 13273.918 | P35: =H35/Q35-1 -> 0 | Q35: 56041.789 | Z35: ICB | AA35: 66 | AB35: PANCHIN | AC35: fela | AF35: 44083.414 | AG35: =+(H35-AF35)/AF35 -> 0.271267 | AK35: 100022039 | AL35: 56041.789 | AN35: =+Q35/H35 -> 1
A36: 100522206 | B36: SALCHICHAS LARGAS 10 x 12 SWIFT INSTITUCIONAL | C36: 7790360983961 | D36: 8.7 | E36: 10 | F36: 56041.789 | H36: =+F36*(1-G36) -> 56041.789 | I36: =+H36/E36 -> 5604.1789 | J36: =+I36*J$3 -> 1176.8776 | K36: =+I36+J36 -> 6781.0565 | L36: =+K36*L$3 -> 2373.3698 | M36: =+K36+L36 -> 9154.4263 | N36: =+M36*N$3 -> 4119.4918 | O36: =+M36+N36 -> 13273.918 | Q36: 56041.789 | AK36: 100522206 | AL36: 56041.789
A37: 100022058 | B37: SALCHICHAS SIN PIEL "LA BLANCA" 24X6X190 Grs; | C37: 7790360026002 | D37: 4.56 | E37: 24 | F37: =+VLOOKUP(A37,$AK$4:$AL$108,2,FALSE) -> 15783.589 | H37: =+F37*(1-G37) -> 15783.589 | I37: =+H37/E37 -> 657.64956 | J37: =+I37*J$3 -> 138.10641 | K37: =+I37+J37 -> 795.75597 | L37: =+K37*0.3 -> 238.72679 | M37: =+K37+L37 -> 1034.4828 | N37: =+M37*N$3 -> 465.51724 | O37: =+M37+N37 -> 1500 | P37: =H37/Q37-1 -> -0.11598841 | Q37: 17854.505 | Y37: 1130 | Z37: 1190 | AA37: 1000 | AB37: 1198 | AC37: 1500 | AD37: MISMO PX MES ANT | AF37: 11449.922 | AG37: =+(H37-AF37)/AF37 -> 0.37848877 | AK37: 100022058 | AL37: 15783.589 | AN37: =+Q37/H37 -> 1.1312069
A38: 100518151 | B38: SALCHICHAS LARGAS 10 x 12 x 870g | C38: 7790360974990 | D38: 8.7 | E38: 10 | F38: =+VLOOKUP(A38,$AK$4:$AL$108,2,FALSE) -> 63845.74 | H38: =+F38*(1-G38) -> 63845.74 | I38: =+H38/E38 -> 6384.574 | J38: =+I38*J$3 -> 1340.7605 | K38: =+I38+J38 -> 7725.3345 | L38: =+K38*0.3 -> 2317.6003 | M38: =+K38+L38 -> 10042.935 | N38: =+M38*N$3 -> 4519.3207 | O38: =+M38+N38 -> 14562.256 | P38: =H38/Q38-1 -> 0 | Q38: 63845.74 | AF38: 50222.132 | AG38: =+(H38-AF38)/AF38 -> 0.271267 | AK38: 100518151 | AL38: 63845.74 | AN38: =+Q38/H38 -> 1
F39: =+VLOOKUP(A39,$AK$4:$AL$108,2,FALSE) -> #N/A | H39: =+F39*(1-G39) -> #N/A | I39: =+H39/E39 -> #N/A | J39: 0.21 | L39: 0.22 | N39: 0.35 | P39: =H39/Q39-1 -> #N/A | Q39: #N/A | Y39: =+Y37*24 -> 27120 | AF39: #N/A | AG39: =+(H39-AF39)/AF39 -> #N/A | AL39: 0 | AN39: =+Q39/H39 -> #N/A
A40: 100021000 | B40: PATE DE FOIE 24X90G SWIFT | C40: 7790360720382 | D40: 2.16 | E40: 24 | F40: =+VLOOKUP(A40,$AK$4:$AL$108,2,FALSE) -> 12345.023 | H40: =+F40*(1-G40) -> 12345.023 | I40: =+H40/E40 -> 514.37594 | J40: =+I40*J$3 -> 108.01895 | K40: =+I40+J40 -> 622.39489 | L40: =+K40*L$39 -> 136.92688 | M40: =+K40+L40 -> 759.32176 | N40: =+M40*N$39 -> 265.76262 | O40: =+M40+N40 -> 1025.0844 | P40: =H40/Q40-1 -> 0 | Q40: 12345.023 | Y40: =+Y39/1.21/1.35/1.45 -> 11449.922 | Z40: PX 22058 | AF40: 10353.088 | AG40: =+(H40-AF40)/AF40 -> 0.1924 | AK40: 100021000 | AL40: 12345.023 | AN40: =+Q40/H40 -> 1
A41: 100021001 | B41: PICADILLO DE CARNE 24X90G SWIFT | C41: 7790360720115 | D41: 2.16 | E41: 24 | F41: =+VLOOKUP(A41,$AK$4:$AL$108,2,FALSE) -> 12345.023 | H41: =+F41*(1-G41) -> 12345.023 | I41: =+H41/E41 -> 514.37594 | J41: =+I41*J$3 -> 108.01895 | K41: =+I41+J41 -> 622.39489 | L41: =+K41*L$39 -> 136.92688 | M41: =+K41+L41 -> 759.32176 | N41: =+M41*N$39 -> 265.76262 | O41: =+M41+N41 -> 1025.0844 | P41: =H41/Q41-1 -> 0 | Q41: 12345.023 | Y41: =+F37-Y40 -> 4333.667 | AF41: 10353.088 | AG41: =+(H41-AF41)/AF41 -> 0.1924 | AK41: 100021001 | AL41: 12345.023 | AN41: =+Q41/H41 -> 1
...

Sheet Sub Litoral
B2: Código | C2: Descripción | D2: EAN | E2: Kg. x Caja | F2: Cant. X Caja | G2: Precio de Lista | H2: Dcto | I2: Precio de factura | J2: Precio Neto estuche en factura | K2: IVA | L2: Px Unitario IVA Inc | M2: M-up Dx | N2: Px Unitario Minorista | O2: M-up Minorista | P2: Px Unitario Público | R2: PX MAYO
K3: 0.21 | M3: 0.3 | O3: 0.4
B4: 100021632 | C4: HAMBURGUESAS 30x160g CLASICA x2 SWIFT | D4: 7790360026606 | E4: 4.8 | F4: 30 | G4: =+VLOOKUP(B4,$T$4:$U$104,2,FALSE) -> 39054.639 | I4: =+G4*(1-H4) -> 39054.639 | J4: =+I4/F4 -> 1301.8213 | K4: =+J4*K$3 -> 273.38247 | L4: =+J4+K4 -> 1575.2038 | M4: =+L4*M$3 -> 472.56113 | N4: =+L4+M4 -> 2047.7649 | O4: =+N4*O$3 -> 819.10595 | P4: =+N4+O4 -> 2866.8708 | R4: 34111.834 | S4: =+(I4-R4)/R4 -> 0.1449 | T4: 100021632 | U4: 39054.639
B5: 100021652 | C5: HAMBURGUESA 18X4X80G CLASICA SWIFT | D5: 7790360026576 | E5: 5.76 | F5: 18 | G5: =+VLOOKUP(B5,$T$4:$U$104,2,FALSE) -> 47014.671 | I5: =+G5*(1-H5) -> 47014.671 | J5: =+I5/F5 -> 2611.9262 | K5: =+J5*K$3 -> 548.5045 | L5: =+J5+K5 -> 3160.4307 | M5: =+L5*M$3 -> 948.1292 | N5: =+L5+M5 -> 4108.5599 | O5: =+N5*O$3 -> 1643.424 | P5: =+N5+O5 -> 5751.9838 | R5: 43938.945 | S5: =+(I5-R5)/R5 -> 0.07 | T5: 100021652 | U5: 47014.671
B6: 100021631 | C6: HAMBURGUESA 8X12X80G CLASICA SWIFT | D6: 7790360026590 | E6: 7.68 | F6: 8 | G6: =+VLOOKUP(B6,$T$4:$U$104,2,FALSE) -> 62487.422 | I6: =+G6*(1-H6) -> 62487.422 | J6: =+I6/F6 -> 7810.9277 | K6: =+J6*K$3 -> 1640.2948 | L6: =+J6+K6 -> 9451.2225 | M6: =+L6*M$3 -> 2835.3668 | N6: =+L6+M6 -> 12286.589 | O6: =+N6*O$3 -> 4914.6357 | P6: =+N6+O6 -> 17201.225 | R6: 73786.602 | S6: =+(I6-R6)/R6 -> -0.15313322 | T6: 100021631 | U6: 62487.422
B7: 100021630 | C7: HAMBURGUESA 6X20X80G CLASICA SWIFT | D7: 7790360026583 | E7: 9.6 | F7: 6 | G7: =+VLOOKUP(B7,$T$4:$U$104,2,FALSE) -> 78109.277 | I7: =+G7*(1-H7) -> 78109.277 | J7: =+I7/F7 -> 13018.213 | K7: =+J7*K$3 -> 2733.8247 | L7: =+J7+K7 -> 15752.038 | M7: =+L7*M$3 -> 4725.6113 | N7: =+L7+M7 -> 20477.649 | O7: =+N7*O$3 -> 8191.0595 | P7: =+N7+O7 -> 28668.708 | R7: 92268.024 | S7: =+(I7-R7)/R7 -> -0.15345237 | T7: 100021630 | U7: 78109.277
B8: 100021653 | C8: MEDALLON 18X4X80G PARRILLERO SWIFT | D8: 7790360026682 | E8: 5.76 | F8: 18 | G8: =+VLOOKUP(B8,$T$4:$U$104,2,FALSE) -> 51552.123 | I8: =+G8*(1-H8) -> 51552.123 | J8: =+I8/F8 -> 2864.0068 | K8: =+J8*K$3 -> 601.44143 | L8: =+J8+K8 -> 3465.4483 | M8: =+L8*M$3 -> 1039.6345 | N8: =+L8+M8 -> 4505.0827 | O8: =+N8*O$3 -> 1802.0331 | P8: =+N8+O8 -> 6307.1158 | R8: 58094.424 | S8: =+(I8-R8)/R8 -> -0.11261495 | T8: 100021653 | U8: 51552.123
B9: 100516169 | C9: MEDALLONES 18X4X80G SWIFT RECETA ESPECIAL | D9: 7790360967961 | E9: 5.76 | F9: 18 | G9: =+VLOOKUP(B9,$T$4:$U$104,2,FALSE) -> 47534.511 | I9: =+G9*(1-H9) -> 47534.511 | J9: =+I9/F9 -> 2640.8062 | K9: =+J9*K$3 -> 554.5693 | L9: =+J9+K9 -> 3195.3755 | M9: =+L9*M$3 -> 958.61264 | N9: =+L9+M9 -> 4153.9881 | O9: =+N9*O$3 -> 1661.5952 | P9: =+N9+O9 -> 5815.5834 | R9: 47534.511 | S9: =+(I9-R9)/R9 -> 0 | T9: 100516169 | U9: 47534.511
B10: 100520337 | C10: MEDALLON BURGER SWIFT MEGA 30 x 160 g | D10: 7790360977960 | E10: 4.8 | F10: 30 | G10: =+VLOOKUP(B10,$T$4:$U$104,2,FALSE) -> 27614.342 | I10: =+G10*(1-H10) -> 27614.342 | J10: =+I10/F10 -> 920.47806 | K10: =+J10*K$3 -> 193.30039 | L10: =+J10+K10 -> 1113.7784 | M10: =+L10*M$3 -> 334.13353 | N10: =+L10+M10 -> 1447.912 | O10: =+N10*O$3 -> 579.16479 | P10: =+N10+O10 -> 2027.0768 | R10: 27614.342 | S10: =+(I10-R10)/R10 -> 0 | T10: 100520337 | U10: 27614.342
B11: 100021503 | C11: Medallón CAJITA 12x4 69 grs | D11: 7790360966841 | E11: 3.312 | F11: 12 | G11: =+VLOOKUP(B11,$T$4:$U$104,2,FALSE) -> 21084.263 | H11: 0.0833 | I11: =+G11*(1-H11) -> 19327.944 | J11: =+I11/F11 -> 1610.662 | K11: =+J11*K$3 -> 338.23902 | L11: =+J11+K11 -> 1948.901 | M11: =+L11*M$3 -> 584.67031 | N11: =+L11+M11 -> 2533.5714 | O11: =+N11*O$3 -> 1013.4285 | P11: =+N11+O11 -> 3546.9999 | R11: 17418.809 | S11: =+(I11-R11)/R11 -> 0.10960195 | T11: 100021503 | U11: 21084.263
B12: 100516201 | C12: HAMBURGUESA 8X12X69G BURGER SWIFT | D12: 7790360968548 | E12: 6.624 | F12: 8 | G12: =+VLOOKUP(B12,$T$4:$U$104,2,FALSE) -> 46067.118 | I12: =+G12*(1-H12) -> 46067.118 | J12: =+I12/F12 -> 5758.3897 | K12: =+J12*K$3 -> 1209.2618 | L12: =+J12+K12 -> 6967.6516 | M12: =+L12*M$3 -> 2090.2955 | N12: =+L12+M12 -> 9057.947 | O12: =+N12*O$3 -> 3623.1788 | P12: =+N12+O12 -> 12681.126 | R12: 43873.446 | S12: =+(I12-R12)/R12 -> 0.05 | T12: 100516201 | U12: 46067.118
B13: 100021643 | C13: MEDALLON 42X112G DOBLE BURGER SWIFT | D13: 7790360966797 | E13: 4.704 | F13: 42 | G13: =+VLOOKUP(B13,$T$4:$U$104,2,FALSE) -> 28251.566 | I13: =+G13*(1-H13) -> 28251.566 | J13: =+I13/F13 -> 672.65633 | K13: =+J13*K$3 -> 141.25783 | L13: =+J13+K13 -> 813.91416 | M13: =+L13*M$3 -> 244.17425 | N13: =+L13+M13 -> 1058.0884 | O13: =+N13*O$3 -> 423.23536 | P13: =+N13+O13 -> 1481.3238 | R13: 26906.253 | S13: =+(I13-R13)/R13 -> 0.05 | T13: 100021643 | U13: 28251.566
B14: 100516325 | C14: MEDALLON DOBLE BURGER 2X2 | D14: 7790360967763 | E14: 4.704 | F14: 21 | G14: =+VLOOKUP(B14,$T$4:$U$104,2,FALSE) -> 31773.021 | I14: =+G14*(1-H14) -> 31773.021 | J14: =+I14/F14 -> 1513.001 | K14: =+J14*K$3 -> 317.73021 | L14: =+J14+K14 -> 1830.7312 | M14: =+L14*M$3 -> 549.21937 | N14: =+L14+M14 -> 2379.9506 | O14: =+N14*O$3 -> 951.98024 | P14: =+N14+O14 -> 3331.9309 | R14: 31773.021 | S14: =+(I14-R14)/R14 -> 0 | T14: 100516325 | U14: 31773.021
B15: 100021676 | C15: HAMBURGUESA 30X250g CLASICA "XL" SWIFT | D15: 7790360967411 | E15: 7.5 | F15: 30 | G15: =+VLOOKUP(B15,$T$4:$U$104,2,FALSE) -> 61903.059 | H15: 0.0667 | I15: =+G15*(1-H15) -> 57774.125 | J15: =+I15/F15 -> 1925.8042 | K15: =+J15*K$3 -> 404.41888 | L15: =+J15+K15 -> 2330.2231 | M15: =+L15*M$3 -> 699.06692 | N15: =+L15+M15 -> 3029.29 | O15: =+N15*O$3 -> 1211.716 | P15: =+N15+O15 -> 4241.006 | R15: 61903.059 | S15: =+(I15-R15)/R15 -> -0.0667 | T15: 100021676 | U15: 61903.059
B16: 100516008 | C16: HAMBURGUESA 24X2X120g CASERA SWIFT | D16: 7790360967701 | E16: 5.76 | F16: 24 | G16: =+VLOOKUP(B16,$T$4:$U$104,2,FALSE) -> 54953.721 | H16: 0.0909 | I16: =+G16*(1-H16) -> 49958.428 | J16: =+I16/F16 -> 2081.6012 | K16: =+J16*K$3 -> 437.13624 | L16: =+J16+K16 -> 2518.7374 | M16: =+L16*M$3 -> 755.62122 | N16: =+L16+M16 -> 3274.3586 | O16: =+N16*O$3 -> 1309.7434 | P16: =+N16+O16 -> 4584.1021 | R16: 54953.721 | S16: =+(I16-R16)/R16 -> -0.0909 | T16: 100516008 | U16: 54953.721
B17: 100520834 | C17: HAMBURGUESA X-TREMA 36 x 185 grs | D17: 7790360980618 | E17: 6.66 | F17: 36 | G17: =+VLOOKUP(B17,$T$4:$U$104,2,FALSE) -> 64264.025 | I17: =+G17*(1-H17) -> 64264.025 | J17: =+I17/F17 -> 1785.1118 | K17: =+J17*K$3 -> 374.87348 | L17: =+J17+K17 -> 2159.9853 | M17: =+L17*M$3 -> 647.99559 | N17: =+L17+M17 -> 2807.9809 | O17: =+N17*O$3 -> 1123.1924 | P17: =+N17+O17 -> 3931.1732 | R17: 64264.025 | S17: =+(I17-R17)/R17 -> 0 | T17: 100520834 | U17: 64264.025
B18: 100021680 | C18: HAMBURGUESAS 18X2X120g CLL BRA/ARG | D18: 7790360967688 | E18: 4.32 | F18: 18 | G18: =+VLOOKUP(B18,$T$4:$U$104,2,FALSE) -> 51472.633 | I18: =+G18*(1-H18) -> 51472.633 | J18: =+I18/F18 -> 2859.5907 | K18: =+J18*K$3 -> 600.51405 | L18: =+J18+K18 -> 3460.1048 | M18: =+L18*M$3 -> 1038.0314 | N18: =+L18+M18 -> 4498.1362 | O18: =+N18*O$3 -> 1799.2545 | P18: =+N18+O18 -> 6297.3907 | R18: 51472.633 | S18: =+(I18-R18)/R18 -> 0 | T18: 100021680 | U18: 51472.633
B19: 100021644 | C19: MEDALLON 42X112G LA BLANCA | D19: 7790360008541 | E19: 4.704 | F19: 42 | G19: =+VLOOKUP(B19,$T$4:$U$104,2,FALSE) -> 19172.581 | I19: =+G19*(1-H19) -> 19172.581 | J19: =+I19/F19 -> 456.49003 | K19: =+J19*K$3 -> 95.862907 | L19: =+J19+K19 -> 552.35294 | M19: =+L19*0.33 -> 182.27647 | N19: =+L19+M19 -> 734.62941 | O19: =+N19*O$3 -> 293.85176 | P19: =+N19+O19 -> 1028.4812 | R19: 16671.81 | S19: =+(I19-R19)/R19 -> 0.15 | T19: 100021644 | U19: 19172.581
B20: 100021677 | C20: MEDALLON 12x4X69G LA BLANCA | D20: 7790360967404 | E20: 3.312 | F20: 12 | G20: =+VLOOKUP(B20,$T$4:$U$104,2,FALSE) -> 15215.664 | I20: =+G20*(1-H20) -> 15215.664 | J20: =+I20/F20 -> 1267.972 | K20: =+J20*K$3 -> 266.27413 | L20: =+J20+K20 -> 1534.2462 | M20: =+L20*0.33 -> 506.30123 | N20: =+L20+M20 -> 2040.5474 | O20: =+N20*O$3 -> 816.21896 | P20: =+N20+O20 -> 2856.7664 | R20: 15215.664 | S20: =+(I20-R20)/R20 -> 0 | T20: 100021677 | U20: 15215.664
B21: 100021638 | C21: MEDALLONES 60X80g "SWIFT BURGER" PARRILLERAS FAMILY | D21: 7790360026699 | E21: 4.8 | F21: 60 | G21: =+VLOOKUP(B21,$T$4:$U$104,2,FALSE) -> 48413.087 | I21: =+G21*(1-H21) -> 48413.087 | J21: =+I21/F21 -> 806.88478 | K21: =+J21*K$3 -> 169.4458 | L21: =+J21+K21 -> 976.33058 | M21: =+L21*M$3 -> 292.89917 | N21: =+L21+M21 -> 1269.2298 | O21: =+N21*O$3 -> 507.6919 | P21: =+N21+O21 -> 1776.9217 | R21: 48413.087 | S21: =+(I21-R21)/R21 -> 0 | T21: 100021638 | U21: 48413.087
B22: 100021575 | C22: MEDALLONES 60X69g "SWIFT BURGER"PARRILLERAS FAMILY | D22: 7790360007032 | E22: 4.14 | F22: 60 | G22: =+VLOOKUP(B22,$T$4:$U$104,2,FALSE) -> 39706.427 | I22: =+G22*(1-H22) -> 39706.427 | J22: =+I22/F22 -> 661.77378 | K22: =+J22*K$3 -> 138.97249 | L22: =+J22+K22 -> 800.74627 | M22: =+L22*M$3 -> 240.22388 | N22: =+L22+M22 -> 1040.9702 | O22: =+N22*O$3 -> 416.38806 | P22: =+N22+O22 -> 1457.3582 | R22: 39706.427 | S22: =+(I22-R22)/R22 -> 0 | T22: 100021575 | U22: 39706.427
B23: 100021514 | C23: MEDALLON 60X69G CARNE VACUNA | D23: 7790360006943 | E23: 4.14 | F23: 60 | G23: =+VLOOKUP(B23,$T$4:$U$104,2,FALSE) -> 36132.623 | I23: =+G23*(1-H23) -> 36132.623 | J23: =+I23/F23 -> 602.21039 | K23: =+J23*K$3 -> 126.46418 | L23: =+J23+K23 -> 728.67457 | M23: =+L23*M$3 -> 218.60237 | N23: =+L23+M23 -> 947.27694 | O23: =+N23*O$3 -> 378.91078 | P23: =+N23+O23 -> 1326.1877 | R23: 36132.623 | S23: =+(I23-R23)/R23 -> 0 | T23: 100021514 | U23: 36132.623
B24: 100516208 | C24: MEDALLON 60x80g PARRILLERO MC SWIFT | D24: 7790360968203 | E24: =60*0.08 -> 4.8 | F24: 60 | G24: =+VLOOKUP(B24,$T$4:$U$104,2,FALSE) -> 41892.919 | I24: =+G24*(1-H24) -> 41892.919 | J24: =+I24/F24 -> 698.21531 | K24: =+J24*K$3 -> 146.62521 | L24: =+J24+K24 -> 844.84052 | M24: =+L24*M$3 -> 253.45216 | N24: =+L24+M24 -> 1098.2927 | O24: =+N24*O$3 -> 439.31707 | P24: =+N24+O24 -> 1537.6098 | R24: 41892.919 | S24: =+(I24-R24)/R24 -> 0 | T24: 100516208 | U24: 41892.919
B25: 100518346 | C25: MEDALLON 60X109G CARNE VACUNA PARRILLERO SWIFT | E25: 6.54 | F25: 60 | G25: =+VLOOKUP(B25,$T$4:$U$104,2,FALSE) -> 59877.117 | I25: =+G25*(1-H25) -> 59877.117 | J25: =+I25/F25 -> 997.95195 | K25: =+J25*K$3 -> 209.56991 | L25: =+J25+K25 -> 1207.5219 | M25: =+L25*M$3 -> 362.25656 | N25: =+L25+M25 -> 1569.7784 | O25: =+N25*O$3 -> 627.91136 | P25: =+N25+O25 -> 2197.6898 | R25: 59877.117 | S25: =+(I25-R25)/R25 -> 0 | T25: 100518346 | U25: 59877.117
B26: 100516259 | C26: MEDALLON GIGANTE 48x113.5g | D26: 7790360968340 | E26: 18.16 | F26: 48 | G26: =+VLOOKUP(B26,$T$4:$U$104,2,FALSE) -> 138537.07 | I26: =+G26*(1-H26) -> 138537.07 | J26: =+I26/F26 -> 2886.1889 | K26: =+J26*K$3 -> 606.09967 | L26: =+J26+K26 -> 3492.2885 | M26: =+L26*M$3 -> 1047.6866 | N26: =+L26+M26 -> 4539.9751 | O26: =+N26*O$3 -> 1815.99 | P26: =+N26+O26 -> 6355.9652 | R26: 138537.07 | S26: =+(I26-R26)/R26 -> 0 | T26: 100516259 | U26: 138537.07
B27: 100518095 | C27: HAMBURGUESA 36 X 185 GRS | D27: 7790360974785 | E27: 6.66 | F27: 36 | G27: =+VLOOKUP(B27,$T$4:$U$104,2,FALSE) -> 69025.627 | I27: =+G27*(1-H27) -> 69025.627 | J27: =+I27/F27 -> 1917.3785 | K27: =+J27*K$3 -> 402.64949 | L27: =+J27+K27 -> 2320.028 | M27: =+L27*M$3 -> 696.00841 | N27: =+L27+M27 -> 3016.0364 | O27: =+N27*O$3 -> 1206.4146 | P27: =+N27+O27 -> 4222.451 | R27: 69025.627 | S27: =+(I27-R27)/R27 -> 0 | T27: 100518095 | U27: 69025.627
B28: 100518223 | C28: HAMBURGUESA 30x2x106 GRS | D28: 7790360975065 | E28: =60*0.106 -> 6.36 | F28: 30 | G28: =+VLOOKUP(B28,$T$4:$U$104,2,FALSE) -> 53740.287 | I28: =+G28*(1-H28) -> 53740.287 | J28: =+I28/F28 -> 1791.3429 | K28: =+J28*K$3 -> 376.18201 | L28: =+J28+K28 -> 2167.5249 | M28: =+L28*M$3 -> 650.25747 | N28: =+L28+M28 -> 2817.7824 | O28: =+N28*O$3 -> 1127.113 | P28: =+N28+O28 -> 3944.8953 | R28: 53740.287 | S28: =+(I28-R28)/R28 -> 0 | T28: 100518223 | U28: 53740.287
J29: =+I29/F29 -> #DIV/0! | K29: 0.21 | M29: 0.3 | O29: 0.4 | S29: =+(I29-R29)/R29 -> #DIV/0!
B30: 100022085 | C30: SALCHICHAS 24X6 SWIFT | D30: 7790360000132 | E30: 5.4 | F30: 24 | G30: =+Litoral!H30*1.1 -> 22477.65 | I30: =+G30*(1-H30) -> 22477.65 | J30: =+I30/F30 -> 936.56875 | K30: =+J30*K$3 -> 196.67944 | L30: =+J30+K30 -> 1133.2482 | M30: =+L30*M$3 -> 339.97446 | N30: =+L30+M30 -> 1473.2226 | O30: =+N30*O$3 -> 589.28906 | P30: =+N30+O30 -> 2062.5117 | R30: 21177.281 | S30: =+(I30-R30)/R30 -> 0.061403979 | T30: 100022085 | U30: 35527.915
B31: 100522204 | C31: SALCHICHAS 24X6 SWIFT | D31: 7790360983947 | E31: 5.4 | F31: 24 | G31: =+Litoral!H31*1.1 -> 22477.65 | I31: =+G31*(1-H31) -> 22477.65 | J31: =+I31/F31 -> 936.56875 | K31: =+J31*K$3 -> 196.67944 | L31: =+J31+K31 -> 1133.2482 | M31: =+L31*M$3 -> 339.97446 | N31: =+L31+M31 -> 1473.2226 | O31: =+N31*O$3 -> 589.28906 | P31: =+N31+O31 -> 2062.5117 | T31: 100522204 | U31: 35527.915
B32: 100022072 | C32: SALCHICHAS 12X12 SWIFT | D32: 7790360024541 | E32: 5.4 | F32: 12 | G32: =+Litoral!H32*1.1 -> 21353.768 | I32: =+G32*(1-H32) -> 21353.768 | J32: =+I32/F32 -> 1779.4806 | K32: =+J32*K$3 -> 373.69093 | L32: =+J32+K32 -> 2153.1716 | M32: =+L32*M$3 -> 645.95147 | N32: =+L32+M32 -> 2799.123 | O32: =+N32*O$3 -> 1119.6492 | P32: =+N32+O32 -> 3918.7722 | R32: 20062.698 | S32: =+(I32-R32)/R32 -> 0.064351759 | T32: 100022072 | U32: 35441.013
B33: 100522205 | C33: SALCHICHAS 12X12 SWIFT | D33: 7790360983954 | E33: 5.4 | F33: 12 | G33: =+Litoral!H33*1.1 -> 21353.768 | I33: =+G33*(1-H33) -> 21353.768 | J33: =+I33/F33 -> 1779.4806 | K33: =+J33*K$3 -> 373.69093 | L33: =+J33+K33 -> 2153.1716 | M33: =+L33*M$3 -> 645.95147 | N33: =+L33+M33 -> 2799.123 | O33: =+N33*O$3 -> 1119.6492 | P33: =+N33+O33 -> 3918.7722 | T33: 100522205 | U33: 35441.013
B34: 100516849 | C34: SALCHICHAS SIN PIEL 24X6 "SWIFT KIDS" X 190 g | D34: 7790360970053 | E34: 4.56 | F34: 24 | G34: =+Litoral!H34*1.1 -> 18881.913 | I34: =+G34*(1-H34) -> 18881.913 | J34: =+I34/F34 -> 786.74636 | K34: =+J34*K$3 -> 165.21674 | L34: =+J34+K34 -> 951.9631 | M34: =+L34*M$3 -> 285.58893 | N34: =+L34+M34 -> 1237.552 | O34: =+N34*O$3 -> 495.02081 | P34: =+N34+O34 -> 1732.5728 | R34: 18390.839 | S34: =+(I34-R34)/R34 -> 0.026702084 | T34: 100516849 | U34: 34489.699
B35: 100022039 | C35: SALCHICHAS LARGAS 10 x 12 SWIFT INSTITUCIONAL | D35: 7790360007063 | E35: 8.7 | F35: 10 | G35: =+VLOOKUP(B35,$T$4:$U$104,2,FALSE) -> 61645.968 | I35: =+G35*(1-H35) -> 61645.968 | J35: =+I35/F35 -> 6164.5968 | K35: =+J35*K$3 -> 1294.5653 | L35: =+J35+K35 -> 7459.1622 | M35: =+L35*M$3 -> 2237.7487 | N35: =+L35+M35 -> 9696.9108 | O35: =+N35*O$3 -> 3878.7643 | P35: =+N35+O35 -> 13575.675 | R35: 51886.178 | S35: =+(I35-R35)/R35 -> 0.1881 | T35: 100022039 | U35: 61645.968
B36: 100522206 | C36: SALCHICHAS LARGAS 10 x 12 SWIFT INSTITUCIONAL | D36: 7790360983961 | E36: 8.7 | F36: 10 | G36: =+VLOOKUP(B36,$T$4:$U$104,2,FALSE) -> 61645.968 | I36: =+G36*(1-H36) -> 61645.968 | J36: =+I36/F36 -> 6164.5968 | K36: =+J36*K$3 -> 1294.5653 | L36: =+J36+K36 -> 7459.1622 | M36: =+L36*M$3 -> 2237.7487 | N36: =+L36+M36 -> 9696.9108 | O36: =+N36*O$3 -> 3878.7643 | P36: =+N36+O36 -> 13575.675 | T36: 100522206 | U36: 61645.968
B37: 100022058 | C37: SALCHICHAS SIN PIEL "LA BLANCA" 24X6X190 Grs; | D37: 7790360026002 | E37: 4.56 | F37: 24 | G37: =+VLOOKUP(B37,$T$4:$U$104,2,FALSE) -> 19639.956 | I37: =+G37*(1-H37) -> 19639.956 | J37: =+I37/F37 -> 818.33148 | K37: =+J37*K$3 -> 171.84961 | L37: =+J37+K37 -> 990.1811 | M37: =+L37*0.33 -> 326.75976 | N37: =+L37+M37 -> 1316.9409 | O37: =+N37*O$3 -> 526.77634 | P37: =+N37+O37 -> 1843.7172 | R37: 12594.915 | S37: =+(I37-R37)/R37 -> 0.55935599 | T37: 100022058 | U37: 19639.956 | X37: Ver posicionamiento por verba según necesidad de la zona
B38: 100518151 | C38: SALCHICHAS LARGAS 10 x 12 x 870g | D38: 7790360974990 | E38: 8.7 | F38: 10 | G38: =+VLOOKUP(B38,$T$4:$U$104,2,FALSE) -> 70230.314 | I38: =+G38*(1-H38) -> 70230.314 | J38: =+I38/F38 -> 7023.0314 | K38: =+J38*K$3 -> 1474.8366 | L38: =+J38+K38 -> 8497.8679 | M38: =+L38*0.33 -> 2804.2964 | N38: =+L38+M38 -> 11302.164 | O38: =+N38*O$3 -> 4520.8657 | P38: =+N38+O38 -> 15823.03 | R38: 59111.45 | S38: =+(I38-R38)/R38 -> 0.1881 | T38: 100518151 | U38: 70230.314
J39: =+I39/F39 -> #DIV/0! | K39: 0.21 | M39: 0.2 | O39: 0.35 | S39: =+(I39-R39)/R39 -> #DIV/0!
B40: 100021000 | C40: PATE DE FOIE 24X90G SWIFT | D40: 7790360720382 | E40: 2.16 | F40: 24 | G40: =+VLOOKUP(B40,$T$4:$U$104,2,FALSE) -> 13579.525 | I40: =+G40*(1-H40) -> 13579.525 | J40: =+I40/F40 -> 565.81353 | K40: =+J40*K$3 -> 118.82084 | L40: =+J40+K40 -> 684.63438 | M40: =+L40*M$39 -> 136.92688 | N40: =+L40+M40 -> 821.56125 | O40: =+N40*O$39 -> 287.54644 | P40: =+N40+O40 -> 1109.1077 | Q40: DCTO VIA NC - SUJETO A LA COMPRA DE 5 CAJAS DE C/U GOURMET | R40: 12345.023 | S40: =+(I40-R40)/R40 -> 0.1 | T40: 100021000 | U40: 13579.525
B41: 100021001 | C41: PICADILLO DE CARNE 24X90G SWIFT | D41: 7790360720115 | E41: 2.16 | F41: 24 | G41: =+VLOOKUP(B41,$T$4:$U$104,2,FALSE) -> 13579.525 | I41: =+G41*(1-H41) -> 13579.525 | J41: =+I41/F41 -> 565.81353 | K41: =+J41*K$3 -> 118.82084 | L41: =+J41+K41 -> 684.63438 | M41: =+L41*M$39 -> 136.92688 | N41: =+L41+M41 -> 821.56125 | O41: =+N41*O$39 -> 287.54644 | P41: =+N41+O41 -> 1109.1077 | Q41: DCTO VIA NC - SUJETO A LA COMPRA DE 5 CAJAS DE C/U GOURMET | R41: 12345.023 | S41: =+(I41-R41)/R41 -> 0.1 | T41: 100021001 | U41: 13579.525
...

Sheet Sub NEA
B2: Código | C2: Descripción | D2: EAN | E2: Kg. x Caja | F2: Cant. X Caja | G2: Precio de Lista | H2: dcto | I2: Precio de Factura | J2: Precio Neto estuche en factura | K2: IVA | L2: Px Unitario IVA Inc | M2: M-up Dx | N2: Px Unitario Minorista | O2: M-up Minorista | P2: Px Unitario Público | R2: PX ABRIL
K3: 0.21 | M3: 0.3 | O3: 0.4
B4: 100021632 | C4: HAMBURGUESAS 30x160g CLASICA x2 SWIFT | D4: 7790360026606 | E4: 4.8 | F4: 30 | G4: =+VLOOKUP(B4,$U$4:$V$104,2,FALSE) -> 44187.112 | I4: =+G4*(1-H4) -> 44187.112 | J4: =+I4/F4 -> 1472.9037 | K4: =+J4*K$3 -> 309.30978 | L4: =+J4+K4 -> 1782.2135 | M4: =+L4*M$3 -> 534.66406 | N4: =+L4+M4 -> 2316.8776 | O4: =+N4*O$3 -> 926.75103 | P4: =+N4+O4 -> 3243.6286 | R4: 42082.964 | S4: =+(I4-R4)/R4 -> 0.05 | U4: 100021632 | V4: 44187.112
B5: 100021652 | C5: HAMBURGUESA 18X4X80G CLASICA SWIFT | D5: 7790360026576 | E5: 5.76 | F5: 18 | G5: =+VLOOKUP(B5,$U$4:$V$104,2,FALSE) -> 57541.051 | I5: =+G5*(1-H5) -> 57541.051 | J5: =+I5/F5 -> 3196.7251 | K5: =+J5*K$3 -> 671.31226 | L5: =+J5+K5 -> 3868.0373 | M5: =+L5*M$3 -> 1160.4112 | N5: =+L5+M5 -> 5028.4485 | O5: =+N5*O$3 -> 2011.3794 | P5: =+N5+O5 -> 7039.8279 | R5: 54801.001 | S5: =+(I5-R5)/R5 -> 0.05 | U5: 100021652 | V5: 57541.051
B6: 100021631 | C6: HAMBURGUESA 8X12X80G CLASICA SWIFT | D6: 7790360026590 | E6: 7.68 | F6: 8 | G6: =+VLOOKUP(B6,$U$4:$V$104,2,FALSE) -> 67164.41 | I6: =+G6*(1-H6) -> 67164.41 | J6: =+I6/F6 -> 8395.5513 | K6: =+J6*K$3 -> 1763.0658 | L6: =+J6+K6 -> 10158.617 | M6: =+L6*M$3 -> 3047.5851 | N6: =+L6+M6 -> 13206.202 | O6: =+N6*O$3 -> 5282.4809 | P6: =+N6+O6 -> 18488.683 | R6: 80712.772 | S6: =+(I6-R6)/R6 -> -0.16785896 | U6: 100021631 | V6: 67164.41
B7: 100021630 | C7: HAMBURGUESA 6X20X80G CLASICA SWIFT | D7: 7790360026583 | E7: 9.6 | F7: 6 | G7: =+VLOOKUP(B7,$U$4:$V$104,2,FALSE) -> 82188.028 | I7: =+G7*(1-H7) -> 82188.028 | J7: =+I7/F7 -> 13698.005 | K7: =+J7*K$3 -> 2876.581 | L7: =+J7+K7 -> 16574.586 | M7: =+L7*M$3 -> 4972.3757 | N7: =+L7+M7 -> 21546.961 | O7: =+N7*O$3 -> 8618.7846 | P7: =+N7+O7 -> 30165.746 | R7: 100890.96 | S7: =+(I7-R7)/R7 -> -0.18537772 | U7: 100021630 | V7: 82188.028
B8: 100021653 | C8: MEDALLON 18X4X80G PARRILLERO SWIFT | D8: 7790360026682 | E8: 5.76 | F8: 18 | G8: =+VLOOKUP(B8,$U$4:$V$104,2,FALSE) -> 58326.988 | I8: =+G8*(1-H8) -> 58326.988 | J8: =+I8/F8 -> 3240.3882 | K8: =+J8*K$3 -> 680.48152 | L8: =+J8+K8 -> 3920.8697 | M8: =+L8*M$3 -> 1176.2609 | N8: =+L8+M8 -> 5097.1307 | O8: =+N8*O$3 -> 2038.8523 | P8: =+N8+O8 -> 7135.9829 | R8: 60814.954 | S8: =+(I8-R8)/R8 -> -0.040910438 | U8: 100021653 | V8: 58326.988
B9: 100516169 | C9: MEDALLONES 18X4X80G SWIFT RECETA ESPECIAL | D9: 7790360967961 | E9: 5.76 | F9: 18 | G9: =+VLOOKUP(B9,$U$4:$V$104,2,FALSE) -> 47534.511 | I9: =+G9*(1-H9) -> 47534.511 | J9: =+I9/F9 -> 2640.8062 | K9: =+J9*K$3 -> 554.5693 | L9: =+J9+K9 -> 3195.3755 | M9: =+L9*M$3 -> 958.61264 | N9: =+L9+M9 -> 4153.9881 | O9: =+N9*O$3 -> 1661.5952 | P9: =+N9+O9 -> 5815.5834 | R9: 47534.511 | S9: =+(I9-R9)/R9 -> 0 | U9: 100516169 | V9: 47534.511
B10: 100520337 | C10: MEDALLON BURGER SWIFT MEGA 30 x 160 g | D10: 7790360977960 | E10: 4.8 | F10: 30 | G10: =+VLOOKUP(B10,$U$4:$V$104,2,FALSE) -> 29765.977 | H10: 0.0666 | I10: =+G10*(1-H10) -> 27783.563 | J10: =+I10/F10 -> 926.11878 | K10: =+J10*K$3 -> 194.48494 | L10: =+J10+K10 -> 1120.6037 | M10: =+L10*M$3 -> 336.18112 | N10: =+L10+M10 -> 1456.7848 | O10: =+N10*O$3 -> 582.71394 | P10: =+N10+O10 -> 2039.4988 | R10: 29765.977 | S10: =+(I10-R10)/R10 -> -0.0666 | U10: 100520337 | V10: 29765.977
B11: 100021503 | C11: Medallón CAJITA 12x4 69 grs | D11: 7790360966841 | E11: 3.312 | F11: 12 | G11: =+VLOOKUP(B11,$U$4:$V$104,2,FALSE) -> 25165.542 | H11: 0.167 | I11: =+G11*(1-H11) -> 20962.897 | J11: =+I11/F11 -> 1746.9081 | K11: =+J11*K$3 -> 366.85069 | L11: =+J11+K11 -> 2113.7587 | M11: =+L11*M$3 -> 634.12762 | N11: =+L11+M11 -> 2747.8864 | O11: =+N11*O$3 -> 1099.1545 | P11: =+N11+O11 -> 3847.0409 | R11: 25165.542 | S11: =+(I11-R11)/R11 -> -0.167 | U11: 100021503 | V11: 25165.542
B12: 100516201 | C12: HAMBURGUESA 8X12X69G BURGER SWIFT | D12: 7790360968548 | E12: 6.624 | F12: 8 | G12: =+VLOOKUP(B12,$U$4:$V$104,2,FALSE) -> 49695.701 | I12: =+G12*(1-H12) -> 49695.701 | J12: =+I12/F12 -> 6211.9627 | K12: =+J12*K$3 -> 1304.5122 | L12: =+J12+K12 -> 7516.4748 | M12: =+L12*M$3 -> 2254.9425 | N12: =+L12+M12 -> 9771.4173 | O12: =+N12*O$3 -> 3908.5669 | P12: =+N12+O12 -> 13679.984 | R12: 49695.701 | S12: =+(I12-R12)/R12 -> 0 | U12: 100516201 | V12: 49695.701
B13: 100021643 | C13: MEDALLON 42X112G DOBLE BURGER SWIFT | D13: 7790360966797 | E13: 4.704 | F13: 42 | G13: =+VLOOKUP(B13,$U$4:$V$104,2,FALSE) -> 24868.421 | I13: =+G13*(1-H13) -> 24868.421 | J13: =+I13/F13 -> 592.10526 | K13: =+J13*K$3 -> 124.34211 | L13: =+J13+K13 -> 716.44737 | M13: =+L13*M$3 -> 214.93421 | N13: =+L13+M13 -> 931.38158 | O13: =+N13*O$3 -> 372.55263 | P13: =+N13+O13 -> 1303.9342 | R13: 22607.656 | S13: =+(I13-R13)/R13 -> 0.1 | U13: 100021643 | V13: 24868.421
B14: 100516325 | C14: MEDALLON DOBLE BURGER 2X2 | D14: 7790360967763 | E14: 4.704 | F14: 21 | G14: =+VLOOKUP(B14,$U$4:$V$104,2,FALSE) -> 29947.062 | I14: =+G14*(1-H14) -> 29947.062 | J14: =+I14/F14 -> 1426.0506 | K14: =+J14*K$3 -> 299.47062 | L14: =+J14+K14 -> 1725.5212 | M14: =+L14*M$3 -> 517.65635 | N14: =+L14+M14 -> 2243.1775 | O14: =+N14*O$3 -> 897.27101 | P14: =+N14+O14 -> 3140.4485 | R14: 29947.062 | S14: =+(I14-R14)/R14 -> 0 | U14: 100516325 | V14: 29947.062
B15: 100021676 | C15: HAMBURGUESA 30X250g CLASICA "XL" SWIFT | D15: 7790360967411 | E15: 7.5 | F15: 30 | G15: =+VLOOKUP(B15,$U$4:$V$104,2,FALSE) -> 70541.904 | I15: =+G15*(1-H15) -> 70541.904 | J15: =+I15/F15 -> 2351.3968 | K15: =+J15*K$3 -> 493.79333 | L15: =+J15+K15 -> 2845.1901 | M15: =+L15*M$3 -> 853.55704 | N15: =+L15+M15 -> 3698.7472 | O15: =+N15*O$3 -> 1479.4989 | P15: =+N15+O15 -> 5178.2461 | R15: 70541.904 | S15: =+(I15-R15)/R15 -> 0 | U15: 100021676 | V15: 70541.904
B16: 100516008 | C16: HAMBURGUESA 24X2X120g CASERA SWIFT | D16: 7790360967701 | E16: 5.76 | F16: 24 | G16: =+VLOOKUP(B16,$U$4:$V$104,2,FALSE) -> 68994.307 | H16: 0.0909 | I16: =+G16*(1-H16) -> 62722.725 | J16: =+I16/F16 -> 2613.4469 | K16: =+J16*K$3 -> 548.82384 | L16: =+J16+K16 -> 3162.2707 | M16: =+L16*M$3 -> 948.68121 | N16: =+L16+M16 -> 4110.9519 | O16: =+N16*O$3 -> 1644.3808 | P16: =+N16+O16 -> 5755.3327 | R16: 68994.307 | S16: =+(I16-R16)/R16 -> -0.0909 | U16: 100516008 | V16: 68994.307
B17: 100520834 | C17: HAMBURGUESA X-TREMA 36 x 185 grs | D17: 7790360980618 | E17: 6.66 | F17: 36 | G17: =+VLOOKUP(B17,$U$4:$V$104,2,FALSE) -> 67560.059 | I17: =+G17*(1-H17) -> 67560.059 | J17: =+I17/F17 -> 1876.6683 | K17: =+J17*K$3 -> 394.10034 | L17: =+J17+K17 -> 2270.7686 | M17: =+L17*M$3 -> 681.23059 | N17: =+L17+M17 -> 2951.9992 | O17: =+N17*O$3 -> 1180.7997 | P17: =+N17+O17 -> 4132.7989 | R17: 67560.059 | S17: =+(I17-R17)/R17 -> 0 | U17: 100520834 | V17: 67560.059
B18: 100021680 | C18: HAMBURGUESAS 18X2X120g CLL BRA/ARG | D18: 7790360967688 | E18: 4.32 | F18: 18 | G18: =+VLOOKUP(B18,$U$4:$V$104,2,FALSE) -> 52915.791 | I18: =+G18*(1-H18) -> 52915.791 | J18: =+I18/F18 -> 2939.7661 | K18: =+J18*K$3 -> 617.35089 | L18: =+J18+K18 -> 3557.117 | M18: =+L18*M$3 -> 1067.1351 | N18: =+L18+M18 -> 4624.2522 | O18: =+N18*O$3 -> 1849.7009 | P18: =+N18+O18 -> 6473.953 | R18: 52915.791 | S18: =+(I18-R18)/R18 -> 0 | U18: 100021680 | V18: 52915.791
B19: 100021644 | C19: MEDALLON 42X112G LA BLANCA | D19: 7790360008541 | E19: 4.704 | F19: 42 | G19: =+VLOOKUP(B19,$U$4:$V$104,2,FALSE) -> 21066.231 | H19: 0.054 | I19: =+G19*(1-H19) -> 19928.654 | J19: =+I19/F19 -> 474.49177 | K19: =+J19*K$3 -> 99.643272 | L19: =+J19+K19 -> 574.13504 | M19: =+L19*0.33 -> 189.46456 | N19: =+L19+M19 -> 763.5996 | O19: =+N19*O$3 -> 305.43984 | P19: =+N19+O19 -> 1069.0394 | R19: 19151.119 | S19: =+(I19-R19)/R19 -> 0.0406 | U19: 100021644 | V19: 21066.231
B20: 100021677 | C20: MEDALLON 12x4X69G LA BLANCA | D20: 7790360967404 | E20: 3.312 | F20: 12 | G20: =+VLOOKUP(B20,$U$4:$V$104,2,FALSE) -> 15913.331 | I20: =+G20*(1-H20) -> 15913.331 | J20: =+I20/F20 -> 1326.1109 | K20: =+J20*K$3 -> 278.48329 | L20: =+J20+K20 -> 1604.5942 | M20: =+L20*0.33 -> 529.51608 | N20: =+L20+M20 -> 2134.1103 | O20: =+N20*O$3 -> 853.64411 | P20: =+N20+O20 -> 2987.7544 | R20: 15913.331 | S20: =+(I20-R20)/R20 -> 0 | U20: 100021677 | V20: 15913.331
B21: 100021638 | C21: MEDALLONES 60X80g "SWIFT BURGER" PARRILLERAS FAMILY | D21: 7790360026699 | E21: 4.8 | F21: 60 | G21: =+VLOOKUP(B21,$U$4:$V$104,2,FALSE) -> 53909.27 | I21: =+G21*(1-H21) -> 53909.27 | J21: =+I21/F21 -> 898.48783 | K21: =+J21*K$3 -> 188.68244 | L21: =+J21+K21 -> 1087.1703 | M21: =+L21*M$3 -> 326.15108 | N21: =+L21+M21 -> 1413.3214 | O21: =+N21*O$3 -> 565.32854 | P21: =+N21+O21 -> 1978.6499 | R21: 53909.27 | S21: =+(I21-R21)/R21 -> 0 | U21: 100021638 | V21: 53909.27
B22: 100021575 | C22: MEDALLONES 60X69g "SWIFT BURGER"PARRILLERAS FAMILY | D22: 7790360007032 | E22: 4.14 | F22: 60 | G22: =+VLOOKUP(B22,$U$4:$V$104,2,FALSE) -> 43782.411 | I22: =+G22*(1-H22) -> 43782.411 | J22: =+I22/F22 -> 729.70684 | K22: =+J22*K$3 -> 153.23844 | L22: =+J22+K22 -> 882.94528 | M22: =+L22*M$3 -> 264.88358 | N22: =+L22+M22 -> 1147.8289 | O22: =+N22*O$3 -> 459.13155 | P22: =+N22+O22 -> 1606.9604 | R22: 43782.411 | S22: =+(I22-R22)/R22 -> 0 | U22: 100021575 | V22: 43782.411
B23: 100021514 | C23: MEDALLON 60X69G CARNE VACUNA | D23: 7790360006943 | E23: 4.14 | F23: 60 | G23: =+VLOOKUP(B23,$U$4:$V$104,2,FALSE) -> 40234.645 | I23: =+G23*(1-H23) -> 40234.645 | J23: =+I23/F23 -> 670.57741 | K23: =+J23*K$3 -> 140.82126 | L23: =+J23+K23 -> 811.39867 | M23: =+L23*M$3 -> 243.4196 | N23: =+L23+M23 -> 1054.8183 | O23: =+N23*O$3 -> 421.92731 | P23: =+N23+O23 -> 1476.7456 | R23: 40234.645 | S23: =+(I23-R23)/R23 -> 0 | U23: 100021514 | V23: 40234.645
B24: 100516208 | C24: MEDALLON 60x80g PARRILLERO MC SWIFT | D24: 7790360968203 | E24: =60*0.08 -> 4.8 | F24: 60 | G24: =+VLOOKUP(B24,$U$4:$V$104,2,FALSE) -> 46172.879 | I24: =+G24*(1-H24) -> 46172.879 | J24: =+I24/F24 -> 769.54798 | K24: =+J24*K$3 -> 161.60508 | L24: =+J24+K24 -> 931.15306 | M24: =+L24*M$3 -> 279.34592 | N24: =+L24+M24 -> 1210.499 | O24: =+N24*O$3 -> 484.19959 | P24: =+N24+O24 -> 1694.6986 | R24: 46172.879 | S24: =+(I24-R24)/R24 -> 0 | U24: 100516208 | V24: 46172.879
B25: 100518346 | C25: MEDALLON 60X109G CARNE VACUNA PARRILLERO SWIFT | E25: 6.54 | F25: 60 | G25: =+VLOOKUP(B25,$U$4:$V$104,2,FALSE) -> 63499.785 | I25: =+G25*(1-H25) -> 63499.785 | J25: =+I25/F25 -> 1058.3298 | K25: =+J25*K$3 -> 222.24925 | L25: =+J25+K25 -> 1280.579 | M25: =+L25*M$3 -> 384.1737 | N25: =+L25+M25 -> 1664.7527 | O25: =+N25*O$3 -> 665.90108 | P25: =+N25+O25 -> 2330.6538 | R25: 63499.785 | S25: =+(I25-R25)/R25 -> 0 | U25: 100518346 | V25: 63499.785
B26: 100516259 | C26: MEDALLON GIGANTE 48x113.5g | D26: 7790360968340 | E26: 18.16 | F26: 48 | G26: =+VLOOKUP(B26,$U$4:$V$104,2,FALSE) -> 149542.39 | I26: =+G26*(1-H26) -> 149542.39 | J26: =+I26/F26 -> 3115.4665 | K26: =+J26*K$3 -> 654.24798 | L26: =+J26+K26 -> 3769.7145 | M26: =+L26*M$3 -> 1130.9144 | N26: =+L26+M26 -> 4900.6289 | O26: =+N26*O$3 -> 1960.2516 | P26: =+N26+O26 -> 6860.8804 | R26: 149542.39 | S26: =+(I26-R26)/R26 -> 0 | U26: 100516259 | V26: 149542.39
B27: 100518095 | C27: HAMBURGUESA 36 X 185 GRS | D27: 7790360974785 | E27: 6.66 | F27: 36 | G27: =+VLOOKUP(B27,$U$4:$V$104,2,FALSE) -> 70960.925 | I27: =+G27*(1-H27) -> 70960.925 | J27: =+I27/F27 -> 1971.1368 | K27: =+J27*K$3 -> 413.93873 | L27: =+J27+K27 -> 2385.0755 | M27: =+L27*M$3 -> 715.52266 | N27: =+L27+M27 -> 3100.5982 | O27: =+N27*O$3 -> 1240.2393 | P27: =+N27+O27 -> 4340.8375 | R27: 70960.925 | S27: =+(I27-R27)/R27 -> 0 | U27: 100518095 | V27: 70960.925
B28: 100518223 | C28: HAMBURGUESA 30x2x106 GRS | D28: 7790360975065 | E28: =60*0.106 -> 6.36 | F28: 30 | G28: =+VLOOKUP(B28,$U$4:$V$104,2,FALSE) -> 55247.024 | I28: =+G28*(1-H28) -> 55247.024 | J28: =+I28/F28 -> 1841.5675 | K28: =+J28*K$3 -> 386.72917 | L28: =+J28+K28 -> 2228.2966 | M28: =+L28*M$3 -> 668.48899 | N28: =+L28+M28 -> 2896.7856 | O28: =+N28*O$3 -> 1158.7142 | P28: =+N28+O28 -> 4055.4999 | R28: 55247.024 | S28: =+(I28-R28)/R28 -> 0 | U28: 100518223 | V28: 55247.024
G29: =+VLOOKUP(B29,$U$4:$V$104,2,FALSE) -> #N/A | I29: =+G29*(1-H29) -> #N/A | J29: =+I29/F29 -> #N/A | K29: 0.21 | M29: 0.3 | O29: 0.4 | R29: #N/A | S29: =+(I29-R29)/R29 -> #N/A | V29: #VALUE!
B30: 100022085 | C30: SALCHICHAS 24X6 SWIFT | D30: 7790360000132 | E30: 5.4 | F30: 24 | G30: =+VLOOKUP(B30,$U$4:$V$104,2,FALSE) -> 26853.823 | I30: =+G30*(1-H30) -> 26853.823 | J30: =+I30/F30 -> 1118.9093 | K30: =+J30*K$3 -> 234.97095 | L30: =+J30+K30 -> 1353.8802 | M30: =+L30*M$3 -> 406.16407 | N30: =+L30+M30 -> 1760.0443 | O30: =+N30*O$3 -> 704.01772 | P30: =+N30+O30 -> 2464.062 | R30: 23435.086 | S30: =+(I30-R30)/R30 -> 0.14588115 | U30: 100022085 | V30: 26853.823
B31: 100522204 | C31: SALCHICHAS 24X6 SWIFT | D31: 7790360983947 | E31: 5.4 | F31: 24 | G31: =+VLOOKUP(B31,$U$4:$V$104,2,FALSE) -> 26853.823 | I31: =+G31*(1-H31) -> 26853.823 | J31: =+I31/F31 -> 1118.9093 | K31: =+J31*K$3 -> 234.97095 | L31: =+J31+K31 -> 1353.8802 | M31: =+L31*M$3 -> 406.16407 | N31: =+L31+M31 -> 1760.0443 | O31: =+N31*O$3 -> 704.01772 | P31: =+N31+O31 -> 2464.062 | R31: 0 | U31: 100522204 | V31: 26853.823
B32: 100022072 | C32: SALCHICHAS 12X12 SWIFT | D32: 7790360024541 | E32: 5.4 | F32: 12 | G32: =+VLOOKUP(B32,$U$4:$V$104,2,FALSE) -> 25511.132 | I32: =+G32*(1-H32) -> 25511.132 | J32: =+I32/F32 -> 2125.9276 | K32: =+J32*K$3 -> 446.44481 | L32: =+J32+K32 -> 2572.3724 | M32: =+L32*M$3 -> 771.71173 | N32: =+L32+M32 -> 3344.0842 | O32: =+N32*O$3 -> 1337.6337 | P32: =+N32+O32 -> 4681.7179 | R32: 21677.574 | S32: =+(I32-R32)/R32 -> 0.1768444 | U32: 100022072 | V32: 25511.132
B33: 100522205 | C33: SALCHICHAS 12X12 SWIFT | D33: 7790360983954 | E33: 5.4 | F33: 12 | G33: =+VLOOKUP(B33,$U$4:$V$104,2,FALSE) -> 25511.132 | I33: =+G33*(1-H33) -> 25511.132 | J33: =+I33/F33 -> 2125.9276 | K33: =+J33*K$3 -> 446.44481 | L33: =+J33+K33 -> 2572.3724 | M33: =+L33*M$3 -> 771.71173 | N33: =+L33+M33 -> 3344.0842 | O33: =+N33*O$3 -> 1337.6337 | P33: =+N33+O33 -> 4681.7179 | R33: 0 | U33: 100522205 | V33: 25511.132
B34: 100516849 | C34: SALCHICHAS SIN PIEL 24X6 "SWIFT KIDS" X 190 g | D34: 7790360970053 | E34: 4.56 | F34: 24 | G34: =+VLOOKUP(B34,$U$4:$V$104,2,FALSE) -> 21483.058 | I34: =+G34*(1-H34) -> 21483.058 | J34: =+I34/F34 -> 895.12743 | K34: =+J34*K$3 -> 187.97676 | L34: =+J34+K34 -> 1083.1042 | M34: =+L34*M$3 -> 324.93126 | N34: =+L34+M34 -> 1408.0354 | O34: =+N34*O$3 -> 563.21418 | P34: =+N34+O34 -> 1971.2496 | R34: 19919.988 | S34: =+(I34-R34)/R34 -> 0.078467421 | U34: 100516849 | V34: 21483.058
B35: 100022039 | C35: SALCHICHAS LARGAS 10 x 12 SWIFT INSTITUCIONAL | D35: 7790360007063 | E35: 8.7 | F35: 10 | G35: =+VLOOKUP(B35,$U$4:$V$104,2,FALSE) -> 66403.468 | I35: =+G35*(1-H35) -> 66403.468 | J35: =+I35/F35 -> 6640.3468 | K35: =+J35*K$3 -> 1394.4728 | L35: =+J35+K35 -> 8034.8197 | M35: =+L35*M$3 -> 2410.4459 | N35: =+L35+M35 -> 10445.266 | O35: =+N35*O$3 -> 4178.1062 | P35: =+N35+O35 -> 14623.372 | R35: 60366.789 | S35: =+(I35-R35)/R35 -> 0.1 | U35: 100022039 | V35: 66403.468
B36: 100522206 | C36: SALCHICHAS LARGAS 10 x 12 SWIFT INSTITUCIONAL | D36: 7790360983961 | E36: 8.7 | F36: 10 | G36: =+VLOOKUP(B36,$U$4:$V$104,2,FALSE) -> 66403.468 | I36: =+G36*(1-H36) -> 66403.468 | J36: =+I36/F36 -> 6640.3468 | K36: =+J36*K$3 -> 1394.4728 | L36: =+J36+K36 -> 8034.8197 | M36: =+L36*M$3 -> 2410.4459 | N36: =+L36+M36 -> 10445.266 | O36: =+N36*O$3 -> 4178.1062 | P36: =+N36+O36 -> 14623.372 | R36: 0 | U36: 100522206 | V36: 66403.468
B37: 100022058 | C37: SALCHICHAS SIN PIEL "LA BLANCA" 24X6X190 Grs; | D37: 7790360026002 | E37: 4.56 | F37: 24 | G37: =+VLOOKUP(B37,$U$4:$V$104,2,FALSE) -> 18273.698 | I37: =+G37*(1-H37) -> 18273.698 | J37: =+I37/F37 -> 761.40408 | K37: =+J37*K$3 -> 159.89486 | L37: =+J37+K37 -> 921.29893 | M37: =+L37*0.33 -> 304.02865 | N37: =+L37+M37 -> 1225.3276 | O37: =+N37*O$3 -> 490.13103 | P37: =+N37+O37 -> 1715.4586 | R37: 12772.19 | S37: =+(I37-R37)/R37 -> 0.43074113 | U37: 100022058 | V37: 18273.698 | X37: Ver posicionamiento por verba según necesidad de la zona
B38: 100518151 | C38: SALCHICHAS LARGAS 10 x 12 x 870g | D38: 7790360974990 | E38: 8.7 | F38: 10 | G38: =+VLOOKUP(B38,$U$4:$V$104,2,FALSE) -> 76363.989 | I38: =+G38*(1-H38) -> 76363.989 | J38: =+I38/F38 -> 7636.3989 | K38: =+J38*K$3 -> 1603.6438 | L38: =+J38+K38 -> 9240.0426 | M38: =+L38*0.33 -> 3049.2141 | N38: =+L38+M38 -> 12289.257 | O38: =+N38*O$3 -> 4915.7027 | P38: =+N38+O38 -> 17204.959 | R38: 69421.808 | S38: =+(I38-R38)/R38 -> 0.1 | U38: 100518151 | V38: 76363.989
G39: =+VLOOKUP(B39,$U$4:$V$104,2,FALSE) -> #N/A | I39: =+G39*(1-H39) -> #N/A | J39: =+I39/F39 -> #N/A | K39: 0.21 | M39: 0.2 | O39: 0.35 | R39: #N/A | S39: =+(I39-R39)/R39 -> #N/A | V39: #VALUE!
B40: 100021000 | C40: PATE DE FOIE 24X90G SWIFT | D40: 7790360720382 | E40: 2.16 | F40: 24 | G40: =+VLOOKUP(B40,$U$4:$V$104,2,FALSE) -> 13579.525 | I40: =+G40*(1-H40) -> 13579.525 | J40: =+I40/F40 -> 565.81353 | K40: =+J40*K$3 -> 118.82084 | L40: =+J40+K40 -> 684.63438 | M40: =+L40*M$39 -> 136.92688 | N40: =+L40+M40 -> 821.56125 | O40: =+N40*O$39 -> 287.54644 | P40: =+N40+O40 -> 1109.1077 | Q40: DCTO VIA NC - SUJETO A LA COMPRA DE 5 CAJAS DE C/U GOURMET | R40: 13579.525 | S40: =+(I40-R40)/R40 -> 0 | U40: 100021000 | V40: 13579.525
B41: 100021001 | C41: PICADILLO DE CARNE 24X90G SWIFT | D41: 7790360720115 | E41: 2.16 | F41: 24 | G41: =+VLOOKUP(B41,$U$4:$V$104,2,FALSE) -> 13579.525 | I41: =+G41*(1-H41) -> 13579.525 | J41: =+I41/F41 -> 565.81353 | K41: =+J41*K$3 -> 118.82084 | L41: =+J41+K41 -> 684.63438 | M41: =+L41*M$39 -> 136.92688 | N41: =+L41+M41 -> 821.56125 | O41: =+N41*O$39 -> 287.54644 | P41: =+N41+O41 -> 1109.1077 | Q41: DCTO VIA NC - SUJETO A LA COMPRA DE 5 CAJAS DE C/U GOURMET | R41: 13579.525 | S41: =+(I41-R41)/R41 -> 0 | U41: 100021001 | V41: 13579.525
...

Sheet Sub NOA
B2: Código | C2: Descripción | D2: EAN | E2: Kg. x Caja | F2: Cant. X Caja | G2: Precio de Lista | H2: Dcto | I2: Precio de Factura | J2: Precio Neto estuche en factura | K2: IVA | L2: Px Unitario IVA Inc | M2: M-up Dx | N2: Px Unitario Minorista | O2: M-up Minorista | P2: Px Unitario Público | R2: PX ABR
K3: 0.21 | M3: 0.3 | O3: 0.4
B4: 100021632 | C4: HAMBURGUESAS 30x160g CLASICA x2 SWIFT | D4: 7790360026606 | E4: 4.8 | F4: 30 | G4: =+VLOOKUP(B4,$U$4:$V$104,2,FALSE) -> 36141.234 | I4: =+G4*(1-H4) -> 36141.234 | J4: =+I4/F4 -> 1204.7078 | K4: =+J4*K$3 -> 252.98864 | L4: =+J4+K4 -> 1457.6965 | M4: =+L4*M$3 -> 437.30894 | N4: =+L4+M4 -> 1895.0054 | O4: =+N4*O$3 -> 758.00216 | P4: =+N4+O4 -> 2653.0076 | R4: 33114.563 | S4: =+(I4-R4)/R4 -> 0.0914 | U4: 100021632 | V4: 36141.234
B5: 100021652 | C5: HAMBURGUESA 18X4X80G CLASICA SWIFT | D5: 7790360026576 | E5: 5.76 | F5: 18 | G5: =+VLOOKUP(B5,$U$4:$V$104,2,FALSE) -> 51551.959 | I5: =+G5*(1-H5) -> 51551.959 | J5: =+I5/F5 -> 2863.9977 | K5: =+J5*K$3 -> 601.43952 | L5: =+J5+K5 -> 3465.4372 | M5: =+L5*M$3 -> 1039.6312 | N5: =+L5+M5 -> 4505.0684 | O5: =+N5*O$3 -> 1802.0274 | P5: =+N5+O5 -> 6307.0958 | R5: 48179.401 | S5: =+(I5-R5)/R5 -> 0.07 | U5: 100021652 | V5: 51551.959
B6: 100021631 | C6: HAMBURGUESA 8X12X80G CLASICA SWIFT | D6: 7790360026590 | E6: 7.68 | F6: 8 | G6: =+VLOOKUP(B6,$U$4:$V$104,2,FALSE) -> 63608.573 | I6: =+G6*(1-H6) -> 63608.573 | J6: =+I6/F6 -> 7951.0716 | K6: =+J6*K$3 -> 1669.725 | L6: =+J6+K6 -> 9620.7966 | M6: =+L6*M$3 -> 2886.239 | N6: =+L6+M6 -> 12507.036 | O6: =+N6*O$3 -> 5002.8142 | P6: =+N6+O6 -> 17509.85 | R6: 70485.893 | S6: =+(I6-R6)/R6 -> -0.097570167 | U6: 100021631 | V6: 63608.573
B7: 100021630 | C7: HAMBURGUESA 6X20X80G CLASICA SWIFT | D7: 7790360026583 | E7: 9.6 | F7: 6 | G7: =+VLOOKUP(B7,$U$4:$V$104,2,FALSE) -> 79510.716 | I7: =+G7*(1-H7) -> 79510.716 | J7: =+I7/F7 -> 13251.786 | K7: =+J7*K$3 -> 2782.8751 | L7: =+J7+K7 -> 16034.661 | M7: =+L7*M$3 -> 4810.3983 | N7: =+L7+M7 -> 20845.059 | O7: =+N7*O$3 -> 8338.0237 | P7: =+N7+O7 -> 29183.083 | R7: 88089.919 | S7: =+(I7-R7)/R7 -> -0.097391432 | U7: 100021630 | V7: 79510.716
B8: 100021653 | C8: MEDALLON 18X4X80G PARRILLERO SWIFT | D8: 7790360026682 | E8: 5.76 | F8: 18 | G8: =+VLOOKUP(B8,$U$4:$V$104,2,FALSE) -> 51551.959 | I8: =+G8*(1-H8) -> 51551.959 | J8: =+I8/F8 -> 2863.9977 | K8: =+J8*K$3 -> 601.43952 | L8: =+J8+K8 -> 3465.4372 | M8: =+L8*M$3 -> 1039.6312 | N8: =+L8+M8 -> 4505.0684 | O8: =+N8*O$3 -> 1802.0274 | P8: =+N8+O8 -> 6307.0958 | R8: 56884.18 | S8: =+(I8-R8)/R8 -> -0.093738215 | U8: 100021653 | V8: 51551.959
