Workbook

Sheet Resumen
C1: =+IF(AND(C14-C24<=0.01, C14-C24>=-0.01), "", C14-C24) | D1: =+IF(AND(D14-D24<=0.01, D14-D24>=-0.01), "", D14-D24) | E1: =+IF(AND(E14-E24<=0.01, E14-E24>=-0.01), "", E14-E24) | F1: =+IF(AND(F14-F24<=0.01, F14-F24>=-0.01), "", F14-F24) | G1: Avance: | H1: =+L4/L3 -> 0.83333333
B2: Clase | C2: Meta | D2: Volumen Neto | E2: Pendientes | F2: Total | G2: Avance Facturado | H2: Avance Total
B3: HAMBURGUESAS | C3: =+HG!AJ47 -> 1805000 | D3: =+HG!AL47 -> 1135327.4 | E3: =+HG!AK47 -> 188098.81 | F3: =+D3+E3 -> 1323426.2 | G3: =IFERROR(+D3/C3,0) -> 0.62899022 | H3: =IFERROR(+F3/C3,0) -> 0.73320009 | K3: Días Hábiles | L3: 18
B4: SALCHICHAS | C4: =+SCH!AJ47 -> 800000 | D4: =+SCH!AL47 -> 456617.04 | E4: =+SCH!AK47 -> 124907.82 | F4: =+D4+E4 -> 581524.86 | G4: =IFERROR(+D4/C4,0) -> 0.5707713 | H4: =IFERROR(+F4/C4,0) -> 0.72690607 | K4: Días transc. | L4: 15
B5: UNTABLES | C5: =+UNT!AJ47 -> 911000 | D5: =+UNT!AL47 -> 477518.78 | E5: =+UNT!AK47 -> 303845.06 | F5: =+D5+E5 -> 781363.84 | G5: =IFERROR(+D5/C5,0) -> 0.52416991 | H5: =IFERROR(+F5/C5,0) -> 0.85769906 | K5: Avance | L5: =+L4/L3 -> 0.83333333
B6: ATUN | C6: =+ATUN!AJ47 -> 11000 | D6: =+ATUN!AL47 -> 3973.92 | E6: =+ATUN!AK47 -> 3541.44 | F6: =+D6+E6 -> 7515.36 | G6: =IFERROR(+D6/C6,0) -> 0.36126545 | H6: =IFERROR(+F6/C6,0) -> 0.68321455
B7: REBOZADOS DE CARNE | C7: =+RB!AJ47 -> 174000 | D7: =+RB!AL47 -> 101288.56 | E7: =+RB!AK47 -> 26626.56 | F7: =+D7+E7 -> 127915.12 | G7: =IFERROR(+D7/C7,0) -> 0.58211816 | H7: =IFERROR(+F7/C7,0) -> 0.73514437
B8: REBOZADOS DE VEGETALES | C8: =+SJ!AJ47 -> 29000 | D8: =+SJ!AL47 -> 17342.4 | E8: =+SJ!AK47 -> 4196.4 | F8: =+D8+E8 -> 21538.8 | G8: =IFERROR(+D8/C8,0) -> 0.59801379 | H8: =IFERROR(+F8/C8,0) -> 0.74271724
B9: GRASA | C9: =+GRASA!AJ47 -> 59000 | D9: =+GRASA!AL47 -> 26019 | E9: =+GRASA!AK47 -> 37944 | F9: =+D9+E9 -> 63963 | G9: =IFERROR(+D9/C9,0) -> 0.441 | H9: =IFERROR(+F9/C9,0) -> 1.0841186
B10: CARNE PICADA | C10: =+PICADA!AJ47 -> 18000 | D10: =+PICADA!AL47 -> 7412 | E10: =+PICADA!AK47 -> 4146 | F10: =+D10+E10 -> 11558 | G10: =IFERROR(+D10/C10,0) -> 0.41177778 | H10: =IFERROR(+F10/C10,0) -> 0.64211111
B11: PAPAS | C11: =+PAPAS!AJ47 -> 76000 | D11: =+PAPAS!AL47 -> 40068 | E11: =+PAPAS!AK47 -> 5957 | F11: =+D11+E11 -> 46025 | G11: =IFERROR(+D11/C11,0) -> 0.52721053 | H11: =IFERROR(+F11/C11,0) -> 0.60559211
B12: CHORIZOS | C12: =+CHORIZOS!AJ47 -> 10300 | D12: =+CHORIZOS!AL47 -> 3585.04 | E12: =+CHORIZOS!AK47 -> 1592 | F12: =+D12+E12 -> 5177.04 | G12: =IFERROR(+D12/C12,0) -> 0.34806214 | H12: =IFERROR(+F12/C12,0) -> 0.50262524
B13: CORTES PORCIONADOS | C13: =+'CORTES PORC'!AJ47 -> 0 | D13: =+'CORTES PORC'!AL47 -> 0 | E13: =+'CORTES PORC'!AK47 -> 0 | F13: =+D13+E13 -> 0 | G13: =IFERROR(+D13/C13,0) -> 0 | H13: =IFERROR(+F13/C13,0) -> 0
B14: Total | C14: =SUM(C3:C13) -> 3893300 | D14: =SUM(D3:D13) -> 2269152.1 | E14: =SUM(E3:E13) -> 700855.09 | F14: =SUM(F3:F13) -> 2970007.2 | G14: =IFERROR(+D14/C14,0) -> 0.58283515 | H14: =IFERROR(+F14/C14,0) -> 0.76285084
B16: Resumen | C16: Meta Total | D16: Volumen Neto | E16: Pendientes | F16: Total | G16: Avance Facturado | H16: Avance Total
B17: Distribuidores Interior | C17: =+C28+C38+C48+C58+C68+C78+C88+C98+C108+C118+C128 -> 1477950 | D17: =+D28+D38+D48+D58+D68+D78+D88+D98+D108+D118+D128 -> 972618.25 | E17: =+E28+E38+E48+E58+E68+E78+E88+E98+E108+E118+E128 -> 175595.03 | F17: =+F28+F38+F48+F58+F68+F78+F88+F98+F108+F118+F128 -> 1148213.3 | G17: =IFERROR(+D17/C17,0) -> 0.65808603 | H17: =IFERROR(+F17/C17,0) -> 0.77689589
B18: Regionales Interior | C18: =+C29+C39+C49+C59+C69+C79+C89+C99+C109+C119+C129 -> 339700 | D18: =+D29+D39+D49+D59+D69+D79+D89+D99+D109+D119+D129 -> 235521.44 | E18: =+E29+E39+E49+E59+E69+E79+E89+E99+E109+E119+E129 -> 56081.42 | F18: =+F29+F39+F49+F59+F69+F79+F89+F99+F109+F119+F129 -> 291602.86 | G18: =IFERROR(+D18/C18,0) -> 0.69332187 | H18: =IFERROR(+F18/C18,0) -> 0.85841289
B19: Distribuidores GBA y Costa | C19: =+C30+C40+C50+C60+C70+C80+C90+C100+C110+C120+C130 -> 563540 | D19: =+D30+D40+D50+D60+D70+D80+D90+D100+D110+D120+D130 -> 245564.29 | E19: =+E30+E40+E50+E60+E70+E80+E90+E100+E110+E120+E130 -> 102871.53 | F19: =+F30+F40+F50+F60+F70+F80+F90+F100+F110+F120+F130 -> 348435.82 | G19: =IFERROR(+D19/C19,0) -> 0.43575308 | H19: =IFERROR(+F19/C19,0) -> 0.61829829
B20: Regionales GBA, Costa y Patagonia | C20: =+C31+C41+C51+C61+C71+C81+C91+C101+C111+C121+C131 -> 32810 | D20: =+D31+D41+D51+D61+D71+D81+D91+D101+D111+D121+D131 -> 6446 | E20: =+E31+E41+E51+E61+E71+E81+E91+E101+E111+E121+E131 -> 6182.53 | F20: =+F31+F41+F51+F61+F71+F81+F91+F101+F111+F121+F131 -> 12628.53 | G20: =IFERROR(+D20/C20,0) -> 0.19646449 | H20: =IFERROR(+F20/C20,0) -> 0.38489881
B21: Gastronomía | C21: =+C32+C42+C52+C62+C72+C82+C92+C102+C112+C122+C132 -> 307300 | D21: =+D32+D42+D52+D62+D72+D82+D92+D102+D112+D122+D132 -> 242052.16 | E21: =+E32+E42+E52+E62+E72+E82+E92+E102+E112+E122+E132 -> 26820.89 | F21: =+F32+F42+F52+F62+F72+F82+F92+F102+F112+F122+F132 -> 268873.05 | G21: =IFERROR(+D21/C21,0) -> 0.7876738 | H21: =IFERROR(+F21/C21,0) -> 0.87495298
B22: Mayoristas | C22: =+C33+C43+C53+C63+C73+C83+C93+C103+C113+C123+C133 -> 350500 | D22: =+D33+D43+D53+D63+D73+D83+D93+D103+D113+D123+D133 -> 109886.23 | E22: =+E33+E43+E53+E63+E73+E83+E93+E103+E113+E123+E133 -> 167562.59 | F22: =+F33+F43+F53+F63+F73+F83+F93+F103+F113+F123+F133 -> 277448.82 | G22: =IFERROR(+D22/C22,0) -> 0.31351278 | H22: =IFERROR(+F22/C22,0) -> 0.79158008
B23: Cadenas | C23: =+C34+C44+C54+C64+C74+C84+C94+C104+C114+C124+C134 -> 821500 | D23: =+D34+D44+D54+D64+D74+D84+D94+D104+D114+D124+D134 -> 457063.73 | E23: =+E34+E44+E54+E64+E74+E84+E94+E104+E114+E124+E134 -> 165741.1 | F23: =+F34+F44+F54+F64+F74+F84+F94+F104+F114+F124+F134 -> 622804.83 | G23: =IFERROR(+D23/C23,0) -> 0.55637703 | H23: =IFERROR(+F23/C23,0) -> 0.75813126
B24: Total | C24: =SUM(C17:C23) -> 3893300 | D24: =SUM(D17:D23) -> 2269152.1 | E24: =SUM(E17:E23) -> 700855.09 | F24: =SUM(F17:F23) -> 2970007.2 | G24: =IFERROR(+D24/C24,0) -> 0.58283515 | H24: =IFERROR(+F24/C24,0) -> 0.76285084
B27: HAMBURGUESAS | C27: Meta Total | D27: Volumen Neto | E27: Pendientes | F27: Total | G27: Avance Facturado | H27: Avance Total
B28: Distribuidores Interior | C28: =+HG!$AJ$18 -> 655000 | D28: =+HG!$AL$18 -> 487355.95 | E28: =+HG!$AK$18 -> 37342.53 | F28: =+D28+E28 -> 524698.48 | G28: =IFERROR(+D28/C28,0) -> 0.74405489 | H28: =IFERROR(+F28/C28,0) -> 0.80106638
B29: Regionales Interior | C29: =+HG!$AJ$22 -> 115000 | D29: =+HG!$AL$22 -> 82063.584 | E29: =+HG!$AK$22 -> 17739.3 | F29: =+D29+E29 -> 99802.884 | G29: =IFERROR(+D29/C29,0) -> 0.71359638 | H29: =IFERROR(+F29/C29,0) -> 0.86785117
B30: Distribuidores GBA y Costa | C30: =+HG!$AJ$28 -> 275000 | D30: =+HG!$AL$28 -> 117367 | E30: =+HG!$AK$28 -> 19352.4 | F30: =+D30+E30 -> 136719.4 | G30: =IFERROR(+D30/C30,0) -> 0.42678908 | H30: =IFERROR(+F30/C30,0) -> 0.49716144
B31: Regionales GBA, Costa y Patagonia | C31: =+HG!$AJ$30 -> 15000 | D31: =+HG!$AL$30 -> 1979.76 | E31: =+HG!$AK$30 -> 2364.49 | F31: =+D31+E31 -> 4344.25 | G31: =IFERROR(+D31/C31,0) -> 0.131984 | H31: =IFERROR(+F31/C31,0) -> 0.28961667
B32: Gastronomía | C32: =+HG!$AJ$33 -> 275000 | D32: =+HG!$AL$33 -> 220875.3 | E32: =+HG!$AK$33 -> 21931.61 | F32: =+D32+E32 -> 242806.91 | G32: =IFERROR(+D32/C32,0) -> 0.80318291 | H32: =IFERROR(+F32/C32,0) -> 0.88293422
B33: Mayoristas | C33: =+HG!$AJ$37 -> 100000 | D33: =+HG!$AL$37 -> 41774.232 | E33: =+HG!$AK$37 -> 15018.28 | F33: =+D33+E33 -> 56792.512 | G33: =IFERROR(+D33/C33,0) -> 0.41774232 | H33: =IFERROR(+F33/C33,0) -> 0.56792512
B34: Cadenas | C34: =+HG!$AJ$46 -> 370000 | D34: =+HG!$AL$46 -> 183911.53 | E34: =+HG!$AK$46 -> 74350.2 | F34: =+D34+E34 -> 258261.73 | G34: =IFERROR(+D34/C34,0) -> 0.49705819 | H34: =IFERROR(+F34/C34,0) -> 0.69800468
B35: Total | C35: =SUM(C28:C34) -> 1805000 | D35: =SUM(D28:D34) -> 1135327.4 | E35: =SUM(E28:E34) -> 188098.81 | F35: =SUM(F28:F34) -> 1323426.2 | G35: =IFERROR(+D35/C35,0) -> 0.62899022 | H35: =IFERROR(+F35/C35,0) -> 0.73320009
B37: SALCHICHAS | C37: Meta Total | D37: Volumen Neto | E37: Pendientes | F37: Total | G37: Avance Facturado | H37: Avance Total
B38: Distribuidores Interior | C38: =+SCH!$AJ$18 -> 343500 | D38: =+SCH!$AL$18 -> 200331.3 | E38: =+SCH!$AK$18 -> 54181.56 | F38: =+D38+E38 -> 254512.86 | G38: =IFERROR(+D38/C38,0) -> 0.58320611 | H38: =IFERROR(+F38/C38,0) -> 0.74093991
B39: Regionales Interior | C39: =+SCH!$AJ$22 -> 82500 | D39: =+SCH!$AL$22 -> 58047.36 | E39: =+SCH!$AK$22 -> 15522.48 | F39: =+D39+E39 -> 73569.84 | G39: =IFERROR(+D39/C39,0) -> 0.70360436 | H39: =IFERROR(+F39/C39,0) -> 0.89175564
B40: Distribuidores GBA y Costa | C40: =+SCH!$AJ$28 -> 100000 | D40: =+SCH!$AL$28 -> 61960.86 | E40: =+SCH!$AK$28 -> 5482.8 | F40: =+D40+E40 -> 67443.66 | G40: =IFERROR(+D40/C40,0) -> 0.6196086 | H40: =IFERROR(+F40/C40,0) -> 0.6744366
B41: Regionales GBA, Costa y Patagonia | C41: =+SCH!$AJ$30 -> 7000 | D41: =+SCH!$AL$30 -> 1399.08 | E41: =+SCH!$AK$30 -> 1572 | F41: =+D41+E41 -> 2971.08 | G41: =IFERROR(+D41/C41,0) -> 0.19986857 | H41: =IFERROR(+F41/C41,0) -> 0.42444
B42: Gastronomía | C42: =+SCH!$AJ$33 -> 17000 | D42: =+SCH!$AL$33 -> 11235.3 | E42: =+SCH!$AK$33 -> 69.6 | F42: =+D42+E42 -> 11304.9 | G42: =IFERROR(+D42/C42,0) -> 0.6609 | H42: =IFERROR(+F42/C42,0) -> 0.66499412
B43: Mayoristas | C43: =+SCH!$AJ$37 -> 35000 | D43: =+SCH!$AL$37 -> 16530.66 | E43: =+SCH!$AK$37 -> 4500.84 | F43: =+D43+E43 -> 21031.5 | G43: =IFERROR(+D43/C43,0) -> 0.47230457 | H43: =IFERROR(+F43/C43,0) -> 0.6009
B44: Cadenas | C44: =+SCH!$AJ$46 -> 215000 | D44: =+SCH!$AL$46 -> 107112.48 | E44: =+SCH!$AK$46 -> 43578.54 | F44: =+D44+E44 -> 150691.02 | G44: =IFERROR(+D44/C44,0) -> 0.49819758 | H44: =IFERROR(+F44/C44,0) -> 0.70088847
...

Sheet HG
B1: HAMBURGUESAS - ARG | C1: HAMBURGUESAS - ARG
B2: Área | C2: Jefe | D2: Ejecutivo | E2: Julio '23 | F2: Agosto '23 | G2: Septiembre '23 | H2: Octubre '23 | I2: Noviembre '23 | J2: Diciembre '23 | K2: Enero '24 | L2: Febrero '24 | M2: Marzo '24 | N2: Abril '24 | O2: Mayo '24 | P2: Junio '24 | Q2: Julio '24 | R2: Agosto '24 | S2: Septiembre '24 | T2: Octubre '24 | U2: Noviembre '24 | V2: Diciembre '24 | W2: Enero '25 | X2: Febrero '25 | Y2: Marzo '25 | Z2: Abril '25 | AA2: Mayo '25 | AB2: Junio '25 | AC2: Julio '25 | AD2: Agosto '25 | AE2: Septiembre '25 | AF2: Octubre '25 | AG2: Noviembre '25 | AH2: Diciembre '25 | AI2: Enero '26 | AJ2: Meta Febrero '26 | AK2: Pendiente | AL2: Ventas | AM2: Avance Neto | AN2: Total | AO2: Avance Total
B3: Rosario | C3: ADRIAN DALLA VERDE | D3: BESSONE JUAN MANUEL (VENDEDOR) | E3: 0 | F3: 0 | G3: 0 | H3: 0 | I3: 0 | J3: 0 | K3: 0 | L3: 0 | M3: 0 | N3: 0 | O3: 0 | P3: 62.4 | Q3: 0 | R3: 0 | S3: 0 | T3: 0 | U3: 0 | V3: 0 | W3: 0 | X3: 0 | Y3: 0 | Z3: 0 | AA3: 0 | AB3: 0 | AC3: 0 | AD3: 0 | AE3: 0 | AF3: 0 | AG3: 0 | AH3: 0 | AI3: 0 | AJ3: 0 | AK3: 0 | AL3: 0 | AM3: =IFERROR(AL3/AJ3,0) -> 0 | AN3: =+AK3+AL3 -> 0 | AO3: =IFERROR(+AN3/AJ3,0) -> 0
B4: Litoral | C4: ADRIAN DALLA VERDE | D4: FUNES ANDRES | E4: 54023.412 | F4: 66871.644 | G4: 59695.788 | H4: 79388.676 | I4: 69537.408 | J4: 74386.884 | K4: 62382.144 | L4: 56434.536 | M4: 37536.96 | N4: 54851.196 | O4: 50930.7 | P4: 57901.164 | Q4: 71669.292 | R4: 59149.08 | S4: 58956.168 | T4: 68284.14 | U4: 69382.992 | V4: 80921.664 | W4: 75468.288 | X4: 74942.892 | Y4: 76115.784 | Z4: 72344.124 | AA4: 70194.06 | AB4: 67410.288 | AC4: 74097.9 | AD4: 69158.604 | AE4: 65285.208 | AF4: 73477.656 | AG4: 73908.468 | AH4: 83421.936 | AI4: 77918.076 | AJ4: 77000 | AK4: 0 | AL4: 66709.44 | AM4: =IFERROR(AL4/AJ4,0) -> 0.86635636 | AN4: =+AK4+AL4 -> 66709.44 | AO4: =IFERROR(+AN4/AJ4,0) -> 0.86635636
B5: Litoral | C5: ADRIAN DALLA VERDE | D5: SCARAFIA YAMIL HERMES | E5: 32344.32 | F5: 45905.064 | G5: 40231.824 | H5: 40556.064 | I5: 34710.504 | J5: 29321.568 | K5: 47604.648 | L5: 39854.868 | M5: 26329.896 | N5: 18569.988 | O5: 24726.156 | P5: 30948.708 | Q5: 36496.872 | R5: 29871.252 | S5: 30824.316 | T5: 39798.492 | U5: 46100.52 | V5: 53965.716 | W5: 61071.276 | X5: 59800.596 | Y5: 58258.068 | Z5: 43380.048 | AA5: 59276.76 | AB5: 52994.196 | AC5: 55251.492 | AD5: 64275.036 | AE5: 66028.344 | AF5: 33776.82 | AG5: 51577.176 | AH5: 58192.896 | AI5: 77962.236 | AJ5: 61000 | AK5: 0 | AL5: 29542.716 | AM5: =IFERROR(AL5/AJ5,0) -> 0.48430682 | AN5: =+AK5+AL5 -> 29542.716 | AO5: =IFERROR(+AN5/AJ5,0) -> 0.48430682 | AP5: VAZQUEZ ALEJANDRO MARCELO
B6: Litoral | C6: ADRIAN DALLA VERDE | D6: GENTILE NICOLAS | E6: 29828.652 | F6: 40491.732 | G6: 34919.424 | H6: 41725.92 | I6: 41941.032 | J6: 35425.86 | K6: 31188.612 | L6: 31869.78 | M6: 27906.852 | N6: 27344.928 | O6: 27080.496 | P6: 30229.284 | Q6: 26633.868 | R6: 33241.344 | S6: 33425.46 | T6: 35130.036 | U6: 39285.276 | V6: 39051.096 | W6: 42752.328 | X6: 39900.984 | Y6: 41237.484 | Z6: 39916.224 | AA6: 36131.748 | AB6: 28044.42 | AC6: 35835.264 | AD6: 34264.836 | AE6: 25961.244 | AF6: 48764.364 | AG6: 42530.052 | AH6: 51834.756 | AI6: 43700.628 | AJ6: 45000 | AK6: 3154.49 | AL6: 30158.304 | AM6: =IFERROR(AL6/AJ6,0) -> 0.67018453 | AN6: =+AK6+AL6 -> 33312.794 | AO6: =IFERROR(+AN6/AJ6,0) -> 0.74028431
B7: NOA | C7: ADRIAN DALLA VERDE | D7: PAZ CARRANZA EDUARDO | E7: 84565.68 | F7: 85809.468 | G7: 84546.948 | H7: 89775.792 | I7: 83980.176 | J7: 81280.452 | K7: 95285.064 | L7: 84829.8 | M7: 78425.364 | N7: 80592.576 | O7: 93610.908 | P7: 41961.3 | Q7: 45991.224 | R7: 48329.304 | S7: 44047.236 | T7: 61483.74 | U7: 63143.544 | V7: 59391.96 | W7: 40713.852 | X7: 78437.172 | Y7: 45768.648 | Z7: 69783.096 | AA7: 70747.944 | AB7: 60234.168 | AC7: 81973.068 | AD7: 59574.132 | AE7: 77077.2 | AF7: 66892.272 | AG7: 58670.688 | AH7: 67720.752 | AI7: 70521.6 | AJ7: 69000 | AK7: 7721.35 | AL7: 59241.588 | AM7: =IFERROR(AL7/AJ7,0) -> 0.85857374 | AN7: =+AK7+AL7 -> 66962.938 | AO7: =IFERROR(+AN7/AJ7,0) -> 0.97047736
B8: NOA | C8: ADRIAN DALLA VERDE | D8: APUD ALEXANDER DARIO | O8: 0 | P8: 57648.372 | Q8: 68377.488 | R8: 51019.62 | S8: 48673.644 | T8: 81418.644 | U8: 60838.824 | V8: 72671.82 | W8: 66298.452 | X8: 91393.344 | Y8: 80848.032 | Z8: 89346.888 | AA8: 90920.628 | AB8: 96227.016 | AC8: 90119.7 | AD8: 92124.66 | AE8: 87152.064 | AF8: 84984.456 | AG8: 84675.66 | AH8: 89001.192 | AI8: 89098.26 | AJ8: 88000 | AK8: 4929.26 | AL8: 76841.988 | AM8: =IFERROR(AL8/AJ8,0) -> 0.87320441 | AN8: =+AK8+AL8 -> 81771.248 | AO8: =IFERROR(+AN8/AJ8,0) -> 0.92921873
B9: NEA | C9: ADRIAN DALLA VERDE | D9: ROBLEDO JORGE LUIS | E9: 26413.512 | F9: 29079.36 | G9: 21742.356 | H9: 24827.604 | I9: 27509.808 | J9: 29238.024 | K9: 33117.012 | L9: 22371.444 | M9: 20208.504 | N9: 28795.116 | O9: 26166.3 | P9: 28760.724 | Q9: 28327.896 | R9: 31781.244 | S9: 26621.292 | T9: 35469.864 | U9: 33930 | V9: 39924.888 | W9: 38704.848 | X9: 36667.824 | Y9: 43266.924 | Z9: 34425.216 | AA9: 31661.556 | AB9: 35649.876 | AC9: 43037.868 | AD9: 43887.972 | AE9: 39990.636 | AF9: 39370.872 | AG9: 41871.924 | AH9: 45102 | AI9: 46599.696 | AJ9: 45500 | AK9: 148.51 | AL9: 36164.424 | AM9: =IFERROR(AL9/AJ9,0) -> 0.79482251 | AN9: =+AK9+AL9 -> 36312.934 | AO9: =IFERROR(+AN9/AJ9,0) -> 0.79808646
B10: NEA | C10: ADRIAN DALLA VERDE | D10: SANCHEZ JUAN CARLOS | E10: 26059.02 | F10: 24381.924 | G10: 26818.128 | H10: 22993.836 | I10: 29871.864 | J10: 32663.628 | K10: 29563.188 | L10: 22781.472 | M10: 17335.68 | N10: 23189.832 | O10: 23627.052 | P10: 23566.92 | Q10: 25677.432 | R10: 25310.064 | S10: 27807.456 | T10: 27517.164 | U10: 33962.832 | V10: 26590.764 | W10: 33914.1 | X10: 31566.336 | Y10: 38964.432 | Z10: 34453.02 | AA10: 29991.696 | AB10: 33008.928 | AC10: 35097.912 | AD10: 34078.644 | AE10: 34104.876 | AF10: 25508.424 | AG10: 27845.556 | AH10: 25577.508 | AI10: 35409.888 | AJ10: 34500 | AK10: 390.13 | AL10: 22738.704 | AM10: =IFERROR(AL10/AJ10,0) -> 0.65909287 | AN10: =+AK10+AL10 -> 23128.834 | AO10: =IFERROR(+AN10/AJ10,0) -> 0.67040099
B11: Cuyo | C11: MARCELO VEGA | D11: VIVARES ABEL MAURICIO | E11: 19622.88 | F11: 20468.952 | G11: 16898.7 | H11: 19258.044 | I11: 20219.268 | J11: 21562.98 | K11: 19187.988 | L11: 20701.716 | M11: 15292.68 | N11: 13887.264 | O11: 14345.832 | P11: 16029.888 | Q11: 18950.484 | R11: 19757.616 | S11: 21269.124 | T11: 21891.384 | U11: 28209.624 | V11: 28961.772 | W11: 27771.36 | X11: 26485.284 | Y11: 25513.344 | Z11: 27463.428 | AA11: 30246.252 | AB11: 30219.432 | AC11: 31862.856 | AD11: 30680.34 | AE11: 29009.64 | AF11: 33060.444 | AG11: 38319.684 | AH11: 38171.844 | AI11: 35634.672 | AJ11: 32500 | AK11: 2116.97 | AL11: 20664.432 | AM11: =IFERROR(AL11/AJ11,0) -> 0.63582868 | AN11: =+AK11+AL11 -> 22781.402 | AO11: =IFERROR(+AN11/AJ11,0) -> 0.70096622
B12: Cuyo | C12: MARCELO VEGA | D12: ANDINO FACUNDO NICOLAS | E12: 31655.16 | F12: 28563.432 | G12: 28647.3 | H12: 22871.604 | I12: 28876.044 | J12: 31561.824 | K12: 23623.74 | L12: 29498.568 | M12: 22222.416 | N12: 18013.272 | O12: 14102.616 | P12: 16101.36 | Q12: 18314.82 | R12: 16637.076 | S12: 18568.536 | T12: 21631.104 | U12: 19852.164 | V12: 21227.136 | W12: 26773.068 | X12: 28614.516 | Y12: 24336.06 | Z12: 28258.092 | AA12: 28343.616 | AB12: 28488 | AC12: 29349.168 | AD12: 29035.488 | AE12: 28639.92 | AF12: 26564.676 | AG12: 26192.952 | AH12: 30267.78 | AI12: 33070.488 | AJ12: 29500 | AK12: 4283.58 | AL12: 26172.588 | AM12: =IFERROR(AL12/AJ12,0) -> 0.88720637 | AN12: =+AK12+AL12 -> 30456.168 | AO12: =IFERROR(+AN12/AJ12,0) -> 1.0324125
B13: Cordoba | C13: MARCELO VEGA | D13: SCHAIGORODSKY IGNACIO | E13: 6177.084 | F13: 3040.488 | K13: 17424.084 | L13: 15885.348 | M13: 14900.928 | N13: 14429.664 | O13: 17983.836 | P13: 14730.78 | Q13: 18029.124 | R13: 16854.9 | S13: 18539.808 | T13: 21747.336 | U13: 24091.944 | V13: 27284.772 | W13: 38046.756 | X13: 30801.516 | Y13: 23472.504 | Z13: 31131.024 | AA13: 31200.396 | AB13: 27626.364 | AC13: 30766.716 | AD13: 29420.388 | AE13: 27535.224 | AF13: 33759.072 | AG13: 34800.132 | AH13: 37243.212 | AI13: 43001.34 | AJ13: 34000 | AK13: 807.34 | AL13: 28084.548 | AM13: =IFERROR(AL13/AJ13,0) -> 0.82601612 | AN13: =+AK13+AL13 -> 28891.888 | AO13: =IFERROR(+AN13/AJ13,0) -> 0.84976141
B14: Cordoba | C14: MARCELO VEGA | D14: FELLINI FERNANDO JOSE MARIA | E14: 16428.876 | F14: 18913.044 | G14: 18901.08 | H14: 21754.908 | I14: 22757.244 | J14: 21504.456 | K14: 16503.324 | L14: 13441.188 | M14: 7701.3 | N14: 8954.88 | O14: 0 | P14: 0 | Q14: 0 | R14: 0 | S14: 0 | T14: 0 | U14: 0 | V14: 0 | W14: 0 | X14: 0 | Y14: 0 | Z14: 0 | AA14: 0 | AB14: 0 | AC14: 0 | AD14: 0 | AE14: 0 | AF14: 0 | AG14: 0 | AH14: 0 | AI14: 0 | AK14: 0 | AL14: 0 | AM14: =IFERROR(AL14/AJ14,0) -> 0 | AN14: =+AK14+AL14 -> 0 | AO14: =IFERROR(+AN14/AJ14,0) -> 0
B15: Cordoba | C15: MARCELO VEGA | D15: ORGAZ GUSTAVO EMANUEL | E15: 21415.896 | F15: 27814.5 | G15: 21434.532 | H15: 27302.676 | I15: 32519.076 | J15: 19189.296 | K15: 21019.524 | L15: 16016.256 | M15: 17611.44 | N15: 11539.932 | O15: 16663.152 | P15: 21320.616 | Q15: 19834.74 | R15: 19699.404 | S15: 21783.732 | T15: 30427.236 | U15: 25294.788 | V15: 29663.46 | W15: 26398.404 | X15: 30273.396 | Y15: 26406.864 | Z15: 28239.66 | AA15: 30347.712 | AB15: 28031.748 | AC15: 32834.316 | AD15: 28567.704 | AE15: 33573.108 | AF15: 23342.34 | AG15: 27226.008 | AH15: 37710.108 | AI15: 35367.396 | AJ15: 33000 | AK15: 1565.51 | AL15: 20986.008 | AM15: =IFERROR(AL15/AJ15,0) -> 0.63593964 | AN15: =+AK15+AL15 -> 22551.518 | AO15: =IFERROR(+AN15/AJ15,0) -> 0.68337933
B16: Patagonia | C16: MARCELO VEGA | D16: ALONSO GUSTAVO DANIEL | E16: 34303.896 | F16: 36177.564 | G16: 31297.764 | H16: 30369.552 | I16: 27988.356 | J16: 29764.404 | K16: 34140.972 | L16: 30358.956 | M16: 27330.444 | N16: 20178.168 | O16: 23466.42 | P16: 24507.9 | Q16: 27907.524 | R16: 26742.612 | S16: 28593.828 | T16: 31728.768 | U16: 35308.044 | V16: 42318.78 | W16: 42158.94 | X16: 36387.912 | Y16: 48951.276 | Z16: 52579.308 | AA16: 53343.144 | AB16: 43186.668 | AC16: 52897.236 | AD16: 40676.16 | AE16: 44996.64 | AF16: 46959.516 | AG16: 39968.736 | AH16: 64584.72 | AI16: 53037.444 | AJ16: 49500 | AK16: 9266.4 | AL16: 26892.564 | AM16: =IFERROR(AL16/AJ16,0) -> 0.54328412 | AN16: =+AK16+AL16 -> 36158.964 | AO16: =IFERROR(+AN16/AJ16,0) -> 0.73048412
B17: Patagonia | C17: MARCELO VEGA | D17: VILOTTA SEBASTIAN | E17: 53055.828 | F17: 65495.304 | G17: 32182.488 | H17: 57687.744 | I17: 37634.724 | J17: 61934.928 | K17: 51277.968 | L17: 47225.82 | M17: 29263.824 | N17: 41223.3 | O17: 45292.512 | P17: 48059.772 | Q17: 70928.04 | R17: 49189.32 | S17: 58125.912 | T17: 74590.62 | U17: 58504.824 | V17: 53668.896 | W17: 58993.164 | X17: 56183.376 | Y17: 54426.348 | Z17: 67204.608 | AA17: 52915.824 | AB17: 52810.188 | AC17: 67680.384 | AD17: 51392.256 | AE17: 46525.764 | AF17: 56809.272 | AG17: 43432.584 | AH17: 76389.72 | AI17: 67066.836 | AJ17: 56500 | AK17: 2958.99 | AL17: 43158.648 | AM17: =IFERROR(AL17/AJ17,0) -> 0.76386988 | AN17: =+AK17+AL17 -> 46117.638 | AO17: =IFERROR(+AN17/AJ17,0) -> 0.81624138
D18: Subtotal Distribuidores Interior | E18: =+SUM(E3:E17) -> 435894.22 | F18: =+SUM(F3:F17) -> 493012.48 | G18: =+SUM(G3:G17) -> 417316.33 | H18: =+SUM(H3:H17) -> 478512.42 | I18: =+SUM(I3:I17) -> 457545.5 | J18: =+SUM(J3:J17) -> 467834.3 | K18: =+SUM(K3:K17) -> 482318.27 | L18: =+SUM(L3:L17) -> 431269.75 | ... AD18: =+SUM(AD3:AD17) -> 607136.22 | AE18: 605879.87 | AF18: 593270.18 | AG18: 591019.62 | AH18: 705218.42 | AI18: 708388.56 | AJ18: 655000 | AK18: =+SUM(AK3:AK17) -> 37342.53 | AL18: =+SUM(AL3:AL17) -> 487355.95 | AM18: =IFERROR(AL18/AJ18,0) -> 0.74405489 | AN18: =+SUM(AN3:AN17) -> 524698.48 | AO18: =IFERROR(+AN18/AJ18,0) -> 0.80106638
A19: HAMBURGUESAS - ARG | B19: Interior - Cadenas | C19: JUAN BESSONE | D19: CABARDOS CLAUDIO SANTIAGO | E19: 14394.012 | F19: 10808.94 | G19: 16067.856 | H19: 16709.544 | I19: 19013.592 | J19: 12985.236 | K19: 13868.136 | L19: 13402.68 | M19: 15104.364 | N19: 15014.784 | O19: 20522.4 | P19: 23385.564 | Q19: 20128.268 | R19: 19132.964 | S19: 18282.032 | T19: 25154.624 | U19: 20852.144 | V19: 16976.376 | W19: 23453.772 | X19: 19247.788 | Y19: 17819.776 | Z19: 18919.776 | AA19: 19628.492 | AB19: 15610.568 | AC19: 16379.052 | AD19: 11140.164 | AE19: 14836.26 | AF19: 16590.708 | AG19: 15145.452 | AH19: 13916.016 | AI19: 15123.216 | AJ19: 15000 | AK19: 113.52 | AL19: 12078.612 | AM19: =IFERROR(AL19/AJ19,0) -> 0.8052408 | AN19: =+AK19+AL19 -> 12192.132 | AO19: =IFERROR(+AN19/AJ19,0) -> 0.8128088
A20: HAMBURGUESAS - ARG | B20: Interior - Cadenas | C20: JUAN BESSONE | D20: MEINERI JOSE MARIA | E20: 44996.544 | F20: 39480.42 | G20: 45771.648 | H20: 58366.284 | I20: 58128.564 | J20: 43762.344 | K20: 39276.6 | L20: 43583.82 | M20: 26979.492 | N20: 47609.424 | O20: 35252.34 | P20: 41727.096 | Q20: 57838.944 | R20: 41085.576 | S20: 49270.788 | T20: 60134.568 | U20: 51173.652 | V20: 61287.816 | W20: 61017.024 | X20: 59233.128 | Y20: 57233.76 | Z20: 53085.108 | AA20: 41769.864 | AB20: 51292.044 | AC20: 62547.12 | AD20: 43823.484 | AE20: 56094.984 | AF20: 57355.668 | AG20: 54858.672 | AH20: 50298.288 | AI20: 59233.068 | AJ20: 57000 | AK20: 6884.46 | AL20: 41557.632 | AM20: =IFERROR(AL20/AJ20,0) -> 0.72908126 | AN20: =+AK20+AL20 -> 48442.092 | AO20: =IFERROR(+AN20/AJ20,0) -> 0.84986126
A21: HAMBURGUESAS - ARG | B21: Interior - Cadenas | C21: JUAN BESSONE | D21: FERNANDEZ JORGE OSCAR | E21: 32791.68 | F21: 29817.444 | G21: 39361.872 | H21: 39582.804 | I21: 47346.552 | J21: 37615.356 | K21: 30963.372 | L21: 38261.52 | M21: 24286.776 | N21: 29028.852 | O21: 33805.74 | P21: 33580.812 | Q21: 44358.468 | R21: 36327.42 | S21: 32324.28 | T21: 36421.152 | U21: 37393.092 | V21: 46655.688 | W21: 48644.904 | X21: 41729.46 | Y21: 35188.224 | Z21: 42460.344 | AA21: 50863.56 | AB21: 38732.016 | AC21: 41781.948 | AD21: 36555.804 | AE21: 46178.172 | AF21: 38135.628 | AG21: 36461.484 | AH21: 44655.048 | AI21: 38337.684 | AJ21: 43000 | AK21: 10741.32 | AL21: 28427.34 | AM21: =IFERROR(AL21/AJ21,0) -> 0.66110093 | AN21: =+AK21+AL21 -> 39168.66 | AO21: =IFERROR(+AN21/AJ21,0) -> 0.91089907
D22: Subtotal Regionales Interior | E22: =+SUM(E19:E21) -> 92182.236 | F22: =+SUM(F19:F21) -> 80106.804 | G22: =+SUM(G19:G21) -> 101201.38 | H22: =+SUM(H19:H21) -> 114658.63 | I22: =+SUM(I19:I21) -> 124488.71 | J22: =+SUM(J19:J21) -> 94362.936 | K22: =+SUM(K19:K21) -> 84108.108 | L22: =+SUM(L19:L21) -> 95248.02 | ... R22: =+SUM(R19:R21) -> 96545.96 | S22: 99877.1 | T22: =+SUM(T19:T21) -> 121710.34 | U22: =+SUM(U19:U21) -> 109418.89 | V22: =+SUM(V19:V21) -> 124919.88 | W22: 133115.7 | X22: 120210.38 | Y22: 110241.76 | Z22: 114465.23 | AA22: 112261.92 | AB22: 105634.63 | AC22: 120708.12 | AD22: 91519.452 | AE22: 117109.42 | AF22: 112082 | AG22: 106465.61 | AH22: 108869.35 | AI22: 112693.97 | AJ22: 115000 | AK22: =+SUM(AK19:AK21) -> 17739.3 | AL22: =+SUM(AL19:AL21) -> 82063.584 | AM22: =IFERROR(AL22/AJ22,0) -> 0.71359638 | AN22: =+SUM(AN19:AN21) -> 99802.884 | AO22: =IFERROR(+AN22/AJ22,0) -> 0.86785117
B23: Capital | C23: FEDERICO JACUM | D23: VELAZQUEZ JONATAN WALTER | E23: 25444.404 | F23: 22801.692 | G23: 25589.952 | H23: 28938.612 | I23: 28839.648 | J23: 27527.304 | K23: 21137.292 | L23: 20476.908 | M23: 15593.556 | N23: 10615.356 | O23: 29975.004 | P23: 37129.836 | Q23: 36304.716 | R23: 33405.132 | S23: 31198.572 | T23: 34466.736 | U23: 41724.888 | V23: 39542.58 | W23: 40754.136 | X23: 44946.984 | Y23: 39794.58 | Z23: 40955.544 | AA23: 41600.1 | AB23: 34471.74 | AC23: 27943.836 | AD23: 48252.588 | AE23: 35510.556 | AF23: 37762.176 | AG23: 22358.352 | AH23: 41155.452 | AI23: 45954.6 | AJ23: 45000 | AK23: 3810.38 | AL23: 21704.196 | AM23: =IFERROR(AL23/AJ23,0) -> 0.48231547 | AN23: =+AK23+AL23 -> 25514.576 | AO23: =IFERROR(+AN23/AJ23,0) -> 0.56699058
B24: GBA (Oeste) | C24: FEDERICO JACUM | D24: TAPIA NERINA MARIELA | E24: 39896.34 | F24: 36053.724 | G24: 35099.292 | H24: 49687.176 | I24: 49040.736 | J24: 44439.708 | K24: 45320.256 | L24: 50924.964 | M24: 46518.756 | N24: 41593.692 | O24: 30182.76 | P24: 36510.768 | Q24: 29647.908 | R24: 32796.204 | S24: 30827.784 | T24: 38065.608 | U24: 35656.5 | V24: 39149.976 | W24: 42315 | X24: 44714.76 | Y24: 33056.676 | Z24: 44671.62 | AA24: 41430.12 | AB24: 38840.868 | AC24: 43524.132 | AD24: 41315.148 | AE24: 36880.26 | AF24: 35325.804 | AG24: 39117.108 | AH24: 35328.324 | AI24: 43383.672 | AJ24: 46000 | AK24: 4707.94 | AL24: 14661.408 | AM24: =IFERROR(AL24/AJ24,0) -> 0.31872626 | AN24: =+AK24+AL24 -> 19369.348 | AO24: =IFERROR(+AN24/AJ24,0) -> 0.42107278
B25: GBA (Sur) | C25: FEDERICO JACUM | D25: VINCZE CINTIA LORENA | E25: 41631.024 | F25: 42882.192 | G25: 34617.6 | H25: 52666.512 | I25: 45618.528 | J25: 54597.672 | K25: 42382.992 | L25: 43339.296 | M25: 38377.296 | N25: 38980.92 | O25: 41456.928 | P25: 34736.208 | Q25: 38190.288 | R25: 41829.288 | S25: 41083.92 | T25: 50763.156 | U25: 47362.86 | V25: 55751.208 | W25: 63285.888 | X25: 60964.584 | Y25: 57355.2 | Z25: 50909.136 | AA25: 50087.016 | AB25: 49992.732 | AC25: 39418.152 | AD25: 47060.532 | AE25: 33056.952 | AF25: 46363.416 | AG25: 42912.828 | AH25: 48746.736 | AI25: 52292.94 | AJ25: 57000 | AK25: 5144.86 | AL25: 31536.24 | AM25: =IFERROR(AL25/AJ25,0) -> 0.55326737 | AN25: =+AK25+AL25 -> 36681.1 | AO25: =IFERROR(+AN25/AJ25,0) -> 0.64352807
B26: GBA (Sur) | C26: FEDERICO JACUM | D26: GOMEZ OURAL ALBERTO | E26: 42608.736 | F26: 40658.04 | G26: 40753.2 | H26: 54164.016 | I26: 60652.56 | J26: 53156.04 | K26: 53504.64 | L26: 58702.488 | M26: 53663.748 | N26: 50250.444 | O26: 26226.432 | P26: 43098.036 | Q26: 38138.568 | R26: 35085.192 | S26: 36889.032 | T26: 53046.348 | U26: 57091.584 | V26: 70822.116 | W26: 65671.764 | X26: 67939.176 | Y26: 62495.724 | Z26: 68273.484 | AA26: 65681.544 | AB26: 56992.44 | AC26: 57195.312 | AD26: 56317.86 | AE26: 53216.94 | AF26: 54902.136 | AG26: 57551.616 | AH26: 53437.824 | AI26: 67969.896 | AJ26: 67000 | AK26: 2202.33 | AL26: 22784.904 | AM26: =IFERROR(AL26/AJ26,0) -> 0.34007319 | AN26: =+AK26+AL26 -> 24987.234 | AO26: =IFERROR(+AN26/AJ26,0) -> 0.37294379
B27: Costa | C27: FEDERICO JACUM | D27: MARTINO FLAVIO | E27: 27321.072 | F27: 46597.032 | G27: 40010.424 | H27: 55177.752 | I27: 54211.104 | J27: 53525.364 | K27: 80668.056 | L27: 27143.448 | M27: 34352.448 | N27: 33644.616 | O27: 38508.96 | P27: 27273.216 | Q27: 34627.32 | R27: 25722.216 | S27: 35620.296 | T27: 41686.404 | U27: 48110.808 | V27: 66748.128 | W27: 83628.06 | X27: 56188.92 | Y27: 42981.168 | Z27: 47867.52 | AA27: 45860.256 | AB27: 39179.328 | AC27: 44726.832 | AD27: 41509.692 | AE27: 40148.388 | AF27: 40901.748 | AG27: 61599.564 | AH27: 74525.136 | AI27: 80400.576 | AJ27: 60000 | AK27: 3486.89 | AL27: 26680.248 | AM27: =IFERROR(AL27/AJ27,0) -> 0.4446708 | AN27: =+AK27+AL27 -> 30167.138 | AO27: =IFERROR(+AN27/AJ27,0) -> 0.50278563
D28: Subtotal Distribuidores GBA y Costa | E28: =+SUM(E23:E27) -> 176901.58 | F28: =+SUM(F23:F27) -> 188992.68 | G28: =+SUM(G23:G27) -> 176070.47 | H28: =+SUM(H23:H27) -> 240634.07 | I28: =+SUM(I23:I27) -> 238362.58 | J28: =+SUM(J23:J27) -> 233246.09 | K28: =+SUM(K23:K27) -> 243013.24 | L28: =+SUM(L23:L27) -> 200587.1 | ... AD28: =+SUM(AD23:AD27) -> 234455.82 | AE28: 198813.1 | AF28: 215255.28 | AG28: 223539.47 | AH28: 253193.47 | AI28: 290001.68 | AJ28: 275000 | AK28: =+SUM(AK23:AK27) -> 19352.4 | AL28: =+SUM(AL23:AL27) -> 117367 | AM28: =IFERROR(AL28/AJ28,0) -> 0.42678908 | AN28: =+SUM(AN23:AN27) -> 136719.4 | AO28: =IFERROR(+AN28/AJ28,0) -> 0.49716144
A29: HAMBURGUESAS - ARG | B29: Patagonia / Costa - Cadenas | C29: FEDERICO JACUM | D29: VAL JULIAN | E29: 32901.732 | F29: 31274.616 | G29: 45687.096 | H29: 37409.628 | I29: 41505.384 | J29: 37217.232 | K29: 61799.88 | L29: 32925.228 | M29: 26580.6 | N29: 25086.024 | O29: 36801.96 | P29: 37285.98 | Q29: 38010.948 | R29: 42650.268 | S29: 40100.124 | T29: 55673.952 | U29: 40574.004 | V29: 33235.284 | W29: 64816.68 | X29: 38451.984 | Y29: 15047.4 | Z29: 23269.116 | AA29: 8000.964 | AB29: 4828.428 | AC29: 20786.784 | AD29: 11660.94 | AE29: 6270.228 | AF29: 7725.456 | AG29: 6161.856 | AH29: 13906.152 | AI29: 14033.424 | AJ29: 15000 | AK29: 2364.49 | AL29: 1979.76 | AM29: =IFERROR(AL29/AJ29,0) -> 0.131984 | AN29: =+AK29+AL29 -> 4344.25 | AO29: =IFERROR(+AN29/AJ29,0) -> 0.28961667 | AP29: 100088964 | AQ29: RAMOS LUCIANO ALEJANDRO
D30: Subtotal Regionales GBA, Costa y Patagonia | E30: =+SUM(E29) -> 32901.732 | F30: =+SUM(F29) -> 31274.616 | G30: =+SUM(G29) -> 45687.096 | H30: =+SUM(H29) -> 37409.628 | I30: =+SUM(I29) -> 41505.384 | J30: =+SUM(J29) -> 37217.232 | K30: =+SUM(K29) -> 61799.88 | L30: =+SUM(L29) -> 32925.228 | ... R30: =+SUM(R29) -> 42650.268 | S30: 40100.124 | T30: =+SUM(T29) -> 55673.952 | U30: =+SUM(U29) -> 40574.004 | V30: =+SUM(V29) -> 33235.284 | W30: 64816.68 | X30: 38451.984 | Y30: 15047.4 | Z30: 23269.116 | AA30: 8000.964 | AB30: 4828.428 | AC30: 20786.784 | AD30: 11660.94 | AE30: 6270.228 | AF30: 7725.456 | AG30: 6161.856 | AH30: 13906.152 | AI30: 14033.424 | AJ30: 15000 | AK30: =+SUM(AK29) -> 2364.49 | AL30: =+SUM(AL29) -> 1979.76 | AM30: =IFERROR(AL30/AJ30,0) -> 0.131984 | AN30: =+SUM(AN29) -> 4344.25 | AO30: =IFERROR(+AN30/AJ30,0) -> 0.28961667
B31: Gastronomia | C31: HERNAN DUARTE | D31: RAMIREZ ARIEL SEBASTIAN | E31: 127614.05 | F31: 141972.12 | G31: 90537.252 | H31: 114916.44 | I31: 127815.16 | J31: 152858.76 | K31: 132010.2 | L31: 103073.36 | M31: 111614.44 | N31: 62509.584 | O31: 87337.788 | P31: 109997.7 | Q31: 144201.3 | R31: 117628.58 | S31: 158566.85 | T31: 189733.34 | U31: 180948.79 | V31: 182759.88 | W31: 190891 | X31: 151933.04 | Y31: 106500.06 | Z31: 161914.12 | AA31: 179834.86 | AB31: 196855.32 | AC31: 232244.32 | AD31: 249978.53 | AE31: 256968.92 | AF31: 150988.07 | AG31: 193590.19 | AH31: 198439.67 | AI31: 321295.19 | AJ31: 266300 | AK31: 21931.61 | AL31: 216448.2 | AM31: =IFERROR(AL31/AJ31,0) -> 0.81279835 | AN31: =+AK31+AL31 -> 238379.81 | AO31: =IFERROR(+AN31/AJ31,0) -> 0.89515513
B32: Gastronomia | C32: HERNAN DUARTE | D32: DUARTE HERNAN | E32: 15563.688 | F32: 6529.68 | G32: 13596.12 | H32: 14678.46 | I32: 9463.56 | J32: 14593.56 | K32: 9291.42 | L32: 16646.448 | M32: 9742.44 | N32: 10288.692 | O32: 12602.868 | P32: 7746.18 | Q32: 8890.296 | R32: 11056.5 | S32: 10023.036 | T32: 8287.14 | U32: 7792.272 | V32: 5665.236 | W32: 9906.888 | X32: 8386.164 | Y32: 6911.304 | Z32: 8870.28 | AA32: 4398.06 | AB32: 0 | AC32: 0 | AD32: 0 | AE32: 9707.508 | AF32: 3791.94 | AG32: 5824.092 | AH32: 8138.748 | AI32: 4231.74 | AJ32: 8700 | AK32: 0 | AL32: 4427.1 | AM32: =IFERROR(AL32/AJ32,0) -> 0.50886207 | AN32: =+AK32+AL32 -> 4427.1 | AO32: =IFERROR(+AN32/AJ32,0) -> 0.50886207 | AP32: VACANTE DIRECTO FOOD SERVICE IND
D33: Subtotal Gastronomía | E33: 143177.74 | F33: 148501.8 | G33: 104133.37 | H33: 129594.9 | I33: 137278.72 | J33: 167452.32 | K33: 141301.62 | L33: 119719.81 | M33: 121356.88 | N33: 72798.276 | O33: 99940.656 | P33: 117743.88 | Q33: 153091.6 | R33: 128685.08 | S33: 168589.88 | T33: 198020.48 | U33: 188741.06 | V33: 188425.12 | W33: 200797.88 | X33: 160319.21 | Y33: 113411.36 | Z33: 170784.4 | AA33: 184232.92 | AB33: 196855.32 | AC33: 232244.32 | AD33: 249978.53 | AE33: 266676.43 | AF33: 154780.01 | AG33: 199414.28 | AH33: 206578.42 | AI33: 325526.93 | AJ33: 275000 | AK33: =+AK31+AK32 -> 21931.61 | AL33: =+AL31+AL32 -> 220875.3 | AM33: =IFERROR(AL33/AJ33,0) -> 0.80318291 | AN33: =+AN31+AN32 -> 242806.91 | AO33: =IFERROR(+AN33/AJ33,0) -> 0.88293422
B34: Mayoristas | C34: PABLO ANDREACCHIO | D34: ARUANNO PARODI MARIA NOEL | W34: 0 | X34: 0 | AC34: 0 | AJ34: 0 | AN34: =+AK34+AL34 -> 0
B35: Mayoristas | C35: ARUANNO PARODI MARIA NOEL | D35: MENDEZ NAVARRO MARIA ALEJANDRA | E35: 58746.468 | F35: 57023.544 | G35: 90976.272 | H35: 111856.44 | I35: 92409.444 | J35: 88479.456 | K35: 75440.028 | L35: 63665.844 | M35: 74915.724 | N35: 24370.128 | O35: 46470.276 | P35: 34516.812 | Q35: 54635.124 | R35: 53945.244 | S35: 38589.324 | T35: 58083.768 | U35: 20922.936 | V35: 102486.77 | W35: 105518.29 | X35: 39292.332 | Y35: 93564.78 | Z35: 81737.052 | AA35: 78446.436 | AB35: 67737.504 | AC35: 71218.968 | AD35: 60476.652 | AE35: 78366.96 | AF35: 66031.98 | AG35: 82937.508 | AH35: 69418.296 | AI35: 108291.25 | AJ35: 91100 | AK35: 12875.67 | AL35: 40627.032 | AM35: =IFERROR(AL35/AJ35,0) -> 0.44596083 | AN35: =+AK35+AL35 -> 53502.702 | AO35: =IFERROR(+AN35/AJ35,0) -> 0.5872964
B36: Mayoristas | C36: ARUANNO PARODI MARIA NOEL | D36: RAMONDINO LEONARDO ERNESTO | T36: 5404.2 | U36: 6574.308 | V36: 2935.08 | W36: 7699.452 | X36: 8911.044 | Y36: 3157.008 | Z36: 5592.72 | AA36: 1784.1 | AB36: 6885.948 | AC36: 2200.632 | AD36: 4866.66 | AE36: -66.24 | AF36: 7975.74 | AG36: 5524.92 | AH36: 7387.2 | AI36: 3492.66 | AJ36: 8900 | AK36: 2142.61 | AL36: 1147.2 | AM36: =IFERROR(AL36/AJ36,0) -> 0.12889888 | AN36: =+AK36+AL36 -> 3289.81 | AO36: =IFERROR(+AN36/AJ36,0) -> 0.36964157 | AP36: 100002258
D37: Subtotal Mayoristas | E37: 58746.468 | F37: 57023.544 | G37: 90976.272 | H37: 111856.44 | I37: 92409.444 | J37: 88479.456 | K37: 75440.028 | L37: 63665.844 | M37: 74915.724 | N37: 24370.128 | O37: 46470.276 | P37: 34516.812 | Q37: 54635.124 | R37: 53945.244 | S37: 38589.324 | T37: 63487.968 | U37: 27497.244 | V37: 105421.85 | W37: 113217.74 | X37: 48203.376 | Y37: 96721.788 | Z37: 87329.772 | AA37: 80230.536 | AB37: 74623.452 | AC37: 73419.6 | AD37: 65343.312 | AE37: 78300.72 | AF37: 74007.72 | AG37: 88462.428 | AH37: 76805.496 | AI37: 111783.91 | AJ37: 100000 | AK37: =+SUM(AK34:AK36) -> 15018.28 | AL37: =+SUM(AL34:AL36) -> 41774.232 | AM37: =IFERROR(AL37/AJ37,0) -> 0.41774232 | AN37: =+SUM(AN34:AN36) -> 56792.512 | AO37: =IFERROR(+AN37/AJ37,0) -> 0.56792512
A38: HAMBURGUESAS - ARG | B38: GBA - Cadenas | C38: ARUANNO PARODI MARIA NOEL | D38: BRION SEBASTIAN | E38: 6828.816 | F38: 11209.152 | G38: 4714.884 | H38: 3087.372 | I38: 1034.16 | J38: 2732.964 | K38: 1778.916 | L38: 1883.76 | M38: 1166.592 | N38: 1410.648 | O38: 1180.872 | P38: 1241.472 | Q38: 2444.724 | R38: 719.664 | S38: 907.86 | T38: 1968.36 | U38: 1924.032 | V38: 2972.52 | W38: 244.932 | X38: 2170.008 | Y38: 1813.488 | Z38: 1982.28 | AA38: 1381.644 | AB38: 1540.308 | AC38: 2274.468 | AD38: 1670.748 | AE38: 1081.332 | AF38: 1842 | AG38: 1591.284 | AH38: 2789.628 | AI38: 1020.036 | AJ38: 2300 | AK38: 595.55 | AL38: 1024.776 | AM38: =IFERROR(AL38/AJ38,0) -> 0.44555478 | AN38: =+AK38+AL38 -> 1620.326 | AO38: =IFERROR(+AN38/AJ38,0) -> 0.70448957 | AP38: 100001914 | AQ38: 100001979 | AR38: 100086833
B39: DBU - BAS | C39: RAMONDINO LEONARDO ERNESTO | D39: DELIVERY HERO E-COMMERCE S. A. | O39: 4400.64 | P39: 2039.04 | Q39: 3346.56 | R39: 7438.08 | S39: 1396.8 | T39: 1933.44 | AD39: 1401.6 | AE39: 3310.08 | AF39: 253.44 | AG39: 1228.8 | AH39: 0 | AI39: 3640.32 | AJ39: 1500 | AK39: 0 | AL39: 0 | AM39: =IFERROR(AL39/AJ39,0) -> 0 | AN39: =+AK39+AL39 -> 0 | AO39: =IFERROR(+AN39/AJ39,0) -> 0
A40: HAMBURGUESAS - ARG | B40: DBU - BAS | C40: RAMONDINO LEONARDO ERNESTO | D40: COTO CENTRO INTEGRAL DE COMERCIALIZACON S A | E40: 42352.368 | F40: 22323.888 | G40: 79115.256 | H40: 69215.472 | I40: 69992.7 | J40: 91216.116 | K40: 29227.368 | L40: 54321.852 | M40: 43936.56 | N40: 50221.212 | O40: 38284.284 | P40: 67121.364 | Q40: 45965.664 | R40: 42092.676 | S40: 46653.384 | T40: 58176.084 | U40: 54262.32 | V40: 53165.928 | W40: 67400.976 | X40: 57838.188 | Y40: 54039.408 | Z40: 55744.188 | AA40: 69680.58 | AB40: 48901.968 | AC40: 52931.508 | AD40: 39339.972 | AE40: 45105.888 | AF40: 57024.84 | AG40: 37582.212 | AH40: 77756.736 | AI40: 62541.6 | AJ40: 68000 | AK40: 17559.83 | AL40: 16527.144 | AM40: =IFERROR(AL40/AJ40,0) -> 0.24304624 | AN40: =+AK40+AL40 -> 34086.974 | AO40: =IFERROR(+AN40/AJ40,0) -> 0.50127903
...

Sheet SCH
B1: SALCHICHAS - ARG | C1: SALCHICHAS - ARG
B2: Área | C2: Jefe | D2: Ejecutivo | E2: Julio '23 | F2: Agosto '23 | G2: Septiembre '23 | H2: Octubre '23 | I2: Noviembre '23 | J2: Diciembre '23 | K2: Enero '24 | L2: Febrero '24 | M2: Marzo '24 | N2: Abril '24 | O2: Mayo '24 | P2: Junio '24 | Q2: Julio '24 | R2: Agosto '24 | S2: Septiembre '24 | T2: Octubre '24 | U2: Noviembre '24 | V2: Diciembre '24 | W2: Enero '25 | X2: Febrero '25 | Y2: Marzo '25 | Z2: Abril '25 | AA2: Mayo '25 | AB2: Junio '25 | AC2: Julio '25 | AD2: Agosto '25 | AE2: Septiembre '25 | AF2: Octubre '25 | AG2: Noviembre '25 | AH2: Diciembre '25 | AI2: Enero '26 | AJ2: Meta Febrero '26 | AK2: Pendiente | AL2: Ventas | AM2: Avance Neto | AN2: Total | AO2: Avance Total
A3: SALCHICHAS - ARG | B3: Rosario | C3: ADRIAN DALLA VERDE | D3: BESSONE JUAN MANUEL (VENDEDOR) | E3: 0 | F3: 75.6 | G3: 0 | H3: 0 | I3: 0 | J3: 0 | K3: 0 | L3: 0 | M3: 0 | N3: 0 | O3: 0 | P3: 0 | Q3: 0 | R3: 0 | S3: 0 | T3: 0 | U3: 0 | V3: 0 | W3: 0 | X3: 0 | Y3: 0 | Z3: 0 | AA3: 0 | AB3: 0 | AC3: 0 | AD3: 0 | AE3: 0 | AF3: 0 | AG3: 0 | AH3: 0 | AI3: 0 | AJ3: 0 | AK3: 0 | AL3: 0 | AM3: =IFERROR(AL3/AJ3,0) -> 0 | AN3: =+AK3+AL3 -> 0 | AO3: =IFERROR(+AN3/AJ3,0) -> 0
A4: SALCHICHAS - ARG | B4: Litoral | C4: ADRIAN DALLA VERDE | D4: FUNES ANDRES | E4: 24108.66 | F4: 22633.74 | G4: 24910.02 | H4: 30240.06 | I4: 31872.96 | J4: 28224.3 | K4: 20769.78 | L4: 19455.3 | M4: 12584.28 | N4: 20253.9 | O4: 20549.64 | P4: 17699.88 | Q4: 15123.48 | R4: 18707.58 | S4: 16854.06 | T4: 16622.58 | U4: 14593.92 | V4: 15767.82 | W4: 12558.3 | X4: 11684.58 | Y4: 10805.28 | Z4: 13638.48 | AA4: 16983.9 | AB4: 18412.8 | AC4: 17069.58 | AD4: 18114.12 | AE4: 15295.92 | AF4: 18650.82 | AG4: 18279 | AH4: 16471.74 | AI4: 16948.68 | AJ4: 17000 | AK4: 0 | AL4: 14891.28 | AM4: =IFERROR(AL4/AJ4,0) -> 0.87595765 | AN4: =+AK4+AL4 -> 14891.28 | AO4: =IFERROR(+AN4/AJ4,0) -> 0.87595765
A5: SALCHICHAS - ARG | B5: Litoral | C5: ADRIAN DALLA VERDE | D5: SCARAFIA YAMIL HERMES | E5: 15103.38 | F5: 20743.14 | G5: 19718.82 | H5: 23346.3 | I5: 25255.32 | J5: 15919.5 | K5: 23695.86 | L5: 17165.34 | M5: 15483.24 | N5: 11336.16 | O5: 14091 | P5: 13200.66 | Q5: 14660.7 | R5: 18184.5 | S5: 16954.38 | T5: 20997.78 | U5: 21534.84 | V5: 27432 | W5: 22627.32 | X5: 16615.14 | Y5: 20764.08 | Z5: 20138.58 | AA5: 24981.06 | AB5: 20143.62 | AC5: 25873.2 | AD5: 26592.3 | AE5: 27670.8 | AF5: 16728.36 | AG5: 28760.1 | AH5: 14224.74 | AI5: 30829.02 | AJ5: 25000 | AK5: 0 | AL5: 12424.8 | AM5: =IFERROR(AL5/AJ5,0) -> 0.496992 | AN5: =+AK5+AL5 -> 12424.8 | AO5: =IFERROR(+AN5/AJ5,0) -> 0.496992 | AP5: VAZQUEZ ALEJANDRO MARCELO
A6: SALCHICHAS - ARG | B6: Litoral | C6: ADRIAN DALLA VERDE | D6: GENTILE NICOLAS | E6: 8658.42 | F6: 10024.02 | G6: 10887.24 | H6: 12059.58 | I6: 13487.46 | J6: 13616.76 | K6: 10472.22 | L6: 10333.14 | M6: 11575.8 | N6: 8632.08 | O6: 9925.62 | P6: 9022.44 | Q6: 6756.96 | R6: 9143.22 | S6: 7995.78 | T6: 8715.3 | U6: 9550.08 | V6: 9668.58 | W6: 7714.08 | X6: 6403.62 | Y6: 8012.76 | Z6: 7659.66 | AA6: 5113.74 | AB6: 3773.28 | AC6: 4565.88 | AD6: 5133.18 | AE6: 3270.72 | AF6: 9102.96 | AG6: 8057.1 | AH6: 7046.52 | AI6: 5381.28 | AJ6: 7000 | AK6: 689.94 | AL6: 2995.86 | AM6: =IFERROR(AL6/AJ6,0) -> 0.42798 | AN6: =+AK6+AL6 -> 3685.8 | AO6: =IFERROR(+AN6/AJ6,0) -> 0.52654286
A7: SALCHICHAS - ARG | B7: NOA | C7: ADRIAN DALLA VERDE | D7: PAZ CARRANZA EDUARDO | E7: 121781.7 | F7: 93161.46 | G7: 134368.86 | H7: 118969.98 | I7: 136866 | J7: 141951.42 | K7: 143845.68 | L7: 115080.36 | M7: 118642.38 | N7: 134159.94 | O7: 105465.96 | P7: 91560.12 | Q7: 75716.82 | R7: 93010.8 | S7: 85629.6 | T7: 94794.12 | U7: 81800.64 | V7: 61785.72 | W7: 66731.34 | X7: 35859.3 | Y7: 48290.1 | Z7: 84400.5 | AA7: 80711.4 | AB7: 43374.36 | AC7: 36401.82 | AD7: 104235 | AE7: 40066.38 | AF7: 55931.52 | AG7: 30480.78 | AH7: 74215.38 | AI7: 53428.5 | AJ7: 51000 | AK7: 3197.4 | AL7: 14461.32 | AM7: =IFERROR(AL7/AJ7,0) -> 0.28355529 | AN7: =+AK7+AL7 -> 17658.72 | AO7: =IFERROR(+AN7/AJ7,0) -> 0.34624941
A8: SALCHICHAS - ARG | B8: NOA | C8: ADRIAN DALLA VERDE | D8: APUD ALEXANDER DARIO | O8: 0 | P8: 94679.94 | Q8: 70382.34 | R8: 92919.3 | S8: 93069 | T8: 81088.26 | U8: 88628.46 | V8: 67316.16 | W8: 63020.7 | X8: 63951.72 | Y8: 64174.98 | Z8: 82422.96 | AA8: 90669.84 | AB8: 95089.92 | AC8: 102778.56 | AD8: 107429.04 | AE8: 99682.86 | AF8: 92547.96 | AG8: 111474 | AH8: 95802.78 | AI8: 72352.68 | AJ8: 88000 | AK8: 22544.64 | AL8: 51848.46 | AM8: =IFERROR(AL8/AJ8,0) -> 0.58918705 | AN8: =+AK8+AL8 -> 74393.1 | AO8: =IFERROR(+AN8/AJ8,0) -> 0.84537614
A9: SALCHICHAS - ARG | B9: NEA | C9: ADRIAN DALLA VERDE | D9: ROBLEDO JORGE LUIS | E9: 15329.52 | F9: 16691.76 | G9: 15189.36 | H9: 14861.16 | I9: 21444.24 | J9: 20481.6 | K9: 22579.32 | L9: 22794.18 | M9: 17228.52 | N9: 16800.06 | O9: 12590.52 | P9: 14342.04 | Q9: 20449.92 | R9: 17418.96 | S9: 24911.34 | T9: 19725.06 | U9: 23083.26 | V9: 22660.14 | W9: 17932.02 | X9: 6482.1 | Y9: 11489.46 | Z9: 10743.84 | AA9: 14865.06 | AB9: 14688.36 | AC9: 14591.7 | AD9: 17657.76 | AE9: 15536.58 | AF9: 14564.88 | AG9: 12946.38 | AH9: 11291.16 | AI9: 10190.64 | AJ9: 11000 | AK9: 122.4 | AL9: 3997.8 | AM9: =IFERROR(AL9/AJ9,0) -> 0.36343636 | AN9: =+AK9+AL9 -> 4120.2 | AO9: =IFERROR(+AN9/AJ9,0) -> 0.37456364
A10: SALCHICHAS - ARG | B10: NEA | C10: ADRIAN DALLA VERDE | D10: SANCHEZ JUAN CARLOS | E10: 14713.98 | F10: 23047.38 | G10: 13735.38 | H10: 17490.66 | I10: 19685.94 | J10: 22175.46 | K10: 16218.42 | L10: 13295.64 | M10: 19132.2 | N10: 15445.26 | O10: 9205.08 | P10: 13179.9 | Q10: 9309.48 | R10: 14797.38 | S10: 15426.84 | T10: 13053.24 | U10: 13530.84 | V10: 15404.22 | W10: 9252.18 | X10: 3912.36 | Y10: 12997.56 | Z10: 8162.22 | AA10: 8972.34 | AB10: 9909.12 | AC10: 11996.34 | AD10: 12193.26 | AE10: 10635.42 | AF10: 9952.38 | AG10: 9442.98 | AH10: 8078.94 | AI10: 8094.06 | AJ10: 8000 | AK10: 68.88 | AL10: 4928.4 | AM10: =IFERROR(AL10/AJ10,0) -> 0.61605 | AN10: =+AK10+AL10 -> 4997.28 | AO10: =IFERROR(+AN10/AJ10,0) -> 0.62466
A11: SALCHICHAS - ARG | B11: Cuyo | C11: MARCELO VEGA | D11: VIVARES ABEL MAURICIO | E11: 27637.14 | F11: 29325.48 | G11: 30682.86 | H11: 31534.02 | I11: 35376.42 | J11: 35028.78 | K11: 31582.08 | L11: 36465.72 | M11: 31919.34 | N11: 29048.76 | O11: 26449.44 | P11: 34260.18 | Q11: 34501.44 | R11: 34702.86 | S11: 35525.22 | T11: 40237.86 | U11: 47833.56 | V11: 41671.92 | W11: 33442.68 | X11: 33961.5 | Y11: 30053.1 | Z11: 33944.82 | AA11: 28700.04 | AB11: 35888.64 | AC11: 39205.8 | AD11: 43779.3 | AE11: 43991.88 | AF11: 46566.54 | AG11: 44158.56 | AH11: 48110.64 | AI11: 46149.6 | AJ11: 40000 | AK11: 3891.9 | AL11: 32438.1 | AM11: =IFERROR(AL11/AJ11,0) -> 0.8109525 | AN11: =+AK11+AL11 -> 36330 | AO11: =IFERROR(+AN11/AJ11,0) -> 0.90825
A12: SALCHICHAS - ARG | B12: Cuyo | C12: MARCELO VEGA | D12: ANDINO FACUNDO NICOLAS | E12: 46322.52 | F12: 65058.72 | G12: 61570.44 | H12: 86626.26 | I12: 98400.78 | J12: 84139.32 | K12: 85330.32 | L12: 82663.32 | M12: 49031.04 | N12: 47202.18 | O12: 38210.28 | P12: 33873.3 | Q12: 35561.82 | R12: 45199.2 | S12: 44487.06 | T12: 46150.8 | U12: 48358.98 | V12: 49637.88 | W12: 31524.96 | X12: 46328.04 | Y12: 35789.88 | Z12: 41146.56 | AA12: 39683.7 | AB12: 33630.48 | AC12: 46105.56 | AD12: 54321.66 | AE12: 46139.88 | AF12: 40783.62 | AG12: 36939.6 | AH12: 43611.18 | AI12: 41325.54 | AJ12: 36000 | AK12: 8494.8 | AL12: 29040.42 | AM12: =IFERROR(AL12/AJ12,0) -> 0.80667833 | AN12: =+AK12+AL12 -> 37535.22 | AO12: =IFERROR(+AN12/AJ12,0) -> 1.042645
A13: SALCHICHAS - ARG | B13: Cordoba | C13: MARCELO VEGA | D13: SCHAIGORODSKY IGNACIO | E13: 5892.3 | F13: 5781.6 | K13: 26452.2 | L13: 26087.04 | M13: 18984.9 | N13: 16883.46 | O13: 14484.72 | P13: 13258.86 | Q13: 17522.88 | R13: 15472.68 | S13: 19191.48 | T13: 19549.98 | U13: 17115.66 | V13: 17339.46 | W13: 17663.04 | X13: 14652.84 | Y13: 11751.3 | Z13: 13281.3 | AA13: 13125.96 | AB13: 14229.3 | AC13: 15896.34 | AD13: 15235.38 | AE13: 17443.74 | AF13: 14765.04 | AG13: 19492.98 | AH13: 18415.2 | AI13: 20278.8 | AJ13: 18500 | AK13: 658.2 | AL13: 10618.26 | AM13: =IFERROR(AL13/AJ13,0) -> 0.57396 | AN13: =+AK13+AL13 -> 11276.46 | AO13: =IFERROR(+AN13/AJ13,0) -> 0.60953838
A14: SALCHICHAS - ARG | B14: Cordoba | C14: MARCELO VEGA | D14: FELLINI FERNANDO JOSE MARIA | E14: 18197.28 | F14: 22976.76 | G14: 24127.68 | H14: 28387.92 | I14: 28483.68 | J14: 28884.24 | K14: 8377.86 | L14: 7841.16 | M14: 4745.58 | N14: 4101.6 | O14: 0 | P14: 0 | Q14: 0 | R14: 0 | S14: 0 | T14: 0 | U14: 0 | V14: 0 | W14: 0 | X14: 0 | Y14: 0 | Z14: 0 | AA14: 0 | AB14: 0 | AC14: 0 | AD14: 0 | AE14: 0 | AF14: 0 | AG14: 0 | AH14: 0 | AI14: 0 | AK14: 0 | AL14: 0 | AM14: =IFERROR(AL14/AJ14,0) -> 0 | AN14: =+AK14+AL14 -> 0 | AO14: =IFERROR(+AN14/AJ14,0) -> 0
A15: SALCHICHAS - ARG | B15: Cordoba | C15: MARCELO VEGA | D15: ORGAZ GUSTAVO EMANUEL | E15: 16125.78 | F15: 18862.5 | G15: 23089.5 | H15: 22665.9 | I15: 24702.96 | J15: 23433 | K15: 19851.24 | L15: 23094.06 | M15: 21710.4 | N15: 14686.68 | O15: 11909.94 | P15: 13068 | Q15: 11361.54 | R15: 12243.6 | S15: 12833.1 | T15: 11784.3 | U15: 10847.04 | V15: 10782.9 | W15: 9351.9 | X15: 8717.4 | Y15: 7497.72 | Z15: 9632.7 | AA15: 10764.66 | AB15: 9675.6 | AC15: 13000.74 | AD15: 13274.34 | AE15: 12940.44 | AF15: 10750.32 | AG15: 10434 | AH15: 14943.24 | AI15: 11704.2 | AJ15: 12000 | AK15: 1206.6 | AL15: 6744.96 | AM15: =IFERROR(AL15/AJ15,0) -> 0.56208 | AN15: =+AK15+AL15 -> 7951.56 | AO15: =IFERROR(+AN15/AJ15,0) -> 0.66263
A16: SALCHICHAS - ARG | B16: Patagonia | C16: MARCELO VEGA | D16: ALONSO GUSTAVO DANIEL | E16: 14359.32 | F16: 12635.94 | G16: 13629.54 | H16: 13588.26 | I16: 13229.4 | J16: 9262.68 | K16: 17165.82 | L16: 11389.14 | M16: 10668.78 | N16: 7878.54 | O16: 11688 | P16: 10839.6 | Q16: 10080.72 | R16: 9074.52 | S16: 13909.8 | T16: 8820.24 | U16: 12358.02 | V16: 12453.54 | W16: 9154.02 | X16: 9284.28 | Y16: 11646.24 | Z16: 22392.6 | AA16: 16379.82 | AB16: 29137.02 | AC16: 22409.88 | AD16: 20832.48 | AE16: 19343.88 | AF16: 12864.84 | AG16: 15241.68 | AH16: 20159.46 | AI16: 24903.54 | AJ16: 18200 | AK16: 12442.8 | AL16: 4616.34 | AM16: =IFERROR(AL16/AJ16,0) -> 0.25364505 | AN16: =+AK16+AL16 -> 17059.14 | AO16: =IFERROR(+AN16/AJ16,0) -> 0.93731538
A17: SALCHICHAS - ARG | B17: Patagonia | C17: MARCELO VEGA | D17: VILOTTA SEBASTIAN | E17: 19920.24 | F17: 16483.98 | G17: 10390.2 | H17: 15990.6 | I17: 14114.82 | J17: 14092.8 | K17: 15500.94 | L17: 14364.3 | M17: 9168 | N17: 12051.42 | O17: 17702.58 | P17: 16041.12 | Q17: 13771.92 | R17: 8993.82 | S17: 15219.12 | T17: 13536.36 | U17: 12578.52 | V17: 12655.02 | W17: 7431.54 | X17: 11242.68 | Y17: 10719.9 | Z17: 13547.1 | AA17: 12042.9 | AB17: 11889.9 | AC17: 9909.3 | AD17: 13209.48 | AE17: 11904.36 | AF17: 11997.48 | AG17: 8639.88 | AH17: 14560.2 | AI17: 12274.44 | AJ17: 11800 | AK17: 864 | AL17: 11325.3 | AM17: =IFERROR(AL17/AJ17,0) -> 0.95977119 | AN17: =+AK17+AL17 -> 12189.3 | AO17: =IFERROR(+AN17/AJ17,0) -> 1.0329915
A18: SALCHICHAS - ARG | D18: Subtotal Distribuidores Interior | E18: =+SUM(E3:E17) -> 348150.24 | F18: =+SUM(F3:F17) -> 357502.08 | G18: =+SUM(G3:G17) -> 382299.9 | H18: =+SUM(H3:H17) -> 415760.7 | I18: =+SUM(I3:I17) -> 462919.98 | J18: =+SUM(J3:J17) -> 437209.86 | K18: =+SUM(K3:K17) -> 441841.74 | L18: =+SUM(L3:L17) -> 400028.7 | ... AD18: =+SUM(AD3:AD17) -> 452007.3 | AE18: 363922.86 | AF18: 355206.72 | AG18: 354347.04 | AH18: 386931.18 | AI18: 353860.98 | AJ18: 343500 | AK18: =+SUM(AK3:AK17) -> 54181.56 | AL18: =+SUM(AL3:AL17) -> 200331.3 | AM18: =IFERROR(AL18/AJ18,0) -> 0.58320611 | AN18: =+SUM(AN3:AN17) -> 254512.86 | AO18: =IFERROR(+AN18/AJ18,0) -> 0.74093991
A19: SALCHICHAS - ARG | B19: Interior - Cadenas | C19: JUAN BESSONE | D19: CABARDOS CLAUDIO SANTIAGO | E19: 6894.96 | F19: 10291.56 | G19: 9117.78 | H19: 10687.98 | I19: 9906.3 | J19: 6731.88 | K19: 4937.64 | L19: 5550.18 | M19: 7282.98 | N19: 7478.04 | O19: 8269.56 | P19: 6914.4 | Q19: 7848.98 | R19: 7367.48 | S19: 6472.82 | T19: 5889.92 | U19: 6885.2 | V19: 4616.88 | W19: 4554.42 | X19: 4150.66 | Y19: 3592.66 | Z19: 6205.74 | AA19: 5483.42 | AB19: 4602.44 | AC19: 5465.76 | AD19: 3934.5 | AE19: 4772.1 | AF19: 3255 | AG19: 3275.34 | AH19: 3876 | AI19: 3748.62 | AJ19: 4500 | AK19: 46.08 | AL19: 3212.22 | AM19: =IFERROR(AL19/AJ19,0) -> 0.71382667 | AN19: =+AK19+AL19 -> 3258.3 | AO19: =IFERROR(+AN19/AJ19,0) -> 0.72406667
A20: SALCHICHAS - ARG | B20: Interior - Cadenas | C20: JUAN BESSONE | D20: MEINERI JOSE MARIA | E20: 44528.28 | F20: 39764.34 | G20: 48175.92 | H20: 66296.58 | I20: 53476.62 | J20: 34486.98 | K20: 30798.54 | L20: 47363.88 | M20: 35907.3 | N20: 41012.76 | O20: 46329.6 | P20: 45846.12 | Q20: 44187.78 | R20: 48106.02 | S20: 29608.2 | T20: 54589.26 | U20: 35370.6 | V20: 41635.08 | W20: 49810.02 | X20: 35403.06 | Y20: 34372.08 | Z20: 35988.48 | AA20: 33899.46 | AB20: 46604.16 | AC20: 34787.82 | AD20: 37246.38 | AE20: 32108.7 | AF20: 29480.4 | AG20: 31524.78 | AH20: 24128.34 | AI20: 30706.2 | AJ20: 33000 | AK20: 7231.26 | AL20: 16863.12 | AM20: =IFERROR(AL20/AJ20,0) -> 0.51100364 | AN20: =+AK20+AL20 -> 24094.38 | AO20: =IFERROR(+AN20/AJ20,0) -> 0.73013273
A21: SALCHICHAS - ARG | B21: Interior - Cadenas | C21: JUAN BESSONE | D21: FERNANDEZ JORGE OSCAR | E21: 32935.98 | F21: 27450.18 | G21: 35359.56 | H21: 40495.14 | I21: 40494.96 | J21: 23206.98 | K21: 30261.36 | L21: 24660.18 | M21: 48618.06 | N21: 57384.54 | O21: 36990.78 | P21: 49652.88 | Q21: 48138.42 | R21: 41774.64 | S21: 72205.8 | T21: 46319.82 | U21: 53755.08 | V21: 65037.96 | W21: 51697.2 | X21: 33644.22 | Y21: 43958.4 | Z21: 70777.56 | AA21: 52361.76 | AB21: 55555.74 | AC21: 48139.86 | AD21: 36960.12 | AE21: 41638.2 | AF21: 32034.18 | AG21: 30394.74 | AH21: 47464.68 | AI21: 51663.18 | AJ21: 45000 | AK21: 8245.14 | AL21: 37972.02 | AM21: =IFERROR(AL21/AJ21,0) -> 0.84382267 | AN21: =+AK21+AL21 -> 46217.16 | AO21: =IFERROR(+AN21/AJ21,0) -> 1.027048
A22: SALCHICHAS - ARG | D22: Subtotal Regionales Interior | E22: =+SUM(E19:E21) -> 84359.22 | F22: =+SUM(F19:F21) -> 77506.08 | G22: =+SUM(G19:G21) -> 92653.26 | H22: =+SUM(H19:H21) -> 117479.7 | I22: =+SUM(I19:I21) -> 103877.88 | J22: =+SUM(J19:J21) -> 64425.84 | K22: =+SUM(K19:K21) -> 65997.54 | L22: =+SUM(L19:L21) -> 77574.24 | ... R22: =+SUM(R19:R21) -> 97248.14 | S22: 108286.82 | T22: =+SUM(T19:T21) -> 106799 | U22: =+SUM(U19:U21) -> 96010.88 | V22: =+SUM(V19:V21) -> 111289.92 | W22: =+SUM(W19:W21) -> 106061.64 | X22: =+SUM(X19:X21) -> 73197.94 | Y22: 81923.14 | Z22: 112971.78 | AA22: 91744.64 | AB22: 106762.34 | AC22: 88393.44 | AD22: 78141 | AE22: 78519 | AF22: 64769.58 | AG22: 65194.86 | AH22: 75469.02 | AI22: 86118 | AJ22: 82500 | AK22: =+SUM(AK19:AK21) -> 15522.48 | AL22: =+SUM(AL19:AL21) -> 58047.36 | AM22: =IFERROR(AL22/AJ22,0) -> 0.70360436 | AN22: =+SUM(AN19:AN21) -> 73569.84 | AO22: =IFERROR(+AN22/AJ22,0) -> 0.89175564
A23: SALCHICHAS - ARG | B23: Capital | C23: FEDERICO JACUM | D23: VELAZQUEZ JONATAN WALTER | E23: 16294.56 | F23: 9241.38 | G23: 15490.5 | H23: 16985.46 | I23: 16565.22 | J23: 17875.68 | K23: 11751.42 | L23: 11667.24 | M23: 11146.8 | N23: 10342.38 | O23: 24960.48 | P23: 18172.68 | Q23: 17166.24 | R23: 27058.32 | S23: 21648.9 | T23: 18600.54 | U23: 20401.08 | V23: 19218.12 | W23: 11779.68 | X23: 14412.48 | Y23: 14059.68 | Z23: 11002.86 | AA23: 13530.3 | AB23: 13140.72 | AC23: 11240.4 | AD23: 21079.8 | AE23: 12360.72 | AF23: 16173.6 | AG23: 9893.22 | AH23: 13930.02 | AI23: 13167.06 | AJ23: 14000 | AK23: 486 | AL23: 10015.08 | AM23: =IFERROR(AL23/AJ23,0) -> 0.71536286 | AN23: =+AK23+AL23 -> 10501.08 | AO23: =IFERROR(+AN23/AJ23,0) -> 0.75007714
A24: SALCHICHAS - ARG | B24: GBA (Oeste) | C24: FEDERICO JACUM | D24: TAPIA NERINA MARIELA | E24: 23863.02 | F24: 17484.3 | G24: 24630.6 | H24: 28144.92 | I24: 29195.4 | J24: 32785.08 | K24: 38384.82 | L24: 42660.36 | M24: 32899.08 | N24: 31105.2 | O24: 26337.6 | P24: 26986.68 | Q24: 19220.4 | R24: 26098.32 | S24: 26501.4 | T24: 17000.16 | U24: 22110.72 | V24: 23864.04 | W24: 16470.36 | X24: 14477.4 | Y24: 14336.46 | Z24: 15027.6 | AA24: 16119 | AB24: 17880.24 | AC24: 21265.98 | AD24: 17800.68 | AE24: 15460.44 | AF24: 18051.12 | AG24: 14053.92 | AH24: 21255.6 | AI24: 17125.98 | AJ24: 16800 | AK24: 648 | AL24: 9897.6 | AM24: =IFERROR(AL24/AJ24,0) -> 0.58914286 | AN24: =+AK24+AL24 -> 10545.6 | AO24: =IFERROR(+AN24/AJ24,0) -> 0.62771429
A25: SALCHICHAS - ARG | B25: GBA (Sur) | C25: FEDERICO JACUM | D25: VINCZE CINTIA LORENA | E25: 34882.8 | F25: 29839.2 | G25: 37211.4 | H25: 37233.6 | I25: 33715.02 | J25: 41355.24 | K25: 35703.3 | L25: 35063.1 | M25: 41224.8 | N25: 35248.2 | O25: 37397.16 | P25: 30973.98 | Q25: 32100.06 | R25: 36486.3 | S25: 39498.18 | T25: 29474.16 | U25: 38307.42 | V25: 39212.7 | W25: 31365.6 | X25: 35002.8 | Y25: 25739.88 | Z25: 34239.6 | AA25: 36015.54 | AB25: 26154.6 | AC25: 28405.2 | AD25: 24042 | AE25: 22510.2 | AF25: 29057.4 | AG25: 28823.4 | AH25: 23829.84 | AI25: 25597.56 | AJ25: 25500 | AK25: 3427.2 | AL25: 14088.72 | AM25: =IFERROR(AL25/AJ25,0) -> 0.55249882 | AN25: =+AK25+AL25 -> 17515.92 | AO25: =IFERROR(+AN25/AJ25,0) -> 0.68689882
A26: SALCHICHAS - ARG | B26: GBA (Sur) | C26: FEDERICO JACUM | D26: GOMEZ OURAL ALBERTO | E26: 35685.6 | F26: 33638.4 | G26: 34844.4 | H26: 33789.9 | I26: 40828.2 | J26: 38242.2 | K26: 52590.96 | L26: 46155.96 | M26: 43379.52 | N26: 40274.04 | O26: 36596.4 | P26: 34023.6 | Q26: 22079.4 | R26: 35971.2 | S26: 31178.4 | T26: 24830.4 | U26: 33460.8 | V26: 26541.6 | W26: 29010.6 | X26: 25492.2 | Y26: 23043.6 | Z26: 28103.4 | AA26: 23828.28 | AB26: 22274.4 | AC26: 26706.6 | AD26: 21070.2 | AE26: 24311.4 | AF26: 22680 | AG26: 17565 | AH26: 25228.32 | AI26: 21525.6 | AJ26: 22900 | AK26: 432 | AL26: 13577.52 | AM26: =IFERROR(AL26/AJ26,0) -> 0.5929048 | AN26: =+AK26+AL26 -> 14009.52 | AO26: =IFERROR(+AN26/AJ26,0) -> 0.61176943
A27: SALCHICHAS - ARG | B27: Costa | C27: FEDERICO JACUM | D27: MARTINO FLAVIO | E27: 13495.8 | F27: 15040.8 | G27: 11033.1 | H27: 14846.1 | I27: 14973.9 | J27: 18412.14 | K27: 31243.98 | L27: 19176.12 | M27: 16669.8 | N27: 13496.28 | O27: 17167.2 | P27: 18609.3 | Q27: 15474.9 | R27: 10677.36 | S27: 17160.3 | T27: 13631.58 | U27: 14991.6 | V27: 18290.88 | W27: 26546.22 | X27: 16558.56 | Y27: 11161.14 | Z27: 12504 | AA27: 11700.12 | AB27: 14082 | AC27: 13680.3 | AD27: 13205.7 | AE27: 12126 | AF27: 13617.3 | AG27: 12336.96 | AH27: 22847.64 | AI27: 27250.38 | AJ27: 20800 | AK27: 489.6 | AL27: 14381.94 | AM27: =IFERROR(AL27/AJ27,0) -> 0.69143942 | AN27: =+AK27+AL27 -> 14871.54 | AO27: =IFERROR(+AN27/AJ27,0) -> 0.71497788
A28: SALCHICHAS - ARG | D28: Subtotal Distribuidores GBA y Costa | E28: =+SUM(E23:E27) -> 124221.78 | F28: =+SUM(F23:F27) -> 105244.08 | G28: =+SUM(G23:G27) -> 123210 | H28: =+SUM(H23:H27) -> 130999.98 | I28: =+SUM(I23:I27) -> 135277.74 | J28: =+SUM(J23:J27) -> 148670.34 | K28: =+SUM(K23:K27) -> 169674.48 | L28: =+SUM(L23:L27) -> 154722.78 | ... AD28: =+SUM(AD23:AD27) -> 97198.38 | AE28: 86768.76 | AF28: 99579.42 | AG28: 82672.5 | AH28: 107091.42 | AI28: 104666.58 | AJ28: 100000 | AK28: =+SUM(AK23:AK27) -> 5482.8 | AL28: =+SUM(AL23:AL27) -> 61960.86 | AM28: =IFERROR(AL28/AJ28,0) -> 0.6196086 | AN28: =+SUM(AN23:AN27) -> 67443.66 | AO28: =IFERROR(+AN28/AJ28,0) -> 0.6744366
A29: SALCHICHAS - ARG | B29: Patagonia / Costa - Cadenas | C29: FEDERICO JACUM | D29: VAL JULIAN | E29: 21260.34 | F29: 11622.66 | G29: 13211.64 | H29: 15844.2 | I29: 19666.38 | J29: 8502.06 | K29: 29082.66 | L29: 14613.42 | M29: 31068.54 | N29: 49595.04 | O29: 42512.52 | P29: 9172.08 | Q29: 27431.34 | R29: 22879.5 | S29: 26528.34 | T29: 18256.98 | U29: 20328.3 | V29: 19045.14 | W29: 31285.38 | X29: 12915.3 | Y29: 6096.12 | Z29: 13529.04 | AA29: 5658.84 | AB29: 2255.52 | AC29: 13742.04 | AD29: 8105.52 | AE29: 2156.88 | AF29: 2792.04 | AG29: 1474.92 | AH29: 2677.32 | AI29: 3992.64 | AJ29: 7000 | AK29: 1572 | AL29: 1399.08 | AM29: =IFERROR(AL29/AJ29,0) -> 0.19986857 | AN29: =+AK29+AL29 -> 2971.08 | AO29: =IFERROR(+AN29/AJ29,0) -> 0.42444 | AP29: 100088964 | AQ29: RAMOS LUCIANO ALEJANDRO
A30: SALCHICHAS - ARG | D30: Subtotal Regionales GBA, Costa y Patagonia | E30: =+SUM(E29) -> 21260.34 | F30: =+SUM(F29) -> 11622.66 | G30: =+SUM(G29) -> 13211.64 | H30: =+SUM(H29) -> 15844.2 | I30: =+SUM(I29) -> 19666.38 | J30: =+SUM(J29) -> 8502.06 | K30: =+SUM(K29) -> 29082.66 | L30: =+SUM(L29) -> 14613.42 | ... R30: =+SUM(R29) -> 22879.5 | S30: 26528.34 | T30: =+SUM(T29) -> 18256.98 | U30: =+SUM(U29) -> 20328.3 | V30: =+SUM(V29) -> 19045.14 | W30: =+SUM(W29) -> 31285.38 | X30: =+SUM(X29) -> 12915.3 | Y30: 6096.12 | Z30: 13529.04 | AA30: 5658.84 | AB30: 2255.52 | AC30: 13742.04 | AD30: 8105.52 | AE30: 2156.88 | AF30: 2792.04 | AG30: 1474.92 | AH30: 2677.32 | AI30: 3992.64 | AJ30: 7000 | AK30: =+SUM(AK29) -> 1572 | AL30: =+SUM(AL29) -> 1399.08 | AM30: =IFERROR(AL30/AJ30,0) -> 0.19986857 | AN30: =+SUM(AN29) -> 2971.08 | AO30: =IFERROR(+AN30/AJ30,0) -> 0.42444
A31: SALCHICHAS - ARG | B31: Gastronomia | C31: HERNAN DUARTE | D31: RAMIREZ ARIEL SEBASTIAN | E31: 12591.6 | F31: 16058.4 | G31: 15248.4 | H31: 14898 | I31: 18070.5 | J31: 14485.38 | K31: 13435.92 | L31: 14706.9 | M31: 9855 | N31: 10754.88 | O31: 11392.5 | P31: 9655.86 | Q31: 13420.38 | R31: 16200.66 | S31: 15079.8 | T31: 9947.58 | U31: 18678.9 | V31: 13146.3 | W31: 17089.26 | X31: 10561.62 | Y31: 7427.7 | Z31: 12121.62 | AA31: 11395.68 | AB31: 8671.32 | AC31: 10780.2 | AD31: 13828.5 | AE31: 11162.52 | AF31: 12324.84 | AG31: 13814.1 | AH31: 15567 | AI31: 14679.78 | AJ31: 16500 | AK31: 69.6 | AL31: 11073.3 | AM31: =IFERROR(AL31/AJ31,0) -> 0.67110909 | AN31: =+AK31+AL31 -> 11142.9 | AO31: =IFERROR(+AN31/AJ31,0) -> 0.67532727
A32: SALCHICHAS - ARG | B32: Gastronomia | C32: HERNAN DUARTE | D32: DUARTE HERNAN | E32: 3108 | F32: 1501.2 | G32: 1121.4 | H32: 502.8 | I32: 4821.9 | J32: 10696.5 | K32: 4887.9 | L32: 1191.9 | M32: 1629.9 | N32: 984.9 | O32: 831.6 | P32: 578.1 | Q32: 787.5 | R32: 473.7 | S32: 1004.4 | T32: 276.9 | U32: 487.5 | V32: 504 | W32: 523.8 | X32: 1004.1 | Y32: 384.9 | Z32: 465 | AA32: 642.6 | AB32: 0 | AC32: 0 | AD32: 0 | AE32: 459.6 | AF32: 270 | AG32: 564.3 | AH32: 186.3 | AI32: 453.6 | AJ32: 500 | AK32: 0 | AL32: 162 | AM32: =IFERROR(AL32/AJ32,0) -> 0.324 | AN32: =+AK32+AL32 -> 162 | AO32: =IFERROR(+AN32/AJ32,0) -> 0.324 | AP32: VACANTE DIRECTO FOOD SERVICE IND
