Workbook

Sheet DINAMICA ENERO 26
B2: MES: | C2: 46054
E4: CHORIZOS | H4: PAPAS | K4: VEGGIES | N4: RB (kids + crunchies) | Q4: UNT (picante/jalapeño) | T4: MILANESITAS | W4: ATUN
B5: Jefe | C5: NOM VENDEDOR | D5: NOM CENTRALIZADOR | E5: 'Compradores (C) | F5: 'No Compradores (C) | G5: Cobertura (C) | H5: Compradores (P) | I5: No Compradores (P) | J5: Cobertura (P) | K5: Compradores (V) | L5: No Compradores (V) | M5: Cobertura (V) | N5: Compradores (RB) | O5: No Compradores (RB | P5: Cobertura (RB) | Q5: Compradores (UNT) | R5: No compradores (UNT) | S5: Cobertura (UNT) | T5: Compradores (Mil.) | U5: No Compradores (Mil.) | V5: Cobertura (Mil.) | W5: Compradores (Atun) | X5: No compradores (Atun) | Y5: Cobertura (ATUN)
B6: ARUANNO PARODI MARIA NOEL | C6: MENDEZ NAVARRO MARIA ALEJANDRA | E6: 2 | F6: 0 | G6: 1 | H6: 4 | I6: 1 | J6: 0.8 | K6: 4 | L6: 1 | M6: 0.8 | N6: 5 | O6: 0 | P6: 1 | Q6: 2 | R6: 3 | S6: 0.4 | T6: 5 | U6: 0 | V6: 1 | W6: 0 | X6: 5 | Y6: 0
B7: ARUANNO PARODI MARIA NOEL | C7: RAMONDINO LEONARDO ERNESTO | E7: 2 | F7: 2 | G7: 0.5 | H7: 3 | I7: 1 | J7: 0.75 | K7: 3 | L7: 1 | M7: 0.75 | N7: 3 | O7: 1 | P7: 0.75 | Q7: 1 | R7: 3 | S7: 0.25 | T7: 2 | U7: 2 | V7: 0.5 | W7: 0 | X7: 4 | Y7: 0
B8: ARUANNO PARODI MARIA NOEL | C8: RODRIGUEZ JUDITH | E8: 0 | F8: 2 | G8: 0 | H8: 1 | I8: 1 | J8: 0.5 | K8: 1 | L8: 1 | M8: 0.5 | N8: 2 | O8: 0 | P8: 1 | Q8: 2 | R8: 0 | S8: 1 | T8: 1 | U8: 1 | V8: 0.5 | W8: 0 | X8: 2 | Y8: 0
B9: ARUANNO PARODI MARIA NOEL | C9: BRION SEBASTIAN | E9: 1 | F9: 3 | G9: 0.25 | H9: 3 | I9: 1 | J9: 0.75 | K9: 2 | L9: 2 | M9: 0.5 | N9: 3 | O9: 1 | P9: 0.75 | Q9: 2 | R9: 2 | S9: 0.5 | T9: 1 | U9: 3 | V9: 0.25 | W9: 0 | X9: 4 | Y9: 0
B10: Total ARUANNO PARODI MARIA NOEL | E10: 5 | F10: 7 | G10: 0.41666667 | H10: 11 | I10: 4 | J10: 0.73333333 | K10: 10 | L10: 5 | M10: 0.66666667 | N10: 13 | O10: 2 | P10: 0.86666667 | Q10: 7 | R10: 8 | S10: 0.46666667 | T10: 9 | U10: 6 | V10: 0.6 | W10: 0 | X10: 15 | Y10: 0
B11: BESSONE JUAN | C11: CABARDOS CLAUDIO SANTIAGO | E11: 4 | F11: 4 | G11: 0.5 | H11: 6 | I11: 2 | J11: 0.75 | K11: 5 | L11: 3 | M11: 0.625 | N11: 5 | O11: 3 | P11: 0.625 | Q11: 2 | R11: 6 | S11: 0.25 | T11: 3 | U11: 5 | V11: 0.375 | W11: 0 | X11: 8 | Y11: 0
B12: BESSONE JUAN | C12: FERNANDEZ JORGE OSCAR | E12: 1 | F12: 7 | G12: 0.125 | H12: 8 | I12: 0 | J12: 1 | K12: 8 | L12: 0 | M12: 1 | N12: 6 | O12: 2 | P12: 0.75 | Q12: 5 | R12: 3 | S12: 0.625 | T12: 4 | U12: 4 | V12: 0.5 | W12: 1 | X12: 7 | Y12: 0.125
B13: BESSONE JUAN | C13: MEINERI JOSE MARIA | E13: 3 | F13: 9 | G13: 0.25 | H13: 9 | I13: 3 | J13: 0.75 | K13: 6 | L13: 6 | M13: 0.5 | N13: 7 | O13: 5 | P13: 0.58333333 | Q13: 6 | R13: 6 | S13: 0.5 | T13: 4 | U13: 8 | V13: 0.33333333 | W13: 1 | X13: 11 | Y13: 0.083333333
B14: Total BESSONE JUAN | E14: 8 | F14: 20 | G14: 0.28571429 | H14: 23 | I14: 5 | J14: 0.82142857 | K14: 19 | L14: 9 | M14: 0.67857143 | N14: 18 | O14: 10 | P14: 0.64285714 | Q14: 13 | R14: 15 | S14: 0.46428571 | T14: 11 | U14: 17 | V14: 0.39285714 | W14: 2 | X14: 26 | Y14: 0.071428571
B15: DALLA VERDE RAMON ADRIAN | C15: APUD ALEXANDER DARIO | E15: 8 | F15: 7 | G15: 0.53333333 | H15: 9 | I15: 6 | J15: 0.6 | K15: 7 | L15: 8 | M15: 0.46666667 | N15: 11 | O15: 4 | P15: 0.73333333 | Q15: 7 | R15: 8 | S15: 0.46666667 | T15: 9 | U15: 6 | V15: 0.6 | W15: 3 | X15: 12 | Y15: 0.2
B16: DALLA VERDE RAMON ADRIAN | C16: FUNES ANDRES | E16: 10 | F16: 15 | G16: 0.4 | H16: 11 | I16: 14 | J16: 0.44 | K16: 11 | L16: 14 | M16: 0.44 | N16: 14 | O16: 11 | P16: 0.56 | Q16: 7 | R16: 18 | S16: 0.28 | T16: 11 | U16: 14 | V16: 0.44 | W16: 6 | X16: 19 | Y16: 0.24
B17: DALLA VERDE RAMON ADRIAN | C17: PAZ CARRANZA EDUARDO | E17: 5 | F17: 19 | G17: 0.20833333 | H17: 10 | I17: 14 | J17: 0.41666667 | K17: 4 | L17: 20 | M17: 0.16666667 | N17: 13 | O17: 11 | P17: 0.54166667 | Q17: 1 | R17: 23 | S17: 0.041666667 | T17: 4 | U17: 20 | V17: 0.16666667 | W17: 5 | X17: 19 | Y17: 0.20833333
B18: DALLA VERDE RAMON ADRIAN | C18: ROBLEDO JORGE LUIS | E18: 5 | F18: 14 | G18: 0.26315789 | H18: 8 | I18: 11 | J18: 0.42105263 | K18: 7 | L18: 12 | M18: 0.36842105 | N18: 8 | O18: 11 | P18: 0.42105263 | Q18: 3 | R18: 16 | S18: 0.15789474 | T18: 0 | U18: 19 | V18: 0 | W18: 2 | X18: 17 | Y18: 0.10526316
B19: DALLA VERDE RAMON ADRIAN | C19: SANCHEZ JUAN CARLOS | E19: 3 | F19: 11 | G19: 0.21428571 | H19: 5 | I19: 9 | J19: 0.35714286 | K19: 2 | L19: 12 | M19: 0.14285714 | N19: 7 | O19: 7 | P19: 0.5 | Q19: 0 | R19: 14 | S19: 0 | T19: 1 | U19: 13 | V19: 0.071428571 | W19: 1 | X19: 13 | Y19: 0.071428571
B20: DALLA VERDE RAMON ADRIAN | C20: SCARAFIA YAMIL HERMES | E20: 5 | F20: 10 | G20: 0.33333333 | H20: 6 | I20: 9 | J20: 0.4 | K20: 4 | L20: 11 | M20: 0.26666667 | N20: 5 | O20: 10 | P20: 0.33333333 | Q20: 2 | R20: 13 | S20: 0.13333333 | T20: 2 | U20: 13 | V20: 0.13333333 | W20: 1 | X20: 14 | Y20: 0.066666667
B21: DALLA VERDE RAMON ADRIAN | C21: GENTILE NICOLAS | E21: 7 | F21: 21 | G21: 0.25 | H21: 9 | I21: 19 | J21: 0.32142857 | K21: 6 | L21: 22 | M21: 0.21428571 | N21: 8 | O21: 20 | P21: 0.28571429 | Q21: 3 | R21: 25 | S21: 0.10714286 | T21: 7 | U21: 21 | V21: 0.25 | W21: 2 | X21: 26 | Y21: 0.071428571
B22: Total DALLA VERDE RAMON ADRIAN | E22: 43 | F22: 97 | G22: 0.30714286 | H22: 58 | I22: 82 | J22: 0.41428571 | K22: 41 | L22: 99 | M22: 0.29285714 | N22: 66 | O22: 74 | P22: 0.47142857 | Q22: 23 | R22: 117 | S22: 0.16428571 | T22: 34 | U22: 106 | V22: 0.24285714 | W22: 20 | X22: 120 | Y22: 0.14285714
B23: MARCELO VEGA | C23: ALONSO GUSTAVO DANIEL | E23: 5 | F23: 11 | G23: 0.3125 | H23: 5 | I23: 11 | J23: 0.3125 | K23: 6 | L23: 10 | M23: 0.375 | N23: 7 | O23: 9 | P23: 0.4375 | Q23: 4 | R23: 12 | S23: 0.25 | T23: 6 | U23: 10 | V23: 0.375 | W23: 3 | X23: 13 | Y23: 0.1875
B24: MARCELO VEGA | C24: ANDINO FACUNDO NICOLAS | E24: 0 | F24: 23 | G24: 0 | H24: 6 | I24: 17 | J24: 0.26086957 | K24: 6 | L24: 17 | M24: 0.26086957 | N24: 8 | O24: 15 | P24: 0.34782609 | Q24: 5 | R24: 18 | S24: 0.2173913 | T24: 4 | U24: 19 | V24: 0.17391304 | W24: 4 | X24: 19 | Y24: 0.17391304
B25: MARCELO VEGA | C25: ORGAZ GUSTAVO EMANUEL | E25: 0 | F25: 15 | G25: 0 | H25: 6 | I25: 9 | J25: 0.4 | K25: 2 | L25: 13 | M25: 0.13333333 | N25: 9 | O25: 6 | P25: 0.6 | Q25: 2 | R25: 13 | S25: 0.13333333 | T25: 5 | U25: 10 | V25: 0.33333333 | W25: 0 | X25: 15 | Y25: 0
B26: MARCELO VEGA | C26: VILOTTA SEBASTIAN | E26: 6 | F26: 16 | G26: 0.27272727 | H26: 8 | I26: 14 | J26: 0.36363636 | K26: 4 | L26: 18 | M26: 0.18181818 | N26: 11 | O26: 11 | P26: 0.5 | Q26: 5 | R26: 17 | S26: 0.22727273 | T26: 8 | U26: 14 | V26: 0.36363636 | W26: 3 | X26: 19 | Y26: 0.13636364
B27: MARCELO VEGA | C27: VIVARES ABEL MAURICIO | E27: 6 | F27: 23 | G27: 0.20689655 | H27: 15 | I27: 14 | J27: 0.51724138 | K27: 11 | L27: 18 | M27: 0.37931034 | N27: 16 | O27: 13 | P27: 0.55172414 | Q27: 11 | R27: 18 | S27: 0.37931034 | T27: 11 | U27: 18 | V27: 0.37931034 | W27: 12 | X27: 17 | Y27: 0.4137931
B28: MARCELO VEGA | C28: SCHAIGORODSKY IGNACIO | E28: 6 | F28: 14 | G28: 0.3 | H28: 7 | I28: 13 | J28: 0.35 | K28: 7 | L28: 13 | M28: 0.35 | N28: 13 | O28: 7 | P28: 0.65 | Q28: 2 | R28: 18 | S28: 0.1 | T28: 2 | U28: 18 | V28: 0.1 | W28: 6 | X28: 14 | Y28: 0.3
B29: Total MARCELO VEGA | E29: 23 | F29: 102 | G29: 0.184 | H29: 47 | I29: 78 | J29: 0.376 | K29: 36 | L29: 89 | M29: 0.288 | N29: 64 | O29: 61 | P29: 0.512 | Q29: 29 | R29: 96 | S29: 0.232 | T29: 36 | U29: 89 | V29: 0.288 | W29: 28 | X29: 97 | Y29: 0.224
B30: FEDERICO JACUM | C30: GOMEZ OURAL ALBERTO | E30: 0 | F30: 3 | G30: 0 | H30: 2 | I30: 1 | J30: 0.66666667 | K30: 0 | L30: 3 | M30: 0 | N30: 2 | O30: 1 | P30: 0.66666667 | Q30: 0 | R30: 3 | S30: 0 | T30: 1 | U30: 2 | V30: 0.33333333 | W30: 0 | X30: 3 | Y30: 0
B31: FEDERICO JACUM | C31: MARTINO FLAVIO | E31: 1 | F31: 5 | G31: 0.16666667 | H31: 2 | I31: 4 | J31: 0.33333333 | K31: 4 | L31: 2 | M31: 0.66666667 | N31: 6 | O31: 0 | P31: 1 | Q31: 1 | R31: 5 | S31: 0.16666667 | T31: 1 | U31: 5 | V31: 0.16666667 | W31: 0 | X31: 6 | Y31: 0
B32: FEDERICO JACUM | C32: TAPIA NERINA MARIELA | E32: 1 | F32: 5 | G32: 0.16666667 | H32: 4 | I32: 2 | J32: 0.66666667 | K32: 2 | L32: 4 | M32: 0.33333333 | N32: 3 | O32: 3 | P32: 0.5 | Q32: 2 | R32: 4 | S32: 0.33333333 | T32: 2 | U32: 4 | V32: 0.33333333 | W32: 1 | X32: 5 | Y32: 0.16666667
B33: FEDERICO JACUM | C33: VAL JULIAN | E33: 0 | F33: 5 | G33: 0 | H33: 2 | I33: 3 | J33: 0.4 | K33: 2 | L33: 3 | M33: 0.4 | N33: 3 | O33: 2 | P33: 0.6 | Q33: 0 | R33: 5 | S33: 0 | T33: 2 | U33: 3 | V33: 0.4 | W33: 0 | X33: 5 | Y33: 0
B34: FEDERICO JACUM | C34: VELAZQUEZ JONATAN WALTER | E34: 1 | F34: 10 | G34: 0.090909091 | H34: 3 | I34: 8 | J34: 0.27272727 | K34: 4 | L34: 7 | M34: 0.36363636 | N34: 5 | O34: 6 | P34: 0.45454545 | Q34: 4 | R34: 7 | S34: 0.36363636 | T34: 2 | U34: 9 | V34: 0.18181818 | W34: 2 | X34: 9 | Y34: 0.18181818
B35: FEDERICO JACUM | C35: VINCZE CINTIA LORENA | E35: 0 | F35: 4 | G35: 0 | H35: 0 | I35: 4 | J35: 0 | K35: 2 | L35: 2 | M35: 0.5 | N35: 3 | O35: 1 | P35: 0.75 | Q35: 1 | R35: 3 | S35: 0.25 | T35: 0 | U35: 4 | V35: 0 | W35: 0 | X35: 4 | Y35: 0
B36: Total FEDERICO JACUM | E36: 3 | F36: 32 | G36: 0.085714286 | H36: 13 | I36: 22 | J36: 0.37142857 | K36: 14 | L36: 21 | M36: 0.4 | N36: 22 | O36: 13 | P36: 0.62857143 | Q36: 8 | R36: 27 | S36: 0.22857143 | T36: 8 | U36: 27 | V36: 0.22857143 | W36: 3 | X36: 32 | Y36: 0.085714286
B37: DUARTE HERNAN | C37: RAMIREZ ARIEL SEBASTIAN | E37: 1 | F37: 17 | G37: 0.055555556 | H37: 0 | I37: 18 | J37: 0 | K37: 1 | L37: 17 | M37: 0.055555556 | N37: 7 | O37: 11 | P37: 0.38888889 | Q37: 0 | R37: 18 | S37: 0 | T37: 5 | U37: 13 | V37: 0.27777778 | W37: 0 | X37: 18 | Y37: 0
B38: DUARTE HERNAN | C38: DUARTE HERNAN | E38: 0 | F38: 3 | G38: 0 | H38: 0 | I38: 3 | J38: 0 | K38: 0 | L38: 3 | M38: 0 | N38: 0 | O38: 3 | P38: 0 | Q38: 0 | R38: 3 | S38: 0 | T38: 0 | U38: 3 | V38: 0 | W38: 0 | X38: 3 | Y38: 0
B39: Total DUARTE HERNAN | E39: 1 | F39: 20 | G39: 0.047619048 | H39: 0 | I39: 21 | J39: 0 | K39: 1 | L39: 20 | M39: 0.047619048 | N39: 7 | O39: 14 | P39: 0.33333333 | Q39: 0 | R39: 21 | S39: 0 | T39: 5 | U39: 16 | V39: 0.23809524 | W39: 0 | X39: 21 | Y39: 0
B40: Total general | E40: 83 | F40: 278 | G40: 0.2299169 | H40: 152 | I40: 212 | J40: 0.41758242 | K40: 121 | L40: 243 | M40: 0.33241758 | N40: 190 | O40: 174 | P40: 0.52197802 | Q40: 80 | R40: 284 | S40: 0.21978022 | T40: 103 | U40: 261 | V40: 0.28296703 | W40: 53 | X40: 311 | Y40: 0.1456044

Sheet Chorizos
A1: COMPRADORES CHORIZOS | S1: 100520837 | T1: 100522395
A2: CANAL | B2: ZONA | C2: Jefe | D2: COD VENDEDOR | E2: NOM VENDEDOR | F2: COD CENTRALIZADOR | G2: NOM CENTRALIZADOR | H2: AGO 25 | I2: SEP 25 | J2: OCT 25 | K2: NOV '25 | L2: DIC '25 | M2: ENE '26 | N2: PROMEDIO ULT 3 MESES | O2: =+UPPER(TEXT('DINAMICA ENERO 26'!$C$2,"mmm 'yy"))&" FACT" -> FEB '26 FACT | P2: =+UPPER(TEXT('DINAMICA ENERO 26'!$C$2,"mmm 'yy"))&" PEND." -> FEB '26 PEND. | Q2: =+UPPER(TEXT('DINAMICA ENERO 26'!$C$2,"mmm 'yy"))&" TOTAL" -> FEB '26 TOTAL | R2: ESTADO
A3: Distribuidores | B3: Capital | C3: FEDERICO JACUM | D3: 100077477 | E3: VELAZQUEZ JONATAN WALTER | F3: 100086577 | G3: LOGISTICA Y DISTRIBUCION RIBAUDO HNOS S.A. | H3: 9.6 | I3: 0 | J3: 4.8 | K3: 4.8 | L3: 24 | M3: 4.8 | N3: =+AVERAGE(K3:M3) -> 11.2 | O3: 0 | P3: 0 | Q3: =+O3+P3 -> 0 | R3: =+IF(Q3+N3<=0, "NO COMPRADOR", +IF(Q3<=0, "SIN COMPRA "&+UPPER(TEXT('DINAMICA ENERO 26'!$C$2,"mmm 'yy")), "COMPRADOR")) -> SIN COMPRA FEB '26
A4: Distribuidores | B4: Capital | C4: FEDERICO JACUM | D4: 100077477 | E4: VELAZQUEZ JONATAN WALTER | F4: 100065731 | G4: CINCUNEGUI MARCELO RODOLFO | H4: 0 | I4: 0 | J4: 0 | K4: 0 | L4: 0 | M4: 0 | N4: =+AVERAGE(K4:M4) -> 0 | O4: 0 | P4: 0 | Q4: =+O4+P4 -> 0 | R4: =+IF(Q4+N4<=0, "NO COMPRADOR", +IF(Q4<=0, "SIN COMPRA "&+UPPER(TEXT('DINAMICA ENERO 26'!$C$2,"mmm 'yy")), "COMPRADOR")) -> NO COMPRADOR
A5: Distribuidores | B5: Capital | C5: FEDERICO JACUM | D5: 100077477 | E5: VELAZQUEZ JONATAN WALTER | F5: 100010095 | G5: SUPERCONGELADOS FATIMA SOCIEDAD ANONIMA | H5: 48 | I5: 38.4 | J5: 14.4 | K5: 0 | L5: 33.6 | M5: 28.8 | N5: =+AVERAGE(K5:M5) -> 20.8 | O5: 14.4 | P5: 0 | Q5: =+O5+P5 -> 14.4 | R5: =+IF(Q5+N5<=0, "NO COMPRADOR", +IF(Q5<=0, "SIN COMPRA "&+UPPER(TEXT('DINAMICA ENERO 26'!$C$2,"mmm 'yy")), "COMPRADOR")) -> COMPRADOR
A6: Distribuidores | B6: Capital | C6: FEDERICO JACUM | D6: 100077477 | E6: VELAZQUEZ JONATAN WALTER | F6: 100079173 | G6: IQF DISTRIBUCION S.A. | H6: 0 | I6: 0 | J6: 0 | K6: 0 | L6: 24 | M6: 14.4 | N6: =+AVERAGE(K6:M6) -> 12.8 | O6: 0 | P6: 0 | Q6: =+O6+P6 -> 0 | R6: =+IF(Q6+N6<=0, "NO COMPRADOR", +IF(Q6<=0, "SIN COMPRA "&+UPPER(TEXT('DINAMICA ENERO 26'!$C$2,"mmm 'yy")), "COMPRADOR")) -> SIN COMPRA FEB '26
A7: Distribuidores | B7: Capital | C7: FEDERICO JACUM | D7: 100077477 | E7: VELAZQUEZ JONATAN WALTER | F7: 100079594 | G7: DANIEL BUENO SAU | H7: 14.4 | I7: 0 | J7: 0 | K7: 0 | L7: 9.6 | M7: 14.4 | N7: =+AVERAGE(K7:M7) -> 8 | O7: 0 | P7: 0 | Q7: =+O7+P7 -> 0 | R7: =+IF(Q7+N7<=0, "NO COMPRADOR", +IF(Q7<=0, "SIN COMPRA "&+UPPER(TEXT('DINAMICA ENERO 26'!$C$2,"mmm 'yy")), "COMPRADOR")) -> SIN COMPRA FEB '26
A8: Distribuidores | B8: Capital | C8: FEDERICO JACUM | D8: 100077477 | E8: VELAZQUEZ JONATAN WALTER | F8: 100078788 | G8: CAMPO DE SABORES S.A.S. | H8: 0 | I8: 0 | J8: 0 | K8: 0 | L8: 19.2 | M8: 0 | N8: =+AVERAGE(K8:M8) -> 6.4 | O8: 0 | P8: 0 | Q8: =+O8+P8 -> 0 | R8: =+IF(Q8+N8<=0, "NO COMPRADOR", +IF(Q8<=0, "SIN COMPRA "&+UPPER(TEXT('DINAMICA ENERO 26'!$C$2,"mmm 'yy")), "COMPRADOR")) -> SIN COMPRA FEB '26
A9: Distribuidores | B9: Capital | C9: FEDERICO JACUM | D9: 100077477 | E9: VELAZQUEZ JONATAN WALTER | F9: 100084185 | G9: ADN DISTRIBUCION S.R.L. | H9: 4.8 | I9: 0 | J9: 0 | K9: 0 | L9: 0 | M9: 0 | N9: =+AVERAGE(K9:M9) -> 0 | O9: 0 | P9: 0 | Q9: =+O9+P9 -> 0 | R9: =+IF(Q9+N9<=0, "NO COMPRADOR", +IF(Q9<=0, "SIN COMPRA "&+UPPER(TEXT('DINAMICA ENERO 26'!$C$2,"mmm 'yy")), "COMPRADOR")) -> NO COMPRADOR
A10: Distribuidores | B10: Capital | C10: FEDERICO JACUM | D10: 100077477 | E10: VELAZQUEZ JONATAN WALTER | F10: 100087922 | G10: FETECH INVESTMENTS S.A. | H10: 0 | I10: 0 | J10: 0 | K10: 0 | L10: 0 | M10: 0 | N10: =+AVERAGE(K10:M10) -> 0 | O10: 0 | P10: 0 | Q10: =+O10+P10 -> 0 | R10: =+IF(Q10+N10<=0, "NO COMPRADOR", +IF(Q10<=0, "SIN COMPRA "&+UPPER(TEXT('DINAMICA ENERO 26'!$C$2,"mmm 'yy")), "COMPRADOR")) -> NO COMPRADOR
A11: Distribuidores | B11: Capital | C11: FEDERICO JACUM | D11: 100077477 | E11: VELAZQUEZ JONATAN WALTER | F11: 100071741 | G11: BRIENZA DISTRIBUIDORA SOCIEDAD ANONIMA | H11: 0 | I11: 0 | J11: 0 | K11: 0 | L11: 0 | M11: 0 | N11: =+AVERAGE(K11:M11) -> 0 | O11: 0 | P11: 0 | Q11: =+O11+P11 -> 0 | R11: =+IF(Q11+N11<=0, "NO COMPRADOR", +IF(Q11<=0, "SIN COMPRA "&+UPPER(TEXT('DINAMICA ENERO 26'!$C$2,"mmm 'yy")), "COMPRADOR")) -> NO COMPRADOR
A12: Distribuidores | B12: Capital | C12: FEDERICO JACUM | D12: 100077477 | E12: VELAZQUEZ JONATAN WALTER | F12: 100075448 | G12: V&D LAS DOS MARIAS SRL | H12: 4.8 | I12: 0 | J12: 0 | K12: 0 | L12: 28.8 | M12: 0 | N12: =+AVERAGE(K12:M12) -> 9.6 | O12: 0 | P12: 0 | Q12: =+O12+P12 -> 0 | R12: =+IF(Q12+N12<=0, "NO COMPRADOR", +IF(Q12<=0, "SIN COMPRA "&+UPPER(TEXT('DINAMICA ENERO 26'!$C$2,"mmm 'yy")), "COMPRADOR")) -> SIN COMPRA FEB '26
A13: Distribuidores | B13: Capital | C13: FEDERICO JACUM | D13: 100077477 | E13: VELAZQUEZ JONATAN WALTER | F13: 100089232 | G13: DOBLE V DISTRIBUIDORES | H13: 0 | I13: 0 | J13: 0 | K13: 0 | L13: 0 | M13: 0 | N13: =+AVERAGE(K13:M13) -> 0 | O13: 0 | P13: 0 | Q13: =+O13+P13 -> 0 | R13: =+IF(Q13+N13<=0, "NO COMPRADOR", +IF(Q13<=0, "SIN COMPRA "&+UPPER(TEXT('DINAMICA ENERO 26'!$C$2,"mmm 'yy")), "COMPRADOR")) -> NO COMPRADOR
A14: Distribuidores | B14: GBA (Oeste) | C14: FEDERICO JACUM | D14: 100041217 | E14: TAPIA NERINA MARIELA | F14: 100073953 | G14: COMESTIBLES LUFAR SRL | H14: 0 | I14: 0 | J14: 0 | K14: 0 | L14: 0 | M14: 0 | N14: =+AVERAGE(K14:M14) -> 0 | O14: 0 | P14: 0 | Q14: =+O14+P14 -> 0 | R14: =+IF(Q14+N14<=0, "NO COMPRADOR", +IF(Q14<=0, "SIN COMPRA "&+UPPER(TEXT('DINAMICA ENERO 26'!$C$2,"mmm 'yy")), "COMPRADOR")) -> NO COMPRADOR
... A153: Distribuidores | B153: Gastronomia | C153: DUARTE HERNAN | D153: 100031199 | E153: RAMIREZ ARIEL SEBASTIAN | F153: 100085481 | G153: RUANO ROJAS GREISSI | H153: 0 | I153: 0 | J153: 0 | K153: 0 | L153: 0 | M153: 0 | N153: =+AVERAGE(K153:M153) -> 0 | O153: 0 | P153: 0 | Q153: =+O153+P153 -> 0 | R153: =+IF(Q153+N153<=0, "NO COMPRADOR", +IF(Q153<=0, "SIN COMPRA "&+UPPER(TEXT('DINAMICA ENERO 26'!$C$2,"mmm 'yy")), "COMPRADOR")) -> NO COMPRADOR
A154: Distribuidores | B154: Gastronomia | C154: DUARTE HERNAN | D154: 100031199 | E154: RAMIREZ ARIEL SEBASTIAN | F154: 100008613 | G154: AXIS LOGISTICA S.A. | H154: 0 | I154: 0 | J154: 0 | K154: 0 | L154: 0 | M154: 0 | N154: =+AVERAGE(K154:M154) -> 0 | O154: 0 | P154: 0 | Q154: 0 | R154: =+IF(Q154+N154<=0, "NO COMPRADOR", +IF(Q154<=0, "SIN COMPRA "&+UPPER(TEXT('DINAMICA ENERO 26'!$C$2,"mmm 'yy")), "COMPRADOR")) -> NO COMPRADOR
A155: Distribuidores | B155: Gastronomia | C155: DUARTE HERNAN | D155: 100031199 | E155: RAMIREZ ARIEL SEBASTIAN | F155: 100002250 | G155: RECATUME ADALBERTO OSCAR | H155: 0 | I155: 0 | J155: 0 | K155: 0 | L155: 57.6 | M155: 0 | N155: =+AVERAGE(K155:M155) -> 19.2 | O155: 0 | P155: 0 | Q155: =+O155+P155 -> 0 | R155: =+IF(Q155+N155<=0, "NO COMPRADOR", +IF(Q155<=0, "SIN COMPRA "&+UPPER(TEXT('DINAMICA ENERO 26'!$C$2,"mmm 'yy")), "COMPRADOR")) -> SIN COMPRA FEB '26
A156: Distribuidores | B156: Gastronomia | C156: DUARTE HERNAN | D156: 100031199 | E156: RAMIREZ ARIEL SEBASTIAN | F156: 100002229 | G156: PROMOFIESTA MAR DEL PLATA SRL | H156: 0 | I156: 0 | J156: 0 | K156: 0 | L156: 0 | M156: 0 | N156: =+AVERAGE(K156:M156) -> 0 | O156: 0 | P156: 0 | Q156: =+O156+P156 -> 0 | R156: =+IF(Q156+N156<=0, "NO COMPRADOR", +IF(Q156<=0, "SIN COMPRA "&+UPPER(TEXT('DINAMICA ENERO 26'!$C$2,"mmm 'yy")), "COMPRADOR")) -> NO COMPRADOR
A157: Distribuidores | B157: Gastronomia | C157: DUARTE HERNAN | D157: 100031199 | E157: RAMIREZ ARIEL SEBASTIAN | F157: 100022327 | G157: ROSARIO BURGUER SRL | H157: 0 | I157: 0 | J157: 0 | K157: 0 | L157: 0 | M157: 0 | N157: =+AVERAGE(K157:M157) -> 0 | O157: 0 | P157: 0 | Q157: =+O157+P157 -> 0 | R157: =+IF(Q157+N157<=0, "NO COMPRADOR", +IF(Q157<=0, "SIN COMPRA "&+UPPER(TEXT('DINAMICA ENERO 26'!$C$2,"mmm 'yy")), "COMPRADOR")) -> NO COMPRADOR
A158: Distribuidores | B158: Gastronomia | C158: DUARTE HERNAN | D158: 100031199 | E158: RAMIREZ ARIEL SEBASTIAN | F158: 100002225 | G158: PROMO FIESTA LA PLATA S.R.L. | H158: 0 | I158: 0 | J158: 0 | K158: 0 | L158: 0 | M158: 0 | N158: =+AVERAGE(K158:M158) -> 0 | O158: 0 | P158: 0 | Q158: =+O158+P158 -> 0 | R158: =+IF(Q158+N158<=0, "NO COMPRADOR", +IF(Q158<=0, "SIN COMPRA "&+UPPER(TEXT('DINAMICA ENERO 26'!$C$2,"mmm 'yy")), "COMPRADOR")) -> NO COMPRADOR
A159: Distribuidores | B159: Gastronomia | C159: DUARTE HERNAN | D159: 100031199 | E159: RAMIREZ ARIEL SEBASTIAN | F159: 100071477 | G159: PADRONE MONICA RAQUEL | H159: 0 | I159: 0 | J159: 0 | K159: 0 | L159: 0 | M159: 0 | N159: =+AVERAGE(K159:M159) -> 0 | O159: 0 | P159: 0 | Q159: =+O159+P159 -> 0 | R159: =+IF(Q159+N159<=0, "NO COMPRADOR", +IF(Q159<=0, "SIN COMPRA "&+UPPER(TEXT('DINAMICA ENERO 26'!$C$2,"mmm 'yy")), "COMPRADOR")) -> NO COMPRADOR
A160: Distribuidores | B160: Gastronomia | C160: DUARTE HERNAN | D160: 100031199 | E160: RAMIREZ ARIEL SEBASTIAN | F160: 100073868 | G160: VALDEZ MARIA ALEJANDRA | H160: 0 | I160: 0 | J160: 0 | K160: 0 | L160: 0 | M160: 0 | N160: =+AVERAGE(K160:M160) -> 0 | O160: 0 | P160: 0 | Q160: =+O160+P160 -> 0 | R160: =+IF(Q160+N160<=0, "NO COMPRADOR", +IF(Q160<=0, "SIN COMPRA "&+UPPER(TEXT('DINAMICA ENERO 26'!$C$2,"mmm 'yy")), "COMPRADOR")) -> NO COMPRADOR
A161: Distribuidores | B161: Gastronomia | C161: DUARTE HERNAN | D161: 100031199 | E161: RAMIREZ ARIEL SEBASTIAN | F161: 100040021 | G161: RAMIREZ NEYRA LUIS ALBERTO | H161: 0 | I161: 0 | J161: 0 | K161: 0 | L161: 0 | M161: 0 | N161: =+AVERAGE(K161:M161) -> 0 | O161: 0 | P161: 0 | Q161: =+O161+P161 -> 0 | R161: =+IF(Q161+N161<=0, "NO COMPRADOR", +IF(Q161<=0, "SIN COMPRA "&+UPPER(TEXT('DINAMICA ENERO 26'!$C$2,"mmm 'yy")), "COMPRADOR")) -> NO COMPRADOR
A162: Distribuidores | B162: Gastronomia | C162: DUARTE HERNAN | D162: 100031199 | E162: RAMIREZ ARIEL SEBASTIAN | F162: 100019451 | G162: PROMO BURGUER SRL | H162: 28.8 | I162: 9.6 | J162: 14.4 | K162: 0 | L162: 48 | M162: 0 | N162: =+AVERAGE(K162:M162) -> 16 | O162: 0 | P162: 0 | Q162: =+O162+P162 -> 0 | R162: =+IF(Q162+N162<=0, "NO COMPRADOR", +IF(Q162<=0, "SIN COMPRA "&+UPPER(TEXT('DINAMICA ENERO 26'!$C$2,"mmm 'yy")), "COMPRADOR")) -> SIN COMPRA FEB '26
A163: Distribuidores | B163: Gastronomia | C163: DUARTE HERNAN | D163: 100031199 | E163: RAMIREZ ARIEL SEBASTIAN | F163: 100066048 | G163: TIANI KARINA BEATRIZ | H163: 0 | I163: 0 | J163: 0 | K163: 0 | L163: 0 | M163: 0 | N163: =+AVERAGE(K163:M163) -> 0 | O163: 48 | P163: 0 | Q163: =+O163+P163 -> 48 | R163: =+IF(Q163+N163<=0, "NO COMPRADOR", +IF(Q163<=0, "SIN COMPRA "&+UPPER(TEXT('DINAMICA ENERO 26'!$C$2,"mmm 'yy")), "COMPRADOR")) -> COMPRADOR
A164: Distribuidores | B164: Gastronomia | C164: DUARTE HERNAN | D164: 100031199 | E164: RAMIREZ ARIEL SEBASTIAN | F164: 100086078 | G164: DISTRIBUIDORA BLANCALUNA S A | H164: 0 | I164: 0 | J164: 0 | K164: 0 | L164: 0 | M164: 0 | N164: =+AVERAGE(K164:M164) -> 0 | O164: 0 | P164: 0 | Q164: =+O164+P164 -> 0 | R164: =+IF(Q164+N164<=0, "NO COMPRADOR", +IF(Q164<=0, "SIN COMPRA "&+UPPER(TEXT('DINAMICA ENERO 26'!$C$2,"mmm 'yy")), "COMPRADOR")) -> NO COMPRADOR
A165: Distribuidores | B165: Gastronomia | C165: DUARTE HERNAN | D165: 100031199 | E165: RAMIREZ ARIEL SEBASTIAN | F165: 100089860 | G165: MR TASTY LOMAS S.A. | H165: 0 | I165: 0 | J165: 0 | K165: 0 | L165: 0 | M165: 0 | N165: =+AVERAGE(K165:M165) -> 0 | O165: 0 | P165: 0 | Q165: =+O165+P165 -> 0 | R165: =+IF(Q165+N165<=0, "NO COMPRADOR", +IF(Q165<=0, "SIN COMPRA "&+UPPER(TEXT('DINAMICA ENERO 26'!$C$2,"mmm 'yy")), "COMPRADOR")) -> NO COMPRADOR
A166: Distribuidores | B166: Litoral | C166: DALLA VERDE RAMON ADRIAN | D166: 100088690 | E166: FUNES ANDRES | F166: 100080700 | G166: SALINAS RUBEN ALBERTO | H166: 4.8 | I166: 0 | J166: 4.8 | K166: 0 | L166: 4.8 | M166: -4.8 | N166: =+AVERAGE(K166:M166) -> 0 | O166: 0 | P166: 0 | Q166: =+O166+P166 -> 0 | R166: =+IF(Q166+N166<=0, "NO COMPRADOR", +IF(Q166<=0, "SIN COMPRA "&+UPPER(TEXT('DINAMICA ENERO 26'!$C$2,"mmm 'yy")), "COMPRADOR")) -> NO COMPRADOR
... A327: Mayoristas | B327: Mayoristas | C327: ARUANNO PARODI MARIA NOEL | D327: 100087600 | E327: MENDEZ NAVARRO MARIA ALEJANDRA | F327: 100002545 | G327: SUPERMERCADOS MAYORISTAS MAKRO SA | H327: 9.6 | I327: 244.8 | J327: -72 | K327: 100.8 | L327: -19.2 | M327: 33.6 | N327: =+AVERAGE(K327:M327) -> 38.4 | O327: 0 | P327: 43.2 | Q327: =+O327+P327 -> 43.2 | R327: =+IF(Q327+N327<=0, "NO COMPRADOR", +IF(Q327<=0, "SIN COMPRA "&+UPPER(TEXT('DINAMICA ENERO 26'!$C$2,"mmm 'yy")), "COMPRADOR")) -> COMPRADOR
A328: Mayoristas | B328: Mayoristas | C328: ARUANNO PARODI MARIA NOEL | D328: 100087600 | E328: MENDEZ NAVARRO MARIA ALEJANDRA | F328: 100002424 | G328: SUPERMERCADOS MAY. YAGUAR S.A.
A329: Mayoristas | B329: Mayoristas | C329: ARUANNO PARODI MARIA NOEL | D329: 100087600 | E329: MENDEZ NAVARRO MARIA ALEJANDRA | F329: 100002055 | G329: MAYCAR S.A.
A330: Mayoristas | B330: Mayoristas | C330: ARUANNO PARODI MARIA NOEL | D330: 100087600 | E330: MENDEZ NAVARRO MARIA ALEJANDRA | F330: 100002054 | G330: MAXICONSUMO S.A. | H330: 14.4 | I330: -38.4 | J330: -4.8 | K330: 0 | L330: 1032 | M330: 345.6 | N330: =+AVERAGE(K330:M330) -> 459.2 | O330: 321.6 | P330: 0 | Q330: =+O330+P330 -> 321.6 | R330: =+IF(Q330+N330<=0, "NO COMPRADOR", +IF(Q330<=0, "SIN COMPRA "&+UPPER(TEXT('DINAMICA ENERO 26'!$C$2,"mmm/yy")), "COMPRADOR")) -> COMPRADOR
A331: Mayoristas | B331: Mayoristas | C331: ARUANNO PARODI MARIA NOEL | D331: 100087600 | E331: MENDEZ NAVARRO MARIA ALEJANDRA | F331: 100001241 | G331: AUTOSERVICIO MAY. DIARCO S.A.
A332: Cadenas | B332: GBA | C332: ARUANNO PARODI MARIA NOEL | D332: 100066387 | E332: RAMONDINO LEONARDO ERNESTO | F332: 100086833 | G332: DELIVERY HERO E-COMMERCE S. A. | H332: 0 | I332: 0 | J332: 0 | K332: 0 | L332: 0 | M332: 0 | N332: =+AVERAGE(K332:M332) -> 0 | O332: 0 | P332: 0 | Q332: =+O332+P332 -> 0 | R332: =+IF(Q332+N332<=0, "NO COMPRADOR", +IF(Q332<=0, "SIN COMPRA "&+UPPER(TEXT('DINAMICA ENERO 26'!$C$2,"mmm/yy")), "COMPRADOR")) -> NO COMPRADOR
A333: Cadenas | B333: DBU - BAS | C333: ARUANNO PARODI MARIA NOEL | D333: 100066387 | E333: RAMONDINO LEONARDO ERNESTO | F333: 100001434 | G333: COTO CENTRO INTEGRAL DE COMERCIALIZACON S A | H333: -374.4 | I333: 302.4 | J333: 168 | K333: 283.2 | L333: 153.6 | M333: 81.6 | N333: =+AVERAGE(K333:M333) -> 172.8 | O333: -4.8 | P333: 48 | Q333: =+O333+P333 -> 43.2 | R333: =+IF(Q333+N333<=0, "NO COMPRADOR", +IF(Q333<=0, "SIN COMPRA "&+UPPER(TEXT('DINAMICA ENERO 26'!$C$2,"mmm/yy")), "COMPRADOR")) -> COMPRADOR
A334: Cadenas | B334: DBU - BAS | C334: ARUANNO PARODI MARIA NOEL | D334: 100089882 | E334: BRION SEBASTIAN | F334: 100002273 | G334: S A IMPORTADORA Y EXPORTADORA DE LA PATAGONIA | H334: 0 | I334: 0 | J334: 0 | K334: 0 | L334: 0 | M334: 1209.6 | N334: =+AVERAGE(K334:M334) -> 403.2 | O334: 0 | P334: 0 | Q334: =+O334+P334 -> 0 | R334: =+IF(Q334+N334<=0, "NO COMPRADOR", +IF(Q334<=0, "SIN COMPRA "&+UPPER(TEXT('DINAMICA ENERO 26'!$C$2,"mmm/yy")), "COMPRADOR")) -> SIN COMPRA FEB/26
A335: Cadenas | B335: DBU - BAS | C335: ARUANNO PARODI MARIA NOEL | D335: 100002748 | E335: RODRIGUEZ JUDITH | F335: 100005896 | G335: INC SOCIEDAD ANONIMA | H335: 182.4 | I335: 129.6 | J335: 494.4 | K335: 211.2 | L335: 0 | M335: 0 | N335: =+AVERAGE(K335:M335) -> 70.4 | O335: 0 | P335: 0 | Q335: =+O335+P335 -> 0 | R335: =+IF(Q335+N335<=0, "NO COMPRADOR", +IF(Q335<=0, "SIN COMPRA "&+UPPER(TEXT('DINAMICA ENERO 26'!$C$2,"mmm/yy")), "COMPRADOR")) -> SIN COMPRA FEB/26
A336: Cadenas | B336: DBU - BAS | C336: ARUANNO PARODI MARIA NOEL | D336: 100002748 | E336: RODRIGUEZ JUDITH | F336: 100001550 | G336: DIA ARGENTINA S.A. | H336: 0 | I336: 0 | J336: 0 | K336: 0 | L336: 0 | M336: 0 | N336: =+AVERAGE(K336:M336) -> 0 | O336: 0 | P336: 0 | Q336: =+O336+P336 -> 0 | R336: =+IF(Q336+N336<=0, "NO COMPRADOR", +IF(Q336<=0, "SIN COMPRA "&+UPPER(TEXT('DINAMICA ENERO 26'!$C$2,"mmm/yy")), "COMPRADOR")) -> NO COMPRADOR
A337: Cadenas | B337: DBU - BAS | C337: ARUANNO PARODI MARIA NOEL | D337: 100089882 | E337: BRION SEBASTIAN | F337: 100002492 | G337: DORINKA S.R.L. | H337: 0 | I337: 0 | J337: 0 | K337: 0 | L337: 945.6 | M337: 0 | N337: =+AVERAGE(K337:M337) -> 315.2 | O337: 451.2 | P337: 984 | Q337: =+O337+P337 -> 1435.2 | R337: =+IF(Q337+N337<=0, "NO COMPRADOR", +IF(Q337<=0, "SIN COMPRA "&+UPPER(TEXT('DINAMICA ENERO 26'!$C$2,"mmm/yy")), "COMPRADOR")) -> COMPRADOR
A338: Cadenas | B338: DBU - BAS | C338: ARUANNO PARODI MARIA NOEL | D338: 100066387 | E338: RAMONDINO LEONARDO ERNESTO | F338: 100001342 | G338: CENCOSUD S A | H338: 0 | I338: 0 | J338: 0 | K338: 0 | L338: 0 | M338: 0 | N338: =+AVERAGE(K338:M338) -> 0 | O338: 0 | P338: 0 | Q338: =+O338+P338 -> 0 | R338: =+IF(Q338+N338<=0, "NO COMPRADOR", +IF(Q338<=0, "SIN COMPRA "&+UPPER(TEXT('DINAMICA ENERO 26'!$C$2,"mmm/yy")), "COMPRADOR")) -> NO COMPRADOR
...

Sheet Papas
A1: COMPRADORES PAPAS | S1: 100520902
A2: CANAL | B2: ZONA | C2: Jefe | D2: COD VENDEDOR | E2: NOM VENDEDOR | F2: COD CENTRALIZADOR | G2: NOM CENTRALIZADOR | H2: AGO '25 | I2: SEP 25 | J2: OCT 25 | K2: NOV '25 | L2: DIC '25 | M2: ENE '26 | N2: PROMEDIO ULT 3 MESES | O2: =+UPPER(TEXT('DINAMICA ENERO 26'!$C$2,"mmm 'yy"))&" FACT" -> FEB '26 FACT | P2: =+UPPER(TEXT('DINAMICA ENERO 26'!$C$2,"mmm 'yy"))&" PEND." -> FEB '26 PEND. | Q2: =+UPPER(TEXT('DINAMICA ENERO 26'!$C$2,"mmm 'yy"))&" TOTAL" -> FEB '26 TOTAL | R2: ESTADO
A3: Distribuidores | B3: Capital | C3: FEDERICO JACUM | D3: 100077477 | E3: VELAZQUEZ JONATAN WALTER | F3: 100086577 | G3: LOGISTICA Y DISTRIBUCION RIBAUDO HNOS S.A. | H3: 29.4 | I3: 0 | J3: 686 | K3: 49 | L3: 49 | M3: 0 | N3: =+AVERAGE(K3:M3) -> 32.666667 | O3: 0 | P3: 0 | Q3: =+O3+P3 -> 0 | R3: =+IF(Q3+N3<=0, "NO COMPRADOR", +IF(Q3<=0, "SIN COMPRA "&+UPPER(TEXT('DINAMICA ENERO 26'!$C$2,"mmm 'yy")), "COMPRADOR")) -> SIN COMPRA FEB '26
A4: Distribuidores | B4: Capital | C4: FEDERICO JACUM | D4: 100077477 | E4: VELAZQUEZ JONATAN WALTER | F4: 100065731 | G4: CINCUNEGUI MARCELO RODOLFO | H4: 0 | I4: 0 | J4: 0 | K4: 0 | L4: 0 | M4: 0 | N4: =+AVERAGE(K4:M4) -> 0 | O4: 0 | P4: 0 | Q4: =+O4+P4 -> 0 | R4: =+IF(Q4+N4<=0, "NO COMPRADOR", +IF(Q4<=0, "SIN COMPRA "&+UPPER(TEXT('DINAMICA ENERO 26'!$C$2,"mmm 'yy")), "COMPRADOR")) -> NO COMPRADOR
A5: Distribuidores | B5: Capital | C5: FEDERICO JACUM | D5: 100077477 | E5: VELAZQUEZ JONATAN WALTER | F5: 100010095 | G5: SUPERCONGELADOS FATIMA SOCIEDAD ANONIMA | H5: 0 | I5: 0 | J5: 0 | K5: 0 | L5: 0 | M5: 0 | N5: =+AVERAGE(K5:M5) -> 0 | O5: 0 | P5: 0 | Q5: =+O5+P5 -> 0 | R5: =+IF(Q5+N5<=0, "NO COMPRADOR", +IF(Q5<=0, "SIN COMPRA "&+UPPER(TEXT('DINAMICA ENERO 26'!$C$2,"mmm 'yy")), "COMPRADOR")) -> NO COMPRADOR
A6: Distribuidores | B6: Capital | C6: FEDERICO JACUM | D6: 100077477 | E6: VELAZQUEZ JONATAN WALTER | F6: 100079173 | G6: IQF DISTRIBUCION S.A. | H6: 392 | I6: 235.2 | J6: 156.8 | K6: 98 | L6: 980 | M6: 460.6 | N6: =+AVERAGE(K6:M6) -> 512.86667 | O6: 0 | P6: 196 | Q6: =+O6+P6 -> 196 | R6: =+IF(Q6+N6<=0, "NO COMPRADOR", +IF(Q6<=0, "SIN COMPRA "&+UPPER(TEXT('DINAMICA ENERO 26'!$C$2,"mmm 'yy")), "COMPRADOR")) -> COMPRADOR
A7: Distribuidores | B7: Capital | C7: FEDERICO JACUM | D7: 100077477 | E7: VELAZQUEZ JONATAN WALTER | F7: 100079594 | G7: DANIEL BUENO SAU | H7: 343 | I7: 196 | J7: 343 | K7: 196 | L7: 98 | M7: 392 | N7: =+AVERAGE(K7:M7) -> 228.66667 | O7: 0 | P7: 0 | Q7: =+O7+P7 -> 0 | R7: =+IF(Q7+N7<=0, "NO COMPRADOR", +IF(Q7<=0, "SIN COMPRA "&+UPPER(TEXT('DINAMICA ENERO 26'!$C$2,"mmm 'yy")), "COMPRADOR")) -> SIN COMPRA FEB '26
A8: Distribuidores | B8: Capital | C8: FEDERICO JACUM | D8: 100077477 | E8: VELAZQUEZ JONATAN WALTER | F8: 100078788 | G8: CAMPO DE SABORES S.A.S. | H8: 490 | I8: 460.6 | J8: 539 | K8: 343 | L8: 784 | M8: 588 | N8: =+AVERAGE(K8:M8) -> 571.66667 | O8: 588 | P8: 0 | Q8: =+O8+P8 -> 588 | R8: =+IF(Q8+N8<=0, "NO COMPRADOR", +IF(Q8<=0, "SIN COMPRA "&+UPPER(TEXT('DINAMICA ENERO 26'!$C$2,"mmm 'yy")), "COMPRADOR")) -> COMPRADOR
A9: Distribuidores | B9: Capital | C9: FEDERICO JACUM | D9: 100077477 | E9: VELAZQUEZ JONATAN WALTER | F9: 100084185 | G9: ADN DISTRIBUCION S.R.L. | H9: 0 | I9: 147 | J9: 245 | K9: 196 | L9: 147 | M9: 196 | N9: =+AVERAGE(K9:M9) -> 179.66667 | O9: 49 | P9: 0 | Q9: =+O9+P9 -> 49 | R9: =+IF(Q9+N9<=0, "NO COMPRADOR", +IF(Q9<=0, "SIN COMPRA "&+UPPER(TEXT('DINAMICA ENERO 26'!$C$2,"mmm 'yy")), "COMPRADOR")) -> COMPRADOR
A10: Distribuidores | B10: Capital | C10: FEDERICO JACUM | D10: 100077477 | E10: VELAZQUEZ JONATAN WALTER | F10: 100087922 | G10: FETECH INVESTMENTS S.A. | H10: 0 | I10: 0 | J10: 0 | K10: 0 | L10: 0 | M10: 0 | N10: =+AVERAGE(K10:M10) -> 0 | O10: 0 | P10: 0 | Q10: =+O10+P10 -> 0 | R10: =+IF(Q10+N10<=0, "NO COMPRADOR", +IF(Q10<=0, "SIN COMPRA "&+UPPER(TEXT('DINAMICA ENERO 26'!$C$2,"mmm 'yy")), "COMPRADOR")) -> NO COMPRADOR
A11: Distribuidores | B11: Capital | C11: FEDERICO JACUM | D11: 100077477 | E11: VELAZQUEZ JONATAN WALTER | F11: 100071741 | G11: BRIENZA DISTRIBUIDORA SOCIEDAD ANONIMA | H11: 0 | I11: 9.8 | J11: 0 | K11: 0 | L11: 0 | M11: 0 | N11: =+AVERAGE(K11:M11) -> 0 | O11: 0 | P11: 0 | Q11: =+O11+P11 -> 0 | R11: =+IF(Q11+N11<=0, "NO COMPRADOR", +IF(Q11<=0, "SIN COMPRA "&+UPPER(TEXT('DINAMICA ENERO 26'!$C$2,"mmm 'yy")), "COMPRADOR")) -> NO COMPRADOR
A12: Distribuidores | B12: Capital | C12: FEDERICO JACUM | D12: 100077477 | E12: VELAZQUEZ JONATAN WALTER | F12: 100075448 | G12: V&D LAS DOS MARIAS SRL | H12: 39.2 | I12: 19.6 | J12: 0 | K12: 0 | L12: 0 | M12: 0 | N12: =+AVERAGE(K12:M12) -> 0 | O12: 0 | P12: 0 | Q12: =+O12+P12 -> 0 | R12: =+IF(Q12+N12<=0, "NO COMPRADOR", +IF(Q12<=0, "SIN COMPRA "&+UPPER(TEXT('DINAMICA ENERO 26'!$C$2,"mmm 'yy")), "COMPRADOR")) -> NO COMPRADOR
A13: Distribuidores | B13: Capital | C13: FEDERICO JACUM | D13: 100077477 | E13: VELAZQUEZ JONATAN WALTER | F13: 100089232 | G13: DOBLE V DISTRIBUIDORES | H13: 0 | I13: 49 | J13: 9.8 | K13: 0 | L13: 0 | M13: 0 | N13: =+AVERAGE(K13:M13) -> 0 | O13: 0 | P13: 0 | Q13: =+O13+P13 -> 0 | R13: =+IF(Q13+N13<=0, "NO COMPRADOR", +IF(Q13<=0, "SIN COMPRA "&+UPPER(TEXT('DINAMICA ENERO 26'!$C$2,"mmm 'yy")), "COMPRADOR")) -> NO COMPRADOR
A14: Distribuidores | B14: GBA (Oeste) | C14: FEDERICO JACUM | D14: 100041217 | E14: TAPIA NERINA MARIELA | F14: 100073953 | G14: COMESTIBLES LUFAR SRL | H14: 0 | I14: 0 | J14: 0 | K14: 0 | L14: 0 | M14: 0 | N14: =+AVERAGE(K14:M14) -> 0 | O14: 0 | P14: 0 | Q14: =+O14+P14 -> 0 | R14: =+IF(Q14+N14<=0, "NO COMPRADOR", +IF(Q14<=0, "SIN COMPRA "&+UPPER(TEXT('DINAMICA ENERO 26'!$C$2,"mmm 'yy")), "COMPRADOR")) -> NO COMPRADOR
... A366: Distribuidores | B366: NEA | C366: DALLA VERDE RAMON ADRIAN | D366: 100075073 | E366: SANCHEZ JUAN CARLOS | F366: 100001336 | G366: CASA VELAZ SOCIEDAD DE RESPONSABILIDAD LIMITADA | H366: 0 | I366: 0 | J366: 0 | K366: 0 | L366: 0 | M366: 0 | N366: =+AVERAGE(K366:M366) -> 0 | O366: 0 | P366: 0 | Q366: =+O366+P366 -> 0 | R366: =+IF(Q366+N366<=0, "NO COMPRADOR", +IF(Q366<=0, "SIN COMPRA "&+UPPER(TEXT('DINAMICA ENERO 26'!$C$2,"mmm 'yy")), "COMPRADOR")) -> NO COMPRADOR

Sheet Veggies
A1: COMPRADORES VEGGIES | S1: 100521455 | T1: 100521457 | U1: 100521453 | V1: 100521454
A2: CANAL | B2: ZONA | C2: Jefe | D2: COD VENDEDOR | E2: NOM VENDEDOR | F2: COD CENTRALIZADOR | G2: NOM CENTRALIZADOR | H2: AGO 25 | I2: SEP 25 | J2: OCT 25 | K2: NOV '25 | L2: DIC '25 | M2: ENE '26 | N2: PROMEDIO ULT 3 MESES | O2: =+UPPER(TEXT('DINAMICA ENERO 26'!$C$2,"mmm 'yy"))&" FACT" -> FEB '26 FACT | P2: =+UPPER(TEXT('DINAMICA ENERO 26'!$C$2,"mmm 'yy"))&" PEND." -> FEB '26 PEND. | Q2: =+UPPER(TEXT('DINAMICA ENERO 26'!$C$2,"mmm 'yy"))&" TOTAL" -> FEB '26 TOTAL | R2: ESTADO
A3: Distribuidores | B3: Capital | C3: FEDERICO JACUM | D3: 100077477 | E3: VELAZQUEZ JONATAN WALTER | F3: 100086577 | G3: LOGISTICA Y DISTRIBUCION RIBAUDO HNOS S.A. | H3: 122.4 | I3: 20.4 | J3: 4.8 | K3: 20.4 | L3: 20.4 | M3: 0 | N3: =+AVERAGE(K3:M3) -> 13.6 | O3: 0 | P3: 0 | Q3: =+O3+P3 -> 0 | R3: =+IF(Q3+N3<=0, "NO COMPRADOR", +IF(Q3<=0, "SIN COMPRA "&+UPPER(TEXT('DINAMICA ENERO 26'!$C$2,"mmm 'yy")), "COMPRADOR")) -> SIN COMPRA FEB '26
A4: Distribuidores | B4: Capital | C4: FEDERICO JACUM | D4: 100077477 | E4: VELAZQUEZ JONATAN WALTER | F4: 100065731 | G4: CINCUNEGUI MARCELO RODOLFO | H4: 0 | I4: 0 | J4: 0 | K4: 0 | L4: 0 | M4: 0 | N4: =+AVERAGE(K4:M4) -> 0 | O4: 0 | P4: 0 | Q4: =+O4+P4 -> 0 | R4: =+IF(Q4+N4<=0, "NO COMPRADOR", +IF(Q4<=0, "SIN COMPRA "&+UPPER(TEXT('DINAMICA ENERO 26'!$C$2,"mmm 'yy")), "COMPRADOR")) -> NO COMPRADOR
A5: Distribuidores | B5: Capital | C5: FEDERICO JACUM | D5: 100077477 | E5: VELAZQUEZ JONATAN WALTER | F5: 100010095 | G5: SUPERCONGELADOS FATIMA SOCIEDAD ANONIMA | H5: 4.8 | I5: 0 | J5: 0 | K5: 15 | L5: 0 | M5: 9.6 | N5: =+AVERAGE(K5:M5) -> 8.2 | O5: 15 | P5: 0 | Q5: =+O5+P5 -> 15 | R5: =+IF(Q5+N5<=0, "NO COMPRADOR", +IF(Q5<=0, "SIN COMPRA "&+UPPER(TEXT('DINAMICA ENERO 26'!$C$2,"mmm 'yy")), "COMPRADOR")) -> COMPRADOR
A6: Distribuidores | B6: Capital | C6: FEDERICO JACUM | D6: 100077477 | E6: VELAZQUEZ JONATAN WALTER | F6: 100079173 | G6: IQF DISTRIBUCION S.A. | H6: 27 | I6: 24 | J6: 48 | K6: 0 | L6: 115.2 | M6: 9.6 | N6: =+AVERAGE(K6:M6) -> 41.6 | O6: 0 | P6: 0 | Q6: =+O6+P6 -> 0 | R6: =+IF(Q6+N6<=0, "NO COMPRADOR", +IF(Q6<=0, "SIN COMPRA "&+UPPER(TEXT('DINAMICA ENERO 26'!$C$2,"mmm 'yy")), "COMPRADOR")) -> SIN COMPRA FEB '26
A7: Distribuidores | B7: Capital | C7: FEDERICO JACUM | D7: 100077477 | E7: VELAZQUEZ JONATAN WALTER | F7: 100079594 | G7: DANIEL BUENO SAU | H7: 30 | I7: 0 | J7: 10.2 | K7: 5.4 | L7: 4.8 | M7: 10.2 | N7: =+AVERAGE(K7:M7) -> 6.8 | O7: 0 | P7: 0 | Q7: =+O7+P7 -> 0 | R7: =+IF(Q7+N7<=0, "NO COMPRADOR", +IF(Q7<=0, "SIN COMPRA "&+UPPER(TEXT('DINAMICA ENERO 26'!$C$2,"mmm 'yy")), "COMPRADOR")) -> SIN COMPRA FEB '26
A8: Distribuidores | B8: Capital | C8: FEDERICO JACUM | D8: 100077477 | E8: VELAZQUEZ JONATAN WALTER | F8: 100078788 | G8: CAMPO DE SABORES S.A.S. | H8: 0 | I8: 115.2 | J8: 0 | K8: 21.6 | L8: 33.6 | M8: 99.6 | N8: =+AVERAGE(K8:M8) -> 51.6 | O8: 33.6 | P8: 0 | Q8: =+O8+P8 -> 33.6 | R8: =+IF(Q8+N8<=0, "NO COMPRADOR", +IF(Q8<=0, "SIN COMPRA "&+UPPER(TEXT('DINAMICA ENERO 26'!$C$2,"mmm 'yy")), "COMPRADOR")) -> COMPRADOR
A9: Distribuidores | B9: Capital | C9: FEDERICO JACUM | D9: 100077477 | E9: VELAZQUEZ JONATAN WALTER | F9: 100084185 | G9: ADN DISTRIBUCION S.R.L. | H9: 5.4 | I9: 19.8 | J9: 0 | K9: 40.8 | L9: 5.4 | M9: 10.8 | N9: =+AVERAGE(K9:M9) -> 19 | O9: 19.2 | P9: 0 | Q9: =+O9+P9 -> 19.2 | R9: =+IF(Q9+N9<=0, "NO COMPRADOR", +IF(Q9<=0, "SIN COMPRA "&+UPPER(TEXT('DINAMICA ENERO 26'!$C$2,"mmm 'yy")), "COMPRADOR")) -> COMPRADOR
A10: Distribuidores | B10: Capital | C10: FEDERICO JACUM | D10: 100077477 | E10: VELAZQUEZ JONATAN WALTER | F10: 100087922 | G10: FETECH INVESTMENTS S.A. | H10: 0 | I10: 0 | J10: 0 | K10: 0 | L10: 0 | M10: 0 | N10: =+AVERAGE(K10:M10) -> 0 | O10: 0 | P10: 0 | Q10: =+O10+P10 -> 0 | R10: =+IF(Q10+N10<=0, "NO COMPRADOR", +IF(Q10<=0, "SIN COMPRA "&+UPPER(TEXT('DINAMICA ENERO 26'!$C$2,"mmm 'yy")), "COMPRADOR")) -> NO COMPRADOR
A11: Distribuidores | B11: Capital | C11: FEDERICO JACUM | D11: 100077477 | E11: VELAZQUEZ JONATAN WALTER | F11: 100071741 | G11: BRIENZA DISTRIBUIDORA SOCIEDAD ANONIMA | H11: 0 | I11: 5.4 | J11: 4.8 | K11: 15 | L11: 5.4 | M11: 0 | N11: =+AVERAGE(K11:M11) -> 6.8 | O11: 9.6 | P11: 0 | Q11: =+O11+P11 -> 9.6 | R11: =+IF(Q11+N11<=0, "NO COMPRADOR", +IF(Q11<=0, "SIN COMPRA "&+UPPER(TEXT('DINAMICA ENERO 26'!$C$2,"mmm 'yy")), "COMPRADOR")) -> COMPRADOR
A12: Distribuidores | B12: Capital | C12: FEDERICO JACUM | D12: 100077477 | E12: VELAZQUEZ JONATAN WALTER | F12: 100075448 | G12: V&D LAS DOS MARIAS SRL | H12: 51.6 | I12: 15 | J12: 15 | K12: 10.8 | L12: 0 | M12: 0 | N12: =+AVERAGE(K12:M12) -> 3.6 | O12: 0 | P12: 0 | Q12: =+O12+P12 -> 0 | R12: =+IF(Q12+N12<=0, "NO COMPRADOR", +IF(Q12<=0, "SIN COMPRA "&+UPPER(TEXT('DINAMICA ENERO 26'!$C$2,"mmm 'yy")), "COMPRADOR")) -> SIN COMPRA FEB '26
A13: Distribuidores | B13: Capital | C13: FEDERICO JACUM | D13: 100077477 | E13: VELAZQUEZ JONATAN WALTER | F13: 100089232 | G13: DOBLE V DISTRIBUIDORES | H13: 0 | I13: 0 | J13: 0 | K13: 0 | L13: 0 | M13: 0 | N13: =+AVERAGE(K13:M13) -> 0 | O13: 0 | P13: 0 | Q13: =+O13+P13 -> 0 | R13: =+IF(Q13+N13<=0, "NO COMPRADOR", +IF(Q13<=0, "SIN COMPRA "&+UPPER(TEXT('DINAMICA ENERO 26'!$C$2,"mmm 'yy")), "COMPRADOR")) -> NO COMPRADOR
A14: Distribuidores | B14: GBA (Oeste) | C14: FEDERICO JACUM | D14: 100041217 | E14: TAPIA NERINA MARIELA | F14: 100073953 | G14: COMESTIBLES LUFAR SRL | H14: 0 | I14: 0 | J14: 0 | K14: 0 | L14: 0 | M14: 0 | N14: =+AVERAGE(K14:M14) -> 0 | O14: 0 | P14: 0 | Q14: =+O14+P14 -> 0 | R14: =+IF(Q14+N14<=0, "NO COMPRADOR", +IF(Q14<=0, "SIN COMPRA "&+UPPER(TEXT('DINAMICA ENERO 26'!$C$2,"mmm 'yy")), "COMPRADOR")) -> NO COMPRADOR
... A366: Distribuidores | B366: NEA | C366: DALLA VERDE RAMON ADRIAN | D366: 100075073 | E366: SANCHEZ JUAN CARLOS | F366: 100001336 | G366: CASA VELAZ SOCIEDAD DE RESPONSABILIDAD LIMITADA | H366: 0 | I366: 0 | J366: 0 | K366: 0 | L366: 0 | M366: 0 | N366: =+AVERAGE(K366:M366) -> 0 | O366: 0 | P366: 0 | Q366: =+O366+P366 -> 0 | R366: =+IF(Q366+N366<=0, "NO COMPRADOR", +IF(Q366<=0, "SIN COMPRA "&+UPPER(TEXT('DINAMICA ENERO 26'!$C$2,"mmm 'yy")), "COMPRADOR")) -> NO COMPRADOR

Sheet Untables
A1: COMPRADORES NUEVOS LANZAMIENTOS RB | S1: OCT '25 | U1: NOV 25 | W1: DIC 25 | Y1: ENE 25 | AA1: PROMEDIO | AD1: CHILE CHIPOTLE (522277) | AG1: JALAPEÑO (522333) | AL1: 100522277 | AM1: 100522333
A2: CANAL | B2: ZONA | C2: Jefe | D2: COD VENDEDOR | E2: NOM VENDEDOR | F2: COD CENTRALIZADOR | G2: NOM CENTRALIZADOR | S2: CHILE CHIPOTLE (522277) | T2: JALAPEÑO (522333) | U2: CHILE CHIPOTLE (522277) | V2: JALAPEÑO (522333) | W2: CHILE CHIPOTLE (522277) | X2: JALAPEÑO (522333) | Y2: CHILE CHIPOTLE (522277) | Z2: JALAPEÑO (522333) | AA2: CHILE CHIPOTLE (522277) | AB2: JALAPEÑO (522333) | AD2: =+UPPER(TEXT('DINAMICA ENERO 26'!$C$2,"mmm 'yy"))&" FACT" -> FEB '26 FACT | AE2: =+UPPER(TEXT('DINAMICA ENERO 26'!$C$2,"mmm 'yy"))&" PEND." -> FEB '26 PEND. | AF2: =+UPPER(TEXT('DINAMICA ENERO 26'!$C$2,"mmm 'yy"))&" TOTAL" -> FEB '26 TOTAL | AG2: =+UPPER(TEXT('DINAMICA ENERO 26'!$C$2,"mmm 'yy"))&" FACT" -> FEB '26 FACT | AH2: =+UPPER(TEXT('DINAMICA ENERO 26'!$C$2,"mmm 'yy"))&" PEND." -> FEB '26 PEND. | AI2: =+UPPER(TEXT('DINAMICA ENERO 26'!$C$2,"mmm 'yy"))&" TOTAL" -> FEB '26 TOTAL | AJ2: TOTAL | AK2: ESTADO
A3: Distribuidores | B3: Capital | C3: FEDERICO JACUM | D3: 100077477 | E3: VELAZQUEZ JONATAN WALTER | F3: 100086577 | G3: LOGISTICA Y DISTRIBUCION RIBAUDO HNOS S.A. | S3: 86.4 | T3: 86.4 | U3: 86.4 | V3: 86.4 | W3: 86.4 | X3: 86.4 | Y3: 0 | Z3: 0 | AA3: =+AVERAGE(U3,W3,Y3) -> 57.6 | AB3: =+AVERAGE(V3,X3,Z3) -> 57.6 | AD3: 0 | AE3: 0 | AF3: =+AD3+AE3 -> 0 | AG3: 0 | AH3: 0 | AI3: =+AG3+AH3 -> 0 | AJ3: =+AF3+AI3 -> 0 | AK3: =+IF(AB3+AA3+AJ3<=0, "NO COMPRADOR", +IF(AJ3<=0, "SIN COMPRA "&+UPPER(TEXT('DINAMICA ENERO 26'!$C$2,"mmm 'yy")), "COMPRADOR")) -> SIN COMPRA FEB '26
A4: Distribuidores | B4: Capital | C4: FEDERICO JACUM | D4: 100077477 | E4: VELAZQUEZ JONATAN WALTER | F4: 100065731 | G4: CINCUNEGUI MARCELO RODOLFO | S4: 0 | T4: 0 | U4: 0 | V4: 0 | W4: 0 | X4: 0 | Y4: 0 | Z4: 0 | AA4: =+AVERAGE(U4,W4,Y4) -> 0 | AB4: =+AVERAGE(V4,X4,Z4) -> 0 | AD4: 0 | AE4: 0 | AF4: =+AD4+AE4 -> 0 | AG4: 0 | AH4: 0 | AI4: =+AG4+AH4 -> 0 | AJ4: =+AF4+AI4 -> 0 | AK4: =+IF(AB4+AA4+AJ4<=0, "NO COMPRADOR", +IF(AJ4<=0, "SIN COMPRA "&+UPPER(TEXT('DINAMICA ENERO 26'!$C$2,"mmm 'yy")), "COMPRADOR")) -> NO COMPRADOR
A5: Distribuidores | B5: Capital | C5: FEDERICO JACUM | D5: 100077477 | E5: VELAZQUEZ JONATAN WALTER | F5: 100010095 | G5: SUPERCONGELADOS FATIMA SOCIEDAD ANONIMA | S5: 0 | T5: 0 | U5: 0 | V5: 0 | W5: 2.16 | X5: 2.16 | Y5: 0 | Z5: 0 | AA5: =+AVERAGE(U5,W5,Y5) -> 0.72 | AB5: =+AVERAGE(V5,X5,Z5) -> 0.72 | AD5: 0 | AE5: 0 | AF5: =+AD5+AE5 -> 0 | AG5: 0 | AH5: 0 | AI5: =+AG5+AH5 -> 0 | AJ5: =+AF5+AI5 -> 0 | AK5: =+IF(AB5+AA5+AJ5<=0, "NO COMPRADOR", +IF(AJ5<=0, "SIN COMPRA "&+UPPER(TEXT('DINAMICA ENERO 26'!$C$2,"mmm 'yy")), "COMPRADOR")) -> SIN COMPRA FEB '26
A6: Distribuidores | B6: Capital | C6: FEDERICO JACUM | D6: 100077477 | E6: VELAZQUEZ JONATAN WALTER | F6: 100079173 | G6: IQF DISTRIBUCION S.A. | S6: 43.2 | T6: 43.2 | U6: 116.64 | V6: 116.64 | W6: 99.36 | X6: 54 | Y6: 0 | Z6: 43.2 | AA6: =+AVERAGE(U6,W6,Y6) -> 72 | AB6: =+AVERAGE(V6,X6,Z6) -> 71.28 | AD6: 0 | AE6: 10.8 | AF6: =+AD6+AE6 -> 10.8 | AG6: 64.8 | AH6: 0 | AI6: =+AG6+AH6 -> 64.8 | AJ6: =+AF6+AI6 -> 75.6 | AK6: =+IF(AB6+AA6+AJ6<=0, "NO COMPRADOR", +IF(AJ6<=0, "SIN COMPRA "&+UPPER(TEXT('DINAMICA ENERO 26'!$C$2,"mmm 'yy")), "COMPRADOR")) -> COMPRADOR
A7: Distribuidores | B7: Capital | C7: FEDERICO JACUM | D7: 100077477 | E7: VELAZQUEZ JONATAN WALTER | F7: 100079594 | G7: DANIEL BUENO SAU | S7: 388.8 | T7: 388.8 | U7: 216 | V7: 216 | W7: 0 | X7: 0 | Y7: 0 | Z7: 0 | AA7: =+AVERAGE(U7,W7,Y7) -> 72 | AB7: =+AVERAGE(V7,X7,Z7) -> 72 | AD7: 0 | AE7: 0 | AF7: =+AD7+AE7 -> 0 | AG7: 0 | AH7: 0 | AI7: =+AG7+AH7 -> 0 | AJ7: =+AF7+AI7 -> 0 | AK7: =+IF(AB7+AA7+AJ7<=0, "NO COMPRADOR", +IF(AJ7<=0, "SIN COMPRA "&+UPPER(TEXT('DINAMICA ENERO 26'!$C$2,"mmm 'yy")), "COMPRADOR")) -> SIN COMPRA FEB '26
A8: Distribuidores | B8: Capital | C8: FEDERICO JACUM | D8: 100077477 | E8: VELAZQUEZ JONATAN WALTER | F8: 100078788 | G8: CAMPO DE SABORES S.A.S. | S8: 108 | T8: 108 | U8: 367.2 | V8: 367.2 | W8: 302.4 | X8: 302.4 | Y8: 118.8 | Z8: 118.8 | AA8: =+AVERAGE(U8,W8,Y8) -> 262.8 | AB8: =+AVERAGE(V8,X8,Z8) -> 262.8 | AD8: 43.2 | AE8: 0 | AF8: =+AD8+AE8 -> 43.2 | AG8: 86.4 | AH8: 0 | AI8: =+AG8+AH8 -> 86.4 | AJ8: =+AF8+AI8 -> 129.6 | AK8: =+IF(AB8+AA8+AJ8<=0, "NO COMPRADOR", +IF(AJ8<=0, "SIN COMPRA "&+UPPER(TEXT('DINAMICA ENERO 26'!$C$2,"mmm 'yy")), "COMPRADOR")) -> COMPRADOR
A9: Distribuidores | B9: Capital | C9: FEDERICO JACUM | D9: 100077477 | E9: VELAZQUEZ JONATAN WALTER | F9: 100084185 | G9: ADN DISTRIBUCION S.R.L. | S9: 0 | T9: 0 | U9: 0 | V9: 0 | W9: 21.6 | X9: 21.6 | Y9: 32.4 | Z9: 32.4 | AA9: =+AVERAGE(U9,W9,Y9) -> 18 | AB9: =+AVERAGE(V9,X9,Z9) -> 18 | AD9: 10.8 | AE9: 0 | AF9: =+AD9+AE9 -> 10.8 | AG9: 10.8 | AH9: 0 | AI9: =+AG9+AH9 -> 10.8 | AJ9: =+AF9+AI9 -> 21.6 | AK9: =+IF(AB9+AA9+AJ9<=0, "NO COMPRADOR", +IF(AJ9<=0, "SIN COMPRA "&+UPPER(TEXT('DINAMICA ENERO 26'!$C$2,"mmm 'yy")), "COMPRADOR")) -> COMPRADOR
A10: Distribuidores | B10: Capital | C10: FEDERICO JACUM | D10: 100077477 | E10: VELAZQUEZ JONATAN WALTER | F10: 100087922 | G10: FETECH INVESTMENTS S.A. | S10: 0 | T10: 0 | U10: 0 | V10: 0 | W10: 0 | X10: 0 | Y10: 0 | Z10: 0 | AA10: =+AVERAGE(U10,W10,Y10) -> 0 | AB10: =+AVERAGE(V10,X10,Z10) -> 0 | AD10: 0 | AE10: 0 | AF10: =+AD10+AE10 -> 0 | AG10: 0 | AH10: 0 | AI10: =+AG10+AH10 -> 0 | AJ10: =+AF10+AI10 -> 0 | AK10: =+IF(AB10+AA10+AJ10<=0, "NO COMPRADOR", +IF(AJ10<=0, "SIN COMPRA "&+UPPER(TEXT('DINAMICA ENERO 26'!$C$2,"mmm 'yy")), "COMPRADOR")) -> NO COMPRADOR
A11: Distribuidores | B11: Capital | C11: FEDERICO JACUM | D11: 100077477 | E11: VELAZQUEZ JONATAN WALTER | F11: 100071741 | G11: BRIENZA DISTRIBUIDORA SOCIEDAD ANONIMA | S11: 0 | T11: 0 | U11: 2.16 | V11: 2.16 | W11: 2.16 | X11: 2.16 | Y11: 0 | Z11: 2.16 | AA11: =+AVERAGE(U11,W11,Y11) -> 1.44 | AB11: =+AVERAGE(V11,X11,Z11) -> 2.16 | AD11: 2.16 | AE11: 0 | AF11: =+AD11+AE11 -> 2.16 | AG11: 4.32 | AH11: 0 | AI11: =+AG11+AH11 -> 4.32 | AJ11: =+AF11+AI11 -> 6.48 | AK11: =+IF(AB11+AA11+AJ11<=0, "NO COMPRADOR", +IF(AJ11<=0, "SIN COMPRA "&+UPPER(TEXT('DINAMICA ENERO 26'!$C$2,"mmm 'yy")), "COMPRADOR")) -> COMPRADOR
A12: Distribuidores | B12: Capital | C12: FEDERICO JACUM | D12: 100077477 | E12: VELAZQUEZ JONATAN WALTER | F12: 100075448 | G12: V&D LAS DOS MARIAS SRL | S12: 4.32 | T12: 4.32 | U12: 30.24 | V12: 30.24 | W12: 21.6 | X12: 21.6 | Y12: 0 | Z12: 0 | AA12: =+AVERAGE(U12,W12,Y12) -> 17.28 | AB12: =+AVERAGE(V12,X12,Z12) -> 17.28 | AD12: 0 | AE12: 0 | AF12: =+AD12+AE12 -> 0 | AG12: 0 | AH12: 0 | AI12: =+AG12+AH12 -> 0 | AJ12: =+AF12+AI12 -> 0 | AK12: =+IF(AB12+AA12+AJ12<=0, "NO COMPRADOR", +IF(AJ12<=0, "SIN COMPRA "&+UPPER(TEXT('DINAMICA ENERO 26'!$C$2,"mmm 'yy")), "COMPRADOR")) -> SIN COMPRA FEB '26
A13: Distribuidores | B13: Capital | C13: FEDERICO JACUM | D13: 100077477 | E13: VELAZQUEZ JONATAN WALTER | F13: 100089232 | G13: DOBLE V DISTRIBUIDORES | S13: 0 | T13: 0 | U13: 0 | V13: 0 | W13: 0 | X13: 0 | Y13: 0 | Z13: 0 | AA13: =+AVERAGE(U13,W13,Y13) -> 0 | AB13: =+AVERAGE(V13,X13,Z13) -> 0 | AD13: 0 | AE13: 0 | AF13: =+AD13+AE13 -> 0 | AG13: 0 | AH13: 0 | AI13: =+AG13+AH13 -> 0 | AJ13: =+AF13+AI13 -> 0 | AK13: =+IF(AB13+AA13+AJ13<=0, "NO COMPRADOR", +IF(AJ13<=0, "SIN COMPRA "&+UPPER(TEXT('DINAMICA ENERO 26'!$C$2,"mmm 'yy")), "COMPRADOR")) -> NO COMPRADOR
A14: Distribuidores | B14: GBA (Oeste) | C14: FEDERICO JACUM | D14: 100041217 | E14: TAPIA NERINA MARIELA | F14: 100073953 | G14: COMESTIBLES LUFAR SRL | S14: 0 | T14: 0 | U14: 0 | V14: 0 | W14: 0 | X14: 0 | Y14: 0 | Z14: 0 | AA14: =+AVERAGE(U14,W14,Y14) -> 0 | AB14: =+AVERAGE(V14,X14,Z14) -> 0 | AD14: 0 | AE14: 0 | AF14: =+AD14+AE14 -> 0 | AG14: 0 | AH14: 0 | AI14: =+AG14+AH14 -> 0 | AJ14: =+AF14+AI14 -> 0 | AK14: =+IF(AB14+AA14+AJ14<=0, "NO COMPRADOR", +IF(AJ14<=0, "SIN COMPRA "&+UPPER(TEXT('DINAMICA ENERO 26'!$C$2,"mmm 'yy")), "COMPRADOR")) -> NO COMPRADOR
... A22: Distribuidores | B22: GBA (Sur) | C22: FEDERICO JACUM | D22: 100080146 | E22: VINCZE CINTIA LORENA | F22: 100001763 | G22: FORCINITTI DISTRIBUIDORA S.A. | S22: 64.8 | T22: 43.2 | U22: 54 | V22: 54 | W22: 10.8 | X22: 10.8 | Y22: 43.2 | Z22: 43.2 | AA22: =+AVERAGE(U22,W22,Y22) -> 36 | AB22: =+AVERAGE(V22,X22,Z22) -> 36 | AD22: 0 | AE22: 0 | AF22: =+AD22+AE22 -> 0 | AG22: 0 | AH22: 0 | AI22: =+AG22+AH22 -> 0 | AJ22: =+AF22+AI22 -> 0 | AK22: =+IF(AB22+AA22+AJ22<=0, "NO COMPRADOR", +IF(AJ22<=0, "SIN COMPRA "&+UPPER(TEXT('DINAMICA ENERO 26'!$C$2,"mmm 'yy")), "COMPRADOR")) -> SIN COMPRA FEB '26
A23: Distribuidores | B23: GBA (Sur) | C23: FEDERICO JACUM | D23: 100080146 | E23: VINCZE CINTIA LORENA | F23: 100025425 | G23: REALES AGRUPACION DE COLABORACION EMPRESARIA | H23: 0 | I23: 0 | J23: 0 | K23: 0 | S23: 0 | T23: 0 | U23: 0 | V23: 0 | W23: 64.8 | X23: 64.8 | Y23: 8.64 | Z23: 2.16 | AA23: =+AVERAGE(U23,W23,Y23) -> 24.48 | AB23: =+AVERAGE(V23,X23,Z23) -> 22.32 | AD23: 0 | AE23: 0 | AF23: =+AD23+AE23 -> 0 | AG23: 0 | AH23: 0 | AI23: =+AG23+AH23 -> 0 | AJ23: =+AF23+AI23 -> 0 | AK23: =+IF(AB23+AA23+AJ23<=0, "NO COMPRADOR", +IF(AJ23<=0, "SIN COMPRA "&+UPPER(TEXT('DINAMICA ENERO 26'!$C$2,"mmm 'yy")), "COMPRADOR")) -> SIN COMPRA FEB '26
A24: Distribuidores | B24: GBA (Sur) | C24: FEDERICO JACUM | D24: 100068884 | E24: GOMEZ OURAL ALBERTO | F24: 100079808 | G24: SATIMA S.R.L | S24: 129.6 | T24: 129.6 | U24: 162 | V24: 162 | W24: 151.2 | X24: 151.2 | Y24: 0 | Z24: 0 | AA24: =+AVERAGE(U24,W24,Y24) -> 104.4 | AB24: =+AVERAGE(V24,X24,Z24) -> 104.4 | AD24: 0 | AE24: 0 | AF24: =+AD24+AE24 -> 0 | AG24: 0 | AH24: 0 | AI24: =+AG24+AH24 -> 0 | AJ24: =+AF24+AI24 -> 0 | AK24: =+IF(AB24+AA24+AJ24<=0, "NO COMPRADOR", +IF(AJ24<=0, "SIN COMPRA "&+UPPER(TEXT('DINAMICA ENERO 26'!$C$2,"mmm 'yy")), "COMPRADOR")) -> SIN COMPRA FEB '26
A25: Distribuidores | B25: GBA (Sur) | C25: FEDERICO JACUM | D25: 100068884 | E25: GOMEZ OURAL ALBERTO | F25: 100069053 | G25: BORATI SA | S25: 51.84 | T25: 51.84 | U25: 0 | V25: 0 | W25: 0 | X25: 0 | Y25: 64.8 | Z25: 0 | AA25: =+AVERAGE(U25,W25,Y25) -> 21.6 | AB25: =+AVERAGE(V25,X25,Z25) -> 0 | AD25: 0 | AE25: 0 | AF25: =+AD25+AE25 -> 0 | AG25: 0 | AH25: 0 | AI25: =+AG25+AH25 -> 0 | AJ25: =+AF25+AI25 -> 0 | AK25: =+IF(AB25+AA25+AJ25<=0, "NO COMPRADOR", +IF(AJ25<=0, "SIN COMPRA "&+UPPER(TEXT('DINAMICA ENERO 26'!$C$2,"mmm 'yy")), "COMPRADOR")) -> SIN COMPRA FEB '26
A26: Distribuidores | B26: GBA (Sur) | C26: FEDERICO JACUM | D26: 100068884 | E26: GOMEZ OURAL ALBERTO | F26: 100061654 | G26: RICARDO BLANCO E HIJOS S R L | S26: 0 | T26: 0 | U26: 108 | V26: 108 | W26: 64.8 | X26: 64.8 | Y26: 0 | Z26: 64.8 | AA26: =+AVERAGE(U26,W26,Y26) -> 57.6 | AB26: =+AVERAGE(V26,X26,Z26) -> 79.2 | AD26: 0 | AE26: 0 | AF26: =+AD26+AE26 -> 0 | AG26: 0 | AH26: 0 | AI26: =+AG26+AH26 -> 0 | AJ26: =+AF26+AI26 -> 0 | AK26: =+IF(AB26+AA26+AJ26<=0, "NO COMPRADOR", +IF(AJ26<=0, "SIN COMPRA "&+UPPER(TEXT('DINAMICA ENERO 26'!$C$2,"mmm 'yy")), "COMPRADOR")) -> SIN COMPRA FEB '26
A27: Distribuidores | B27: COSTA | C27: FEDERICO JACUM | D27: 100088165 | E27: MARTINO FLAVIO | F27: 100000073 | G27: MAIOLO S.R.L. | S27: 30.24 | T27: 30.24 | U27: 34.56 | V27: 64.8 | W27: 2.16 | X27: 2.16 | Y27: 64.8 | Z27: 86.4 | AA27: =+AVERAGE(U27,W27,Y27) -> 33.84 | AB27: =+AVERAGE(V27,X27,Z27) -> 51.12 | AD27: 0 | AE27: 0 | AF27: =+AD27+AE27 -> 0 | AG27: 0 | AH27: 0 | AI27: =+AG27+AH27 -> 0 | AJ27: =+AF27+AI27 -> 0 | AK27: =+IF(AB27+AA27+AJ27<=0, "NO COMPRADOR", +IF(AJ27<=0, "SIN COMPRA "&+UPPER(TEXT('DINAMICA ENERO 26'!$C$2,"mmm 'yy")), "COMPRADOR")) -> SIN COMPRA FEB '26
A28: Distribuidores | B28: COSTA | C28: FEDERICO JACUM | D28: 100088165 | E28: MARTINO FLAVIO | F28: 100078580 | G28: DASAJU DISTRIBUIDORA S.A | S28: 21.6 | T28: 21.6 | U28: 21.6 | V28: 21.6 | W28: 0 | X28: 0 | Y28: 0 | Z28: 2.16 | AA28: =+AVERAGE(U28,W28,Y28) -> 7.2 | AB28: =+AVERAGE(V28,X28,Z28) -> 7.92 | AD28: 0 | AE28: 0 | AF28: =+AD28+AE28 -> 0 | AG28: 0 | AH28: 0 | AI28: =+AG28+AH28 -> 0 | AJ28: =+AF28+AI28 -> 0 | AK28: =+IF(AB28+AA28+AJ28<=0, "NO COMPRADOR", +IF(AJ28<=0, "SIN COMPRA "&+UPPER(TEXT('DINAMICA ENERO 26'!$C$2,"mmm 'yy")), "COMPRADOR")) -> SIN COMPRA FEB '26
A29: Distribuidores | B29: COSTA | C29: FEDERICO JACUM | D29: 100088165 | E29: MARTINO FLAVIO | F29: 100080926 | G29: DEANCAR SERVICIOS SA | S29: 21.6 | T29: 21.6 | U29: 43.2 | V29: 43.2 | W29: 0 | X29: 0 | Y29: 86.4 | Z29: 86.4 | AA29: =+AVERAGE(U29,W29,Y29) -> 43.2 | AB29: =+AVERAGE(V29,X29,Z29) -> 43.2 | AD29: 0 | AE29: 0 | AF29: =+AD29+AE29 -> 0 | AG29: 64.8 | AH29: 0 | AI29: =+AG29+AH29 -> 64.8 | AJ29: =+AF29+AI29 -> 64.8 | AK29: =+IF(AB29+AA29+AJ29<=0, "NO COMPRADOR", +IF(AJ29<=0, "SIN COMPRA "&+UPPER(TEXT('DINAMICA ENERO 26'!$C$2,"mmm 'yy")), "COMPRADOR")) -> COMPRADOR
A30: Distribuidores | B30: COSTA | C30: FEDERICO JACUM | D30: 100088165 | E30: MARTINO FLAVIO | F30: 100077115 | G30: SABORES S R L | S30: 0 | T30: 0 | U30: 0 | V30: 0 | W30: 0 | X30: 0 | Y30: 0 | Z30: 0 | AA30: =+AVERAGE(U30,W30,Y30) -> 0 | AB30: =+AVERAGE(V30,X30,Z30) -> 0 | AD30: 0 | AE30: 0 | AF30: =+AD30+AE30 -> 0 | AG30: 0 | AH30: 0 | AI30: =+AG30+AH30 -> 0 | AJ30: =+AF30+AI30 -> 0 | AK30: =+IF(AB30+AA30+AJ30<=0, "NO COMPRADOR", +IF(AJ30<=0, "SIN COMPRA "&+UPPER(TEXT('DINAMICA ENERO 26'!$C$2,"mmm 'yy")), "COMPRADOR")) -> NO COMPRADOR
A31: Distribuidores | B31: COSTA | C31: FEDERICO JACUM | D31: 100088165 | E31: MARTINO FLAVIO | F31: 100078578 | G31: MAYOTAN S.R.L EN FORMACION | S31: 17.28 | T31: 17.28 | U31: 0 | V31: 10.8 | W31: 10.8 | X31: 0 | Y31: 0 | Z31: 10.8 | AA31: =+AVERAGE(U31,W31,Y31) -> 3.6 | AB31: =+AVERAGE(V31,X31,Z31) -> 7.2 | AD31: 0 | AE31: 0 | AF31: =+AD31+AE31 -> 0 | AG31: 0 | AH31: 0 | AI31: =+AG31+AH31 -> 0 | AJ31: =+AF31+AI31 -> 0 | AK31: =+IF(AB31+AA31+AJ31<=0, "NO COMPRADOR", +IF(AJ31<=0, "SIN COMPRA "&+UPPER(TEXT('DINAMICA ENERO 26'!$C$2,"mmm 'yy")), "COMPRADOR")) -> SIN COMPRA FEB '26
A32: Distribuidores | B32: COSTA | C32: FEDERICO JACUM | D32: 100088165 | E32: MARTINO FLAVIO | F32: 100021337 | G32: REPRESENTACIONES ALMAR S.R.L. | S32: 32.4 | T32: 32.4 | U32: 0 | V32: 0 | W32: 2.16 | X32: 2.16 | Y32: 0 | Z32: 0 | AA32: =+AVERAGE(U32,W32,Y32) -> 0.72 | AB32: =+AVERAGE(V32,X32,Z32) -> 0.72 | AD32: 0 | AE32: 0 | AF32: =+AD32+AE32 -> 0 | AG32: 0 | AH32: 0 | AI32: =+AG32+AH32 -> 0 | AJ32: =+AF32+AI32 -> 0 | AK32: =+IF(AB32+AA32+AJ32<=0, "NO COMPRADOR", +IF(AJ32<=0, "SIN COMPRA "&+UPPER(TEXT('DINAMICA ENERO 26'!$C$2,"mmm 'yy")), "COMPRADOR")) -> SIN COMPRA FEB '26
A33: Distribuidores | B33: Patagonia | C33: MARCELO VEGA | D33: 100088149 | E33: VILOTTA SEBASTIAN | F33: 100002239 | G33: PUELCHE S.A.I.C.F. | S33: 0 | T33: 0 | U33: 0 | V33: 0 | W33: 0 | X33: 0 | Y33: 0 | Z33: 0 | AA33: =+AVERAGE(U33,W33,Y33) -> 0 | AB33: =+AVERAGE(V33,X33,Z33) -> 0 | AD33: 0 | AE33: 0 | AF33: =+AD33+AE33 -> 0 | AG33: 0 | AH33: 0 | AI33: =+AG33+AH33 -> 0 | AJ33: =+AF33+AI33 -> 0 | AK33: =+IF(AB33+AA33+AJ33<=0, "NO COMPRADOR", +IF(AJ33<=0, "SIN COMPRA "&+UPPER(TEXT('DINAMICA ENERO 26'!$C$2,"mmm 'yy")), "COMPRADOR")) -> NO COMPRADOR
A34: Distribuidores | B34: Patagonia | C34: MARCELO VEGA | D34: 100088149 | E34: VILOTTA SEBASTIAN | F34: 100024103 | G34: ABAMAR SOCIEDAD DE RESPONSABILIDAD LIMITADA | S34: 0 | T34: 0 | U34: 2.16 | V34: 2.16 | W34: 0 | X34: 0 | Y34: 0 | Z34: 0 | AA34: =+AVERAGE(U34,W34,Y34) -> 0.72 | AB34: =+AVERAGE(V34,X34,Z34) -> 0.72 | AD34: 0 | AE34: 0 | AF34: =+AD34+AE34 -> 0 | AG34: 0 | AH34: 0 | AI34: =+AG34+AH34 -> 0 | AJ34: =+AF34+AI34 -> 0 | AK34: =+IF(AB34+AA34+AJ34<=0, "NO COMPRADOR", +IF(AJ34<=0, "SIN COMPRA "&+UPPER(TEXT('DINAMICA ENERO 26'!$C$2,"mmm 'yy")), "COMPRADOR")) -> SIN COMPRA FEB '26
A35: Distribuidores | B35: Patagonia | C35: MARCELO VEGA | D35: 100088149 | E35: VILOTTA SEBASTIAN | F35: 100086135 | G35: HIPERS DISTRIBUIDORA S.A.S | S35: 0 | T35: 0 | U35: 4.32 | V35: 4.32 | W35: 0 | X35: 0 | Y35: 6.48 | Z35: 6.48 | AA35: =+AVERAGE(U35,W35,Y35) -> 3.6 | AB35: =+AVERAGE(V35,X35,Z35) -> 3.6 | AD35: 0 | AE35: 0 | AF35: =+AD35+AE35 -> 0 | AG35: 0 | AH35: 0 | AI35: =+AG35+AH35 -> 0 | AJ35: =+AF35+AI35 -> 0 | AK35: =+IF(AB35+AA35+AJ35<=0, "NO COMPRADOR", +IF(AJ35<=0, "SIN COMPRA "&+UPPER(TEXT('DINAMICA ENERO 26'!$C$2,"mmm 'yy")), "COMPRADOR")) -> SIN COMPRA FEB '26
... A105: Distribuidores | B105: Cuyo | C105: MARCELO VEGA | D105: 100066856 | E105: ANDINO FACUNDO NICOLAS | F105: 100071616 | G105: PIETROFARMA SRL | S105: 10.8 | T105: 10.8 | U105: 6.48 | V105: 8.64 | W105: 0 | X105: 0 | Y105: 21.6 | Z105: 43.2 | AA105: =+AVERAGE(U105,W105,Y105) -> 9.36 | AB105: =+AVERAGE(V105,X105,Z105) -> 17.28 | AD105: 0 | AE105: 0 | AF105: =+AD105+AE105 -> 0 | AG105: 21.6 | AH105: 0 | AI105: =+AG105+AH105 -> 21.6 | AJ105: =+AF105+AI105 -> 21.6 | AK105: =+IF(AB105+AA105+AJ105<=0, "NO COMPRADOR", +IF(AJ105<=0, "SIN COMPRA "&+UPPER(TEXT('DINAMICA ENERO 26'!$C$2,"mmm 'yy")), "COMPRADOR")) -> COMPRADOR
A106: Distribuidores | B106: Cuyo | C106: MARCELO VEGA | D106: 100066856 | E106: ANDINO FACUNDO NICOLAS | F106: 100011726 | G106: JESUS GUIRAO LAG E HIJOS S.R.L. | S106: 0 | T106: 0 | U106: 4.32 | V106: 4.32 | W106: 2.16 | X106: 2.16 | Y106: 0 | Z106: 0 | AA106: =+AVERAGE(U106,W106,Y106) -> 2.16 | AB106: =+AVERAGE(V106,X106,Z106) -> 2.16 | AD106: 0 | AE106: 0 | AF106: =+AD106+AE106 -> 0 | AG106: 0 | AH106: 0 | AI106: =+AG106+AH106 -> 0 | AJ106: =+AF106+AI106 -> 0 | AK106: =+IF(AB106+AA106+AJ106<=0, "NO COMPRADOR", +IF(AJ106<=0, "SIN COMPRA "&+UPPER(TEXT('DINAMICA ENERO 26'!$C$2,"mmm 'yy")), "COMPRADOR")) -> SIN COMPRA FEB '26 | AQ106: =+VLOOKUP(AO106,Veggies!X:Y,2,FALSE) -> #N/A
A107: Distribuidores | B107: Cuyo | C107: MARCELO VEGA | D107: 100066856 | E107: ANDINO FACUNDO NICOLAS | F107: 100077612 | G107: DISOL S.R.L. | S107: 10.8 | T107: 10.8 | U107: 2.16 | V107: 2.16 | W107: 0 | X107: 0 | Y107: 0 | Z107: 0 | AA107: =+AVERAGE(U107,W107,Y107) -> 0.72 | AB107: =+AVERAGE(V107,X107,Z107) -> 0.72 | AD107: 0 | AE107: 0 | AF107: =+AD107+AE107 -> 0 | AG107: 0 | AH107: 0 | AI107: =+AG107+AH107 -> 0 | AJ107: =+AF107+AI107 -> 0 | AK107: =+IF(AB107+AA107+AJ107<=0, "NO COMPRADOR", +IF(AJ107<=0, "SIN COMPRA "&+UPPER(TEXT('DINAMICA ENERO 26'!$C$2,"mmm 'yy")), "COMPRADOR")) -> SIN COMPRA FEB '26 | AQ107: =+VLOOKUP(AO107,Veggies!X:Y,2,FALSE) -> #N/A
A108: Distribuidores | B108: Cuyo | C108: MARCELO VEGA | D108: 100066856 | E108: ANDINO FACUNDO NICOLAS | F108: 100073860 | G108: CEREALES EL DIAMANTE S R L | S108: 10.8 | T108: 10.8 | U108: 15.12 | V108: 4.32 | W108: 0 | X108: 10.8 | Y108: 38.88 | Z108: 10.8 | AA108: =+AVERAGE(U108,W108,Y108) -> 18 | AB108: =+AVERAGE(V108,X108,Z108) -> 8.64 | AD108: 0 | AE108: 0 | AF108: =+AD108+AE108 -> 0 | AG108: 0 | AH108: 0 | AI108: =+AG108+AH108 -> 0 | AJ108: =+AF108+AI108 -> 0 | AK108: =+IF(AB108+AA108+AJ108<=0, "NO COMPRADOR", +IF(AJ108<=0, "SIN COMPRA "&+UPPER(TEXT('DINAMICA ENERO 26'!$C$2,"mmm 'yy")), "COMPRADOR")) -> SIN COMPRA FEB '26 | AQ108: =+VLOOKUP(AO108,Veggies!X:Y,2,FALSE) -> #N/A
A109: Distribuidores | B109: Cuyo | C109: MARCELO VEGA | D109: 100066856 | E109: ANDINO FACUNDO NICOLAS | F109: 100002246 | G109: RAMON BUJ E HIJOS S.A.C.I.A. | S109: 0 | T109: 0 | U109: 4.32 | V109: 4.32 | W109: 0 | X109: 0 | Y109: 0 | Z109: 0 | AA109: =+AVERAGE(U109,W109,Y109) -> 1.44 | AB109: =+AVERAGE(V109,X109,Z109) -> 1.44 | AD109: 0 | AE109: 0 | AF109: =+AD109+AE109 -> 0 | AG109: 0 | AH109: 0 | AI109: =+AG109+AH109 -> 0 | AJ109: =+AF109+AI109 -> 0 | AK109: =+IF(AB109+AA109+AJ109<=0, "NO COMPRADOR", +IF(AJ109<=0, "SIN COMPRA "&+UPPER(TEXT('DINAMICA ENERO 26'!$C$2,"mmm 'yy")), "COMPRADOR")) -> SIN COMPRA FEB '26 | AQ109: =+VLOOKUP(AO109,Veggies!X:Y,2,FALSE) -> #N/A
A110: Distribuidores | B110: Cuyo | C110: MARCELO VEGA | D110: 100066856 | E110: ANDINO FACUNDO NICOLAS | F110: 100071232 | G110: NUEVO MASOL MAYORISTA SOCIEDAD ANONIMA | S110: 0 | T110: 0 | U110: 0 | V110: 0 | W110: 0 | X110: 0 | Y110: 0 | Z110: 0 | AA110: =+AVERAGE(U110,W110,Y110) -> 0 | AB110: =+AVERAGE(V110,X110,Z110) -> 0 | AD110: 0 | AE110: 0 | AF110: =+AD110+AE110 -> 0 | AG110: 0 | AH110: 0 | AI110: =+AG110+AH110 -> 0 | AJ110: =+AF110+AI110 -> 0 | AK110: =+IF(AB110+AA110+AJ110<=0, "NO COMPRADOR", +IF(AJ110<=0, "SIN COMPRA "&+UPPER(TEXT('DINAMICA ENERO 26'!$C$2,"mmm 'yy")), "COMPRADOR")) -> NO COMPRADOR | AQ110: =+VLOOKUP(AO110,Veggies!X:Y,2,FALSE) -> #N/A
